Workbook

Sheet CONTENTS
A1: TABLE OF CONTENTS
A4: Bioenergy
A6: Ethanol
A7: Biodiesel
A8: Fats
A9: Renewable Diesel
A10: Renewable Jet Fuel
A11: Wood Pellets
A12: Waste to Energy
A13: Biogas
A14: Trade
A16: Biobased products
... A38: Canola

Sheet AG SUMMARY
A1: AGRICULTURE
A3: LAND USE | B3: 2010 | C3: 2011 | D3: 2012 | E3: 2013 | F3: 2014 | G3: 2015 | H3: 2016 | I3: 2017 | J3: 2018 | K3: 2019 | L3: 2020 | M3: 2021 | N3: 2022 | O3: 2023 | P3: 2024 | Q3: Source Name | R3: Source URL | S3: Comments
A4: Number of Farms in the United States (million farms) | B4: 2.14952 | C4: 2.13124 | D4: 2.10981 | E4: 2.10201 | F4: 2.085 | G4: 2.068 | H4: 2.06 | I4: 2.042 | J4: 2.0232 | K4: 2.0076 | L4: 1.9922 | M4: 1.95955 | N4: 1.90065 | O4: 1.89495 | P4: 1.88 | Q4: USDA | R4: https://esmis.nal.usda.gov/sites/default/release-files/5712m6524/z316rz25j/db78w849h/fnlo0225.pdf | S4: Retrieved January 2026
A5: Acreage of Agriculture in the United States (million acres) | B5: 915.66 | C5: 914.42 | D5: 914.6 | E5: 914.03 | F5: 913 | G5: 912 | H5: 911 | I5: 900.37 | J5: 898.86 | K5: 894.93 | L5: 893.11 | M5: 888.8 | N5: 879.66 | O5: 878.56 | P5: 876.46 | Q5: USDA | R5: https://esmis.nal.usda.gov/sites/default/release-files/5712m6524/z316rz25j/db78w849h/fnlo0225.pdf | S5: Retrieved January 2026
A6: U.S. Farmland Used as Permanent Pasture (million acres) | D6: 415.3 | I6: 401 | N6: 393 | Q6: USDA | R6: https://www.nass.usda.gov/Publications/Highlights/2024/Census22_HL_FarmsFarmland.pdf | S6: Retrieved January 2026
A7: U.S. Farmland Used as Cropland (million acres) | D7: 389.7 | I7: 396.43382 | N7: 382 | Q7: USDA | R7: https://www.nass.usda.gov/Publications/Highlights/2024/Census22_HL_FarmsFarmland.pdf | S7: Retrieved January 2026
A8: U.S. Cropland Harvested (million acres) | D8: 315 | I8: 320.04186 | N8: 301 | Q8: USDA | R8: https://www.nass.usda.gov/Publications/Highlights/2024/Census22_HL_FarmsFarmland.pdf | S8: Retrieved January 2026
A9: U.S. Farmland Used as Woodland (million acres) | D9: 77 | I9: 73 | N9: 72 | Q9: USDA | R9: https://www.nass.usda.gov/Publications/Highlights/2024/Census22_HL_FarmsFarmland.pdf | S9: Retrieved January 2026
A10: U.S. Farmland Used for other purposes (million acres) | D10: 32.5 | I10: 30 | N10: 33 | Q10: USDA | R10: https://www.nass.usda.gov/Publications/Highlights/2024/Census22_HL_FarmsFarmland.pdf | S10: Retrieved January 2026
A11: Average Farm Size (acres) | B11: 426 | C11: 429 | D11: 433 | E11: 435 | F11: 438 | G11: 441 | H11: 442 | I11: 441 | J11: 444 | K11: 446 | L11: 448 | M11: 454 | N11: 463 | O11: 464 | P11: 466 | Q11: USDA | R11: https://esmis.nal.usda.gov/sites/default/release-files/5712m6524/z316rz25j/db78w849h/fnlo0225.pdf | S11: Retrieved January 2026
A13: PRODUCTION + CONSUMPTION | B13: 2010 | C13: 2011 | D13: 2012 | E13: 2013 | F13: 2014 | G13: 2015 | H13: 2016 | I13: 2017 | J13: 2018 | K13: 2019 | L13: 2020 | M13: 2021 | N13: 2022 | O13: 2023 | P13: 2024 | Q13: Source Name | R13: Source URL | S13: Comments
A14: Agriculture Production (billion dollars) | B14: 191.09883 | C14: 211.35933 | D14: 223.86721 | E14: 210.17749 | F14: 194.80349 | G14: 179.1653 | H14: 185.66011 | I14: 187.8716 | J14: 185.33296 | K14: 174.04985 | L14: 206.44286 | M14: 257.23451 | N14: 263.01477 | O14: 233.4698 | Q14: USDA | R14: https://quickstats.nass.usda.gov/results/FE8787AE-F141-38C3-A8D7-17EC943640FB | S14: Retrieved January 2026
A15: Agriculture Exports (billion dollars) | B15: 118.719 | C15: 142.129 | D15: 145.918 | E15: 148.483 | F15: 154.542 | G15: 137.216 | H15: 138.903 | I15: 142.866 | J15: 144.733 | K15: 141.082 | L15: 149.672 | M15: 176.631 | N15: 195.68 | O15: 174.172 | P15: 175.979 | Q15: USDA | R15: https://www.ers.usda.gov/data-products/foreign-agricultural-trade-of-the-united-states-fatus/calendar-year | S15: Retrieved January 2026
A16: Agriculture Imports (billion dollars) | B16: 85.582 | C16: 102.033 | D16: 108.762 | E16: 111.002 | F16: 118.73 | G16: 121.122 | H16: 122.569 | I16: 129.21 | J16: 137.991 | K16: 141.562 | L16: 146.282 | M16: 170.595 | N16: 198.243 | O16: 194.842 | P16: 213 | Q16: USDA | R16: https://www.ers.usda.gov/data-products/foreign-agricultural-trade-of-the-united-states-fatus/calendar-year | S16: Retrieved January 2026
A18: ECONOMICS | B18: 2010 | C18: 2011 | D18: 2012 | E18: 2013 | F18: 2014 | G18: 2015 | H18: 2016 | I18: 2017 | J18: 2018 | K18: 2019 | L18: 2020 | M18: 2021 | N18: 2022 | O18: 2023 | P18: 2024 | Q18: Source Name | R18: Source URL | S18: Comments
A19: Net cash income (billion dollars) | B19: 96.335985 | C19: 123.21526 | D19: 135.27696 | E19: 135.55843 | F19: 131.55399 | G19: 106.19768 | H19: 95.56963 | I19: 101.26836 | J19: 103.47687 | K19: 109.15947 | L19: 120.87738 | M19: 155.19729 | N19: 210.04299 | O19: 156.74038 | P19: 140.55826 | Q19: USDA | R19: https://www.ers.usda.gov/data-products/farm-income-and-wealth-statistics/data-files-us-and-state-level-farm-income-and-wealth-statistics | S19: Retrieved January 2026
A20: Net farm income (billion dollars) | B20: 77.098341 | C20: 113.59305 | D20: 96.455951 | E20: 123.75284 | F20: 92.429956 | G20: 81.364081 | H20: 62.31452 | I20: 75.727325 | J20: 82.395831 | K20: 82.000034 | L20: 98.866384 | M20: 146.33148 | N20: 181.95228 | O20: 147.28189 | P20: 127.82734 | Q20: USDA | R20: https://www.ers.usda.gov/data-products/farm-income-and-wealth-statistics/data-files-us-and-state-level-farm-income-and-wealth-statistics | S20: Retrieved January 2026
A21: Total Farm Assets (billion dollars) | B21: 2170.8321 | C21: 2318.7202 | D21: 2638.2372 | E21: 2776.1096 | F21: 2949.2385 | G21: 2909.6532 | H21: 2914.4409 | I21: 3005.9449 | J21: 3019.1396 | K21: 3049.0815 | L21: 3130.5056 | M21: 3424.1307 | N21: 3788.4202 | O21: 4014.3413 | P21: 4218.2092 | Q21: USDA | R21: https://www.ers.usda.gov/data-products/farm-income-and-wealth-statistics/data-files-us-and-state-level-farm-income-and-wealth-statistics | S21: Retrieved January 2026
A22: Total Farm Debt (billion dollars) | B22: 278.93053 | C22: 294.47213 | D22: 297.52112 | E22: 315.33249 | F22: 345.20135 | G22: 356.73804 | H22: 374.16421 | I22: 390.42522 | J22: 402.6055 | K22: 420.4948 | L22: 441.25379 | M22: 474.30511 | N22: 496.14235 | O22: 519.29942 | P22: 563.47872 | Q22: USDA | R22: https://www.ers.usda.gov/data-products/farm-income-and-wealth-statistics/data-files-us-and-state-level-farm-income-and-wealth-statistics | S22: Retrieved January 2026
A23: Total Farm Equity (billion dollars) | B23: 1891.9016 | C23: 2024.248 | D23: 2340.7161 | E23: 2460.7771 | F23: 2604.0371 | G23: 2552.9151 | H23: 2540.2767 | I23: 2615.5196 | J23: 2616.5341 | K23: 2628.5867 | L23: 2689.2518 | M23: 2949.8256 | N23: 3292.2779 | O23: 3495.0419 | P23: 3654.7305 | Q23: USDA | R23: https://www.ers.usda.gov/data-products/farm-income-and-wealth-statistics/data-files-us-and-state-level-farm-income-and-wealth-statistics | S23: Retrieved January 2026
A24: Value Added of Farms (billion dollars) | B24: 117 | C24: 151.1 | D24: 148.8 | E24: 184.5 | F24: 167.1 | G24: 146.3 | H24: 130.3 | I24: 138.7 | J24: 136.8 | K24: 122.6 | L24: 120.5 | M24: 185.7 | N24: 247.1 | O24: 218.2 | P24: 215.8 | Q24: Census Bureau | R24: https://apps.bea.gov/iTable/?reqid=1603&step=2&Categories=GDPxInd&isURI=1&_gl=1*bg4lgp*_ga*MTU2MDMwOTkxNy4xNzY3ODk4NTU4*_ga_J4698JNNFT*czE3Njc5NzYxNDUkbzMkZzEkdDE3Njc5NzYxNjYkajM5JGwwJGgw#eyJhcHBpZCI6MTYwMywic3RlcHMiOlsxLDIsNCw0XSwiZGF0YSI6W1siY2F0ZWdvcmllcyIsIkdEUHhJbmQiXSxbIlRhYmxlX0xpc3QiLCJUVkExMDUiXSxbIlNjYWxlIiwiLTkiXSxbIkZpcnN0X1llYXIiLCIyMDEwIl0sWyJMYXN0X1llYXIiLCIyMDI1Il0sWyJSb3dzIixbIjIyUiIsIkdEUCIsIlBWVCIsIjExIiwiMTExQ0EiLCIxMTNGRiIsIjIxIiwiMjExIiwiMjEyIiwiMjEzIiwiMjIiLCIyMyIsIjMxRyIsIjMzREciLCIzMjEiLCIzMjciLCIzMzEiLCIzMzIiLCIzMzMiLCIzMzQiLCIzMzUiLCIzMzYxTVYiLCIzMzY0T1QiLCIzMzciLCIzMzkiLCIzMU5EIiwiMzExRlQiLCIzMTNUVCIsIjMxNUFMIiwiMzIyIiwiMzIzIiwiMzI0IiwiMzI1IiwiMzI2IiwiNDIiLCI0NFJUIiwiNDQxIiwiNDQ1IiwiNDUyIiwiNEEwIiwiNDhUVyIsIjQ4MSIsIjQ4MiIsIjQ4MyIsIjQ4NCIsIjQ4NSIsIjQ4NiIsIjQ4N09TIiwiNDkzIiwiNTEiLCI1MTEiLCI1MTIiLCI1MTMiLCI1MTQiLCJGSVJFIiwiNTIiLCI1MjFDSSIsIjUyMyIsIjUyNCIsIjUyNSIsIjUzIiwiNTMxIiwiSFMiLCJPUkUiLCI1MzJSTCIsIlBST0YiLCI1NCIsIjU0MTEiLCI1NDE1IiwiNTQxMk9QIiwiNTUiLCI1NiIsIjU2MSIsIjU2MiIsIjYiLCI2MSIsIjYyIiwiNjIxIiwiNjIyIiwiNjIzIiwiNjI0IiwiNyIsIjcxIiwiNzExQVMiLCI3MTMiLCI3MiIsIjcyMSIsIjcyMiIsIjgxIiwiRyIsIkdGIiwiR0ZHIiwiR0ZHRCIsIkdGR04iLCJHRkUiLCJHU0wiLCJHU0xHIiwiR1NMRSIsIiIsIlBHT09EIiwiUFNFUlYiLCJJQ1QiXV0sWyJTZXJpZXMiLCJBIl0sWyJDb2x1bW5zIixbIjIwMjAiXV1dfQ== | S24: Retrieved January 2026
A25: Gross Output of Farms (billion dollars) | B25: 320.9 | C25: 380.3 | D25: 404.2 | E25: 437.6 | F25: 442.2 | G25: 403.2 | H25: 379.8 | I25: 395.5 | J25: 395.1 | K25: 388.1 | L25: 390.9 | M25: 475.4 | N25: 576.7 | O25: 570 | P25: 565.7 | Q25: Census Bureau | R25: https://apps.bea.gov/iTable/?reqid=1603&step=2&Categories=GDPxInd&isURI=1&_gl=1*bg4lgp*_ga*MTU2MDMwOTkxNy4xNzY3ODk4NTU4*_ga_J4698JNNFT*czE3Njc5NzYxNDUkbzMkZzEkdDE3Njc5NzYxNjYkajM5JGwwJGgw#eyJhcHBpZCI6MTYwMywic3RlcHMiOlsxLDIsNCw0XSwiZGF0YSI6W1siY2F0ZWdvcmllcyIsIkdEUHhJbmQiXSxbIlRhYmxlX0xpc3QiLCJUVkExMDUiXSxbIlNjYWxlIiwiLTkiXSxbIkZpcnN0X1llYXIiLCIyMDEwIl0sWyJMYXN0X1llYXIiLCIyMDI1Il0sWyJSb3dzIixbIjIyUiIsIkdEUCIsIlBWVCIsIjExIiwiMTExQ0EiLCIxMTNGRiIsIjIxIiwiMjExIiwiMjEyIiwiMjEzIiwiMjIiLCIyMyIsIjMxRyIsIjMzREciLCIzMjEiLCIzMjciLCIzMzEiLCIzMzIiLCIzMzMiLCIzMzQiLCIzMzUiLCIzMzYxTVYiLCIzMzY0T1QiLCIzMzciLCIzMzkiLCIzMU5EIiwiMzExRlQiLCIzMTNUVCIsIjMxNUFMIiwiMzIyIiwiMzIzIiwiMzI0IiwiMzI1IiwiMzI2IiwiNDIiLCI0NFJUIiwiNDQxIiwiNDQ1IiwiNDUyIiwiNEEwIiwiNDhUVyIsIjQ4MSIsIjQ4MiIsIjQ4MyIsIjQ4NCIsIjQ4NSIsIjQ4NiIsIjQ4N09TIiwiNDkzIiwiNTEiLCI1MTEiLCI1MTIiLCI1MTMiLCI1MTQiLCJGSVJFIiwiNTIiLCI1MjFDSSIsIjUyMyIsIjUyNCIsIjUyNSIsIjUzIiwiNTMxIiwiSFMiLCJPUkUiLCI1MzJSTCIsIlBST0YiLCI1NCIsIjU0MTEiLCI1NDE1IiwiNTQxMk9QIiwiNTUiLCI1NiIsIjU2MSIsIjU2MiIsIjYiLCI2MSIsIjYyIiwiNjIxIiwiNjIyIiwiNjIzIiwiNjI0IiwiNyIsIjcxIiwiNzExQVMiLCI3MTMiLCI3MiIsIjcyMSIsIjcyMiIsIjgxIiwiRyIsIkdGIiwiR0ZHIiwiR0ZHRCIsIkdGR04iLCJHRkUiLCJHU0wiLCJHU0xHIiwiR1NMRSIsIiIsIlBHT09EIiwiUFNFUlYiLCJJQ1QiXV0sWyJTZXJpZXMiLCJBIl0sWyJDb2x1bW5zIixbIjIwMjAiXV1dfQ== | S25: Retrieved January 2026
A26: Value Addes as percentage of GDP farms (%) | B26: 0.8 | C26: 1 | D26: 0.9 | E26: 1.1 | F26: 0.9 | G26: 0.8 | H26: 0.7 | I26: 0.7 | J26: 0.7 | K26: 0.6 | L26: 0.6 | M26: 0.8 | N26: 0.9 | O26: 0.8 | P26: 0.7 | Q26: Census Bureau | R26: https://apps.bea.gov/iTable/?reqid=1603&step=2&Categories=GDPxInd&isURI=1&_gl=1*bg4lgp*_ga*MTU2MDMwOTkxNy4xNzY3ODk4NTU4*_ga_J4698JNNFT*czE3Njc5NzYxNDUkbzMkZzEkdDE3Njc5NzYxNjYkajM5JGwwJGgw#eyJhcHBpZCI6MTYwMywic3RlcHMiOlsxLDIsNCw0XSwiZGF0YSI6W1siY2F0ZWdvcmllcyIsIkdEUHhJbmQiXSxbIlRhYmxlX0xpc3QiLCJUVkExMDUiXSxbIlNjYWxlIiwiLTkiXSxbIkZpcnN0X1llYXIiLCIyMDEwIl0sWyJMYXN0X1llYXIiLCIyMDI1Il0sWyJSb3dzIixbIjIyUiIsIkdEUCIsIlBWVCIsIjExIiwiMTExQ0EiLCIxMTNGRiIsIjIxIiwiMjExIiwiMjEyIiwiMjEzIiwiMjIiLCIyMyIsIjMxRyIsIjMzREciLCIzMjEiLCIzMjciLCIzMzEiLCIzMzIiLCIzMzMiLCIzMzQiLCIzMzUiLCIzMzYxTVYiLCIzMzY0T1QiLCIzMzciLCIzMzkiLCIzMU5EIiwiMzExRlQiLCIzMTNUVCIsIjMxNUFMIiwiMzIyIiwiMzIzIiwiMzI0IiwiMzI1IiwiMzI2IiwiNDIiLCI0NFJUIiwiNDQxIiwiNDQ1IiwiNDUyIiwiNEEwIiwiNDhUVyIsIjQ4MSIsIjQ4MiIsIjQ4MyIsIjQ4NCIsIjQ4NSIsIjQ4NiIsIjQ4N09TIiwiNDkzIiwiNTEiLCI1MTEiLCI1MTIiLCI1MTMiLCI1MTQiLCJGSVJFIiwiNTIiLCI1MjFDSSIsIjUyMyIsIjUyNCIsIjUyNSIsIjUzIiwiNTMxIiwiSFMiLCJPUkUiLCI1MzJSTCIsIlBST0YiLCI1NCIsIjU0MTEiLCI1NDE1IiwiNTQxMk9QIiwiNTUiLCI1NiIsIjU2MSIsIjU2MiIsIjYiLCI2MSIsIjYyIiwiNjIxIiwiNjIyIiwiNjIzIiwiNjI0IiwiNyIsIjcxIiwiNzExQVMiLCI3MTMiLCI3MiIsIjcyMSIsIjcyMiIsIjgxIiwiRyIsIkdGIiwiR0ZHIiwiR0ZHRCIsIkdGR04iLCJHRkUiLCJHU0wiLCJHU0xHIiwiR1NMRSIsIiIsIlBHT09EIiwiUFNFUlYiLCJJQ1QiXV0sWyJTZXJpZXMiLCJBIl0sWyJDb2x1bW5zIixbIjIwMjAiXV1dfQ== | S26: Retrieved January 2026
A27: Full time and part time employees by farms (Thousands) | B27: 754 | C27: 763 | D27: 780 | E27: 789 | F27: 803 | G27: 817 | H27: 820 | I27: 819 | J27: 814 | K27: 813 | L27: 809 | M27: 811 | N27: 814 | O27: 813 | P27: 811 | Q27: Census Bureau | R27: https://apps.bea.gov/iTable/?reqid=1603&step=2&Categories=GDPxInd&isURI=1&_gl=1*bg4lgp*_ga*MTU2MDMwOTkxNy4xNzY3ODk4NTU4*_ga_J4698JNNFT*czE3Njc5NzYxNDUkbzMkZzEkdDE3Njc5NzYxNjYkajM5JGwwJGgw#eyJhcHBpZCI6MTYwMywic3RlcHMiOlsxLDIsNCw0XSwiZGF0YSI6W1siY2F0ZWdvcmllcyIsIkdEUHhJbmQiXSxbIlRhYmxlX0xpc3QiLCJUVkExMDUiXSxbIlNjYWxlIiwiLTkiXSxbIkZpcnN0X1llYXIiLCIyMDEwIl0sWyJMYXN0X1llYXIiLCIyMDI1Il0sWyJSb3dzIixbIjIyUiIsIkdEUCIsIlBWVCIsIjExIiwiMTExQ0EiLCIxMTNGRiIsIjIxIiwiMjExIiwiMjEyIiwiMjEzIiwiMjIiLCIyMyIsIjMxRyIsIjMzREciLCIzMjEiLCIzMjciLCIzMzEiLCIzMzIiLCIzMzMiLCIzMzQiLCIzMzUiLCIzMzYxTVYiLCIzMzY0T1QiLCIzMzciLCIzMzkiLCIzMU5EIiwiMzExRlQiLCIzMTNUVCIsIjMxNUFMIiwiMzIyIiwiMzIzIiwiMzI0IiwiMzI1IiwiMzI2IiwiNDIiLCI0NFJUIiwiNDQxIiwiNDQ1IiwiNDUyIiwiNEEwIiwiNDhUVyIsIjQ4MSIsIjQ4MiIsIjQ4MyIsIjQ4NCIsIjQ4NSIsIjQ4NiIsIjQ4N09TIiwiNDkzIiwiNTEiLCI1MTEiLCI1MTIiLCI1MTMiLCI1MTQiLCJGSVJFIiwiNTIiLCI1MjFDSSIsIjUyMyIsIjUyNCIsIjUyNSIsIjUzIiwiNTMxIiwiSFMiLCJPUkUiLCI1MzJSTCIsIlBST0YiLCI1NCIsIjU0MTEiLCI1NDE1IiwiNTQxMk9QIiwiNTUiLCI1NiIsIjU2MSIsIjU2MiIsIjYiLCI2MSIsIjYyIiwiNjIxIiwiNjIyIiwiNjIzIiwiNjI0IiwiNyIsIjcxIiwiNzExQVMiLCI3MTMiLCI3MiIsIjcyMSIsIjcyMiIsIjgxIiwiRyIsIkdGIiwiR0ZHIiwiR0ZHRCIsIkdGR04iLCJHRkUiLCJHU0wiLCJHU0xHIiwiR1NMRSIsIiIsIlBHT09EIiwiUFNFUlYiLCJJQ1QiXV0sWyJTZXJpZXMiLCJBIl0sWyJDb2x1bW5zIixbIjIwMjAiXV1dfQ== | S27: Retrieved January 2026
A29: ENVIRONMENTAL | B29: 2010 | C29: 2011 | D29: 2012 | E29: 2013 | F29: 2014 | G29: 2015 | H29: 2016 | I29: 2017 | J29: 2018 | K29: 2019 | L29: 2020 | M29: 2021 | N29: 2022 | O29: 2023 | P29: 2024 | Q29: Source Name | R29: Source URL | S29: Comments
A30: Fertilizer Consumption in US (million metric tons) | B30: 19.7923 | C30: 20.3628 | D30: 20.8613 | E30: 21.0868 | F30: 19.9778 | G30: 20.0757 | H30: 20.714 | I30: 20.99 | J30: 19.689 | K30: 20.55 | L30: 20.1804 | M30: 18.7322 | N30: 20.5066 | O30: 20.1377 | Q30: IFA | R30: https://www.ifastat.org/databases/plant-nutrition | S30: Retrieved January 2026
A31: Nitrogen products (million metric tons) | B31: 11.737 | C31: 12.2314 | D31: 12.1879 | E31: 12.0607 | F31: 11.8167 | G31: 11.6831 | H31: 11.7514 | I31: 11.8153 | J31: 11.602 | K31: 11.949 | L31: 11.8626 | M31: 11.1641 | N31: 12.0008 | O31: 11.6201 | Q31: IFA | R31: https://www.ifastat.org/databases/plant-nutrition | S31: Retrieved January 2026
A32: Phosphate products (million metric tons) | B32: 3.8902 | C32: 3.9456 | D32: 4.2886 | E32: 4.2601 | F32: 3.8741 | G32: 3.9198 | H32: 4.0908 | I32: 4.2974 | J32: 3.767 | K32: 4.087 | L32: 3.7708 | M32: 3.5238 | N32: 3.895 | O32: 3.8874 | Q32: IFA | R32: https://www.ifastat.org/databases/plant-nutrition | S32: Retrieved January 2026
A33: Potash products (million metric tons) | B33: 4.1651 | C33: 4.1858 | D33: 4.3848 | E33: 4.766 | F33: 4.287 | G33: 4.4728 | H33: 4.8718 | I33: 4.8773 | J33: 4.32 | K33: 4.514 | L33: 4.547 | M33: 4.0443 | N33: 4.6108 | O33: 4.6302 | Q33: IFA | R33: https://www.ifastat.org/databases/plant-nutrition | S33: Retrieved January 2026
A34: WATER | B34: 2010 | C34: 2011 | D34: 2012 | E34: 2013 | F34: 2014 | G34: 2015 | H34: 2016 | I34: 2017 | J34: 2018 | K34: 2019 | L34: 2020 | M34: 2021 | N34: 2022 | O34: 2023 | P34: 2024 | Q34: Source Name | R34: Source URL | S34: Comments
A35: Irrigated Land in the U.S. (million acres) | B35: 62.38349 | G35: 63.5 | Q35: USGS | R35: [2010] https://pubs.usgs.gov/circ/1405/pdf/circ1405.pdf [2015] https://pubs.usgs.gov/circ/1441/circ1441.pdf | S35: Retrieved June 2018 Retrieved October 2018
A36: Withdrawals (million acre-feet year) | B36: 129.16531 | G36: 132 | Q36: USGS | R36: [2010] https://pubs.usgs.gov/circ/1405/pdf/circ1405.pdf [2015] https://pubs.usgs.gov/circ/1441/circ1441.pdf | S36: Retrieved June 2018 Retrieved October 2018
A37: Groundwater withdrawals (million acre-feet year) | B37: 55.40511 | G37: 64.1 | Q37: USGS | R37: [2010] https://pubs.usgs.gov/circ/1405/pdf/circ1405.pdf [2015] https://pubs.usgs.gov/circ/1441/circ1441.pdf | S37: Retrieved June 2018 Retrieved October 2018
A38: Surface water withdrawals (million acre-feet year) | B38: 73.86284 | G38: 68.3 | Q38: USGS | R38: [2010] https://pubs.usgs.gov/circ/1405/pdf/circ1405.pdf [2015] https://pubs.usgs.gov/circ/1441/circ1441.pdf | S38: Retrieved June 2018 Retrieved October 2018

Sheet CORN
A1: CORN
A3: PHYSICAL | B3: 2010 | C3: 2011 | D3: 2012 | E3: 2013 | F3: 2014 | G3: 2015 | H3: 2016 | I3: 2017 | J3: 2018 | K3: 2019 | L3: 2020 | M3: 2021 | N3: 2022 | O3: 2023 | P3: 2024 | Q3: Source Name | R3: Source URL | S3: Comments
A4: Number of Farms Growing Corn in the United States (thousand farms) | D4: 376.179 | I4: 328.101 | N4: 306.053 | Q4: USDA | R4: https://quickstats.nass.usda.gov/results/453C1E4E-CA2D-37D4-AE93-56531E28FED8 | S4: Retrieved January 2026
A5: Planted Acreage of Corn in the United States (million acres) | B5: 90.909 | C5: 94.641 | D5: 88.162 | E5: 92.901 | F5: 90.432 | G5: 89.37 | H5: 88.821 | I5: 90.167 | J5: 94.004 | K5: 88.019 | L5: 90.597 | M5: 95.365 | N5: 97.291 | O5: 91.936 | P5: 88.192 | Q5: USDA-NASS | R5: https://quickstats.nass.usda.gov/results/5C42EA33-506B-37F7-871A-178A7B2FDB70 | S5: Retrieved January 2026
A6: Yield of Corn grown in U.S. (metric tons per acre) | B6: 4.0525247 | C6: 4.0525247 | D6: 5.4363136 | E6: 5.4363136 | F6: 6.1529186 | G6: 5.312761 | H6: 5.0656558 | I6: 3.2123671 | J6: 3.6818669 | K6: 4.8185507 | L6: 4.7938402 | M6: 4.6949981 | N6: 5.5351557 | O6: 4.7691296 | P6: 4.7691296 | Q6: USDA-PSD | R6: https://apps.fas.usda.gov/psdonline/app/index.html#/app/downloads | S6: Retrieved January 2026 1 acre=0.404686 Ha
A7: Planted acreage of corn for ethanol production in the United States (million acres) | B7: =B19/B6 -> 28.32282 | C7: =C19/C6 -> 30.960583 | D7: =D19/D6 -> 22.99367 | E7: =E19/E6 -> 21.343172 | F7: =F19/F6 -> 20.818129 | G7: =G19/G6 -> 24.46981 | H7: =H19/H6 -> 25.779554 | I7: =I19/I6 -> 42.273756 | ... P7: =P19/P6 -> 28.771382 | Q7: Calculation
A9: PRODUCTION | B9: 2010 | C9: 2011 | D9: 2012 | E9: 2013 | F9: 2014 | G9: 2015 | H9: 2016 | I9: 2017 | J9: 2018 | K9: 2019 | L9: 2020 | M9: 2021 | N9: 2022 | O9: 2023 | P9: 2024 | Q9: Source Name | R9: Source URL | S9: Comments
A10: Total Volume of Corn Grown in the US (million metric tons) | B10: 315.618 | C10: 312.789 | D10: 273.192 | E10: 351.316 | F10: 361.136 | G10: 345.506 | H10: 384.778 | I10: 371.096 | J10: 363.787 | K10: 344.651 | L10: 357.819 | M10: 381.469 | N10: 346.739 | O10: 389.667 | P10: 378.268 | Q10: USDA | R10: https://apps.fas.usda.gov/psdonline/app/index.html#/app/downloads | S10: Retrieved January 2026
A11: Total Volume of Corn consumption (million metric tons) | B11: 284.549 | C11: 277.961 | D11: 262.973 | E11: 293.002 | F11: 301.837 | G11: 298.845 | H11: 313.785 | I11: 313.991 | J11: 309.503 | K11: 306.45 | L11: 308.215 | M11: 315.665 | N11: 305.931 | O11: 322.873 | P11: 312.102 | Q11: USDA | R11: https://apps.fas.usda.gov/psdonline/app/index.html#/app/downloads | S11: Retrieved January 2026
A12: Corn imports (million metric tons) | B12: 0.703 | C12: 0.746 | D12: 4.063 | E12: 0.909 | F12: 0.804 | G12: 1.716 | H12: 1.45 | I12: 0.915 | J12: 0.71 | K12: 1.064 | L12: 0.616 | M12: 0.615 | N12: 0.982 | O12: 0.722 | P12: 0.55 | Q12: USDA | R12: https://apps.fas.usda.gov/psdonline/app/index.html#/app/downloads | S12: Retrieved January 2026
A13: Corn exports (million metric tons) | B13: 46.508 | C13: 39.096 | D13: 18.545 | E13: 48.79 | F13: 47.421 | G13: 48.228 | H13: 58.313 | I13: 61.906 | J13: 52.538 | K13: 45.175 | L13: 69.775 | M13: 62.802 | N13: 42.214 | O13: 57.275 | P13: 72.603 | Q13: USDA | R13: https://apps.fas.usda.gov/psdonline/app/index.html#/app/downloads | S13: Retrieved January 2026
A14: Beginning stocks (million metric tons) | B14: 43.38 | C14: 28.644 | D14: 25.122 | E14: 20.859 | F14: 31.292 | G14: 43.974 | H14: 44.123 | I14: 58.253 | J14: 54.367 | K14: 56.823 | L14: 50.913 | M14: 31.358 | N14: 34.975 | O14: 34.551 | P14: 44.792 | Q14: USDA | R14: https://apps.fas.usda.gov/psdonline/app/index.html#/app/downloads | S14: Retrieved January 2026
A15: Ending stocks (million metric tons) | B15: 28.644 | C15: 25.122 | D15: 20.859 | E15: 31.292 | F15: 43.974 | G15: 44.123 | H15: 58.253 | I15: 54.367 | J15: 56.823 | K15: 50.913 | L15: 31.358 | M15: 34.975 | N15: 34.551 | O15: 44.792 | P15: 38.905 | Q15: USDA | R15: https://apps.fas.usda.gov/psdonline/app/index.html#/app/downloads | S15: Retrieved January 2026
A16: Uses
A17: Total Volume of Corn Consumed for Feed (million metric tons) | B17: 127.3894 | C17: 119.25295 | D17: 112.80173 | E17: 107.71598 | F17: 125.10442 | G17: 132.186 | H17: 127.94635 | I17: 136.69875 | J17: 132.61495 | K17: 134.80273 | L17: 144.45947 | M17: 141.68495 | N17: 141.76263 | O17: 137.14748 | P17: 145.79458 | Q17: USDA | R17: https://www.ers.usda.gov/data-products/feed-grains-database/feed-grains-yearbook-tables.aspx | S17: Retrieved January 2026 1 bushel of corn=0.025 metric tons
A18: Total Volume of Corn Consumed for Food, alcohol and industrial use (million metric tons): | B18: 148.46665 | C18: 160.06305 | D18: 159.99335 | E18: 150.33023 | F18: 162.52742 | G18: 164.15252 | H18: 165.4148 | I18: 171.39798 | J18: 175.67863 | K18: 169.08925 | L18: 156.40533 | M18: 160.8963 | N18: 168.19043 | O18: 163.16168 | P18: 171.235 | Q18: USDA | R18: https://www.ers.usda.gov/data-products/feed-grains-database/feed-grains-yearbook-tables.aspx | S18: Retrieved January 2026 1 bushel of corn=0.025 metric tons
A19: Corn Processed into Fuel Alcohol (million metric tons) | B19: 114.77893 | C19: 125.46852 | D19: 125.0008 | E19: 116.02818 | F19: 128.09225 | G19: 130.00225 | H19: 130.59035 | I19: 135.79883 | J19: 140.12068 | K19: 134.45065 | L19: 121.41688 | M19: 125.68988 | N19: 132.99038 | O19: 129.3913 | P19: 137.21445 | Q19: USDA | R19: https://www.ers.usda.gov/data-products/feed-grains-database/feed-grains-yearbook-tables.aspx | S19: Retrieved January 2026 1 bushel of corn=0.025 metric tons
A20: Corn Processed into High Fructose Corn Syrup (million metric tons) | B20: 12.803125 | C20: 13.026225 | D20: 12.7901 | E20: 12.287175 | F20: 11.94345 | G20: 11.952475 | H20: 11.80645 | I20: 11.6744 | J20: 11.481275 | K20: 11.035475 | L20: 10.45515 | M20: 10.51435 | N20: 10.384925 | O20: 10.222675 | P20: 10.44365 | Q20: USDA | R20: https://www.ers.usda.gov/data-products/feed-grains-database/feed-grains-yearbook-tables.aspx | S20: Retrieved January 2026 1 bushel of corn=0.025 metric tons
A21: Corn Processed into Glucose and Dextrose (million metric tons) | B21: 6.4321 | C21: 6.808925 | D21: 7.358975 | E21: 7.298 | F21: 7.67865 | G21: 7.451725 | H21: 8.425975 | I21: 9.2836 | J21: 9.2893 | K21: 8.8778 | L21: 8.904775 | M21: 9.117825 | N21: 9.2758 | O21: 8.594925 | P21: 8.409275 | Q21: USDA | R21: https://www.ers.usda.gov/data-products/feed-grains-database/feed-grains-yearbook-tables.aspx | S21: Retrieved January 2026 1 bushel of corn=0.025 metric tons
A22: Corn Processed into Starch (million metric tons) | B22: 6.260925 | C22: 6.459375 | D22: 6.35025 | E22: 6.234725 | F22: 6.263675 | G22: 6.161175 | H22: 5.939525 | I22: 5.88365 | J22: 5.894875 | K22: 5.762825 | L22: 5.806025 | M22: 6.29425 | N22: 6.154325 | O22: 5.482775 | P22: 5.567625 | Q22: USDA | R22: https://www.ers.usda.gov/data-products/feed-grains-database/feed-grains-yearbook-tables.aspx | S22: Retrieved January 2026 1 bushel of corn=0.025 metric tons
A23: Corn Used as Cereal (million metric tons) | B23: 4.841575 | C23: 4.925 | D23: 5.080725 | E23: 4.9855 | F23: 5.01195 | G23: 5.030225 | H23: 5.0775 | I23: 5.1075 | J23: 5.1675 | K23: 5.2125 | L23: 5.4975 | M23: 5.355 | N23: 5.36 | O23: 5.42 | P23: 5.475 | Q23: USDA | R23: https://www.ers.usda.gov/data-products/feed-grains-database/feed-grains-yearbook-tables.aspx | S23: Retrieved January 2026 1 bushel of corn=0.025 metric tons
A24: Corn Processed into Alcoholic Beverages (million metric tons) | B24: 3.35 | C24: 3.375 | D24: 3.4125 | E24: 3.5 | F24: 3.53745 | G24: 3.554675 | H24: 3.575 | I24: 3.65 | J24: 3.725 | K24: 3.75 | L24: 4.325 | M24: 3.925 | N24: 4.025 | O24: 4.05 | P24: 4.125 | Q24: USDA | R24: https://www.ers.usda.gov/data-products/feed-grains-database/feed-grains-yearbook-tables.aspx | S24: Retrieved January 2026 1 bushel of corn=0.025 metric tons
A25: Corn Saved for Seed (million metric tons) | B25: 0.693875 | C25: 0.7394 | D25: 0.774675 | E25: 0.774075 | F25: 0.74305 | G25: 0.731375 | H25: 0.763875 | I25: 0.7326 | J25: 0.738275 | K25: 0.723475 | L25: 0.744425 | M25: 0.764675 | N25: 0.7279 | O25: 0.79055 | P25: 0.743275 | Q25: USDA | R25: https://www.ers.usda.gov/data-products/feed-grains-database/feed-grains-yearbook-tables.aspx | S25: Retrieved January 2026 1 bushel of corn=0.025 metric tons
A26: Corn into Biofuels
A27: Ethanol production as percent of total corn use | B27: =B19/B10 -> 0.36366407 | C27: =C19/C10 -> 0.40112832 | D27: =D19/D10 -> 0.45755659 | E27: =E19/E10 -> 0.33026727 | F27: =F19/F10 -> 0.35469255 | G27: =G19/G10 -> 0.37626626 | H27: =H19/H10 -> 0.33939142 | I27: =I19/I10 -> 0.36593988 | ... P27: =P19/P10 -> 0.36274401 | Q27: Calculation
A28: Corn Oil Going to Biodiesel (million metric tons) | B28: 0.050801438 | C28: 0.13788962 | D28: 0.25899662 | E28: 0.484428 | F28: 0.43997674 | G28: 0.47354198 | H28: 0.59238105 | I28: 0.71620956 | J28: 0.94573932 | K28: 0.79832192 | L28: 0.68764547 | P28: 1.9663213 | Q28: EIA | R28: https://www.eia.gov/biofuels/biodiesel/production/archive/
A30: ECONOMICS | B30: 2010 | C30: 2011 | D30: 2012 | E30: 2013 | F30: 2014 | G30: 2015 | H30: 2016 | I30: 2017 | J30: 2018 | K30: 2019 | L30: 2020 | M30: 2021 | N30: 2022 | O30: 2023 | P30: 2024 | Q30: Source Name | R30: Source URL | S30: Comments
A31: Corn Prices (dollars per metric ton) | B31: 207.2 | C31: 248.8 | D31: 275.6 | E31: 178.4 | F31: 148 | G31: 144.4 | H31: 134.4 | I31: 134.4 | J31: 144.4 | K31: 142.4 | L31: 181.2 | M31: 240 | N31: 261.6 | O31: 182 | P31: 169.6 | Q31: USDA-NASS | R31: https://quickstats.nass.usda.gov/results/B064DE81-3626-3F18-B562-BBF6B877613A | S31: Retrieved January 2026 1 bushel of corn=0.025 metric tons
A32: Corn Oil Price (dollars per metric ton) | B32: 866.1952 | C32: 1339.5271 | D32: 1236.5714 | E32: 1028.6757 | F32: 869.28167 | G32: 826.29158 | H32: 865.31335 | I32: 824.72078 | J32: 670.08966 | K32: 593.79603 | L32: 871.67 | M32: 1199.3868 | N32: 1416.8477 | O32: 1358.4097 | P32: 1036.1714 | Q32: USDA-ERS (Oil Crops Outlook 2018) | R32: https://www.ers.usda.gov/publications/pub-details/?pubid=86740 | S32: Retrieved April 2018 1 metric ton = 2,204.622 pounds
A33: Direct Value of All Corn Grown in the United States (billion dollars) | B33: 64.529628 | C33: 76.651242 | D33: 74.155299 | E33: 61.935222 | F33: 52.958412 | G33: 49.339261 | H33: 51.304297 | I33: 49.567854 | J33: 52.029758 | K33: 48.737123 | L33: 64.197149 | M33: 90.264369 | N33: 89.452876 | O33: 70.085591 | P33: 64.672613 | Q33: USDA-NASS | R33: https://quickstats.nass.usda.gov/results/6470F0BD-2744-3376-97E7-7B7F46D09C66 | S33: Retrieved January 2026
A34: Value of Corn Used for Starch Ethanol (billion dollars) | B34: =B19*B31/1000 -> 23.782193 | C34: =C19*C31/1000 -> 31.216569 | D34: =D19*D31/1000 -> 34.45022 | E34: =E19*E31/1000 -> 20.699426 | F34: =F19*F31/1000 -> 18.957653 | G34: =G19*G31/1000 -> 18.772325 | H34: =H19*H31/1000 -> 17.551343 | I34: =I19*I31/1000 -> 18.251362 | ... P34: =P19*P31/1000 -> 23.271571 | Q34: Calculation
A35: Value of Corn Used for Biodiesel (billion dollars) | B35: =B28*B32/1000 -> 0.044003962 | C35: =C28*C32/1000 -> 0.18470688 | D35: =D28*D32/1000 -> 0.3202678 | E35: =E28*E32/1000 -> 0.49831931 | F35: =F28*F32/1000 -> 0.38246371 | G35: =G28*G32/1000 -> 0.39128375 | H35: =H28*H32/1000 -> 0.51259523 | I35: =I28*I32/1000 -> 0.59067291 | ... P35: =P28*P32/1000 -> 2.0374459 | Q35: Calculation
A37: ENVIRONMENTAL | B37: 2010 | C37: 2011 | D37: 2012 | E37: 2013 | F37: 2014 | G37: 2015 | H37: 2016 | I37: 2017 | J37: 2018 | K37: 2019 | L37: 2020 | M37: 2021 | N37: 2022 | O37: 2023 | P37: 2024 | Q37: Source Name | R37: Source URL | S37: Comments
A38: Fertilizer Use
A39: Nitrogen (million metric tons) | B39: 5.0895233 | C39: NA | D39: NA | E39: NA | F39: 5.7309119 | G39: NA | H39: 5.5545123 | Q39: USDA | R39: https://www.ers.usda.gov/data-products/fertilizer-use-and-price.aspx | S39: Retrieved April 2018 1 short ton=0.907185 metric tons
A40: Phosphate (million metric tons) | B40: 1.7539742 | C40: NA | D40: NA | E40: NA | F40: 2.0753131 | G40: NA | H40: 1.8878973 | Q40: USDA | R40: https://www.ers.usda.gov/data-products/fertilizer-use-and-price.aspx | S40: Retrieved April 2018 1 short ton=0.907185 metric tons
A41: Potash (million metric tons) | B41: 1.8060687 | C41: NA | D41: NA | E41: NA | F41: 2.1842772 | G41: NA | H41: 2.0403951 | Q41: USDA | R41: https://www.ers.usda.gov/data-products/fertilizer-use-and-price.aspx | S41: Retrieved April 2018 1 short ton=0.907185 metric tons

Sheet SORGHUM
A1: SORGHUM
A3: PHYSICAL | B3: 2010 | C3: 2011 | D3: 2012 | E3: 2013 | F3: 2014 | G3: 2015 | H3: 2016 | I3: 2017 | J3: 2018 | K3: 2019 | L3: 2020 | M3: 2021 | N3: 2022 | O3: 2023 | P3: 2024 | Q3: Source Name | R3: Source URL | S3: Comments
A4: Number of Farms Growing Sorghum in the United States (thousand farms) | D4: 20.037 | I4: 15.339 | N4: 13.591 | Q4: USDA | R4: https://quickstats.nass.usda.gov/results/4FF74281-332C-3441-88F0-C0D86B06FC6F | S4: Retrieved January 2026
A5: Planted Acreage of Sorghum Planted in the United States (million acres) | B5: 5.369 | C5: 5.451 | D5: 6.259 | E5: 8.076 | F5: 7.138 | G5: 8.459 | H5: 6.69 | I5: 5.629 | J5: 5.69 | K5: 5.265 | L5: 5.88 | M5: 7.305 | N5: 6.325 | O5: 7.195 | P5: 6.315 | Q5: USDA-NASS | R5: https://quickstats.nass.usda.gov/results/22AB96F9-09A2-3278-8198-B3E4D37A2F10 | S5: Retrieved January 2026
A7: PRODUCTION | B7: 2010 | C7: 2011 | D7: 2012 | E7: 2013 | F7: 2014 | G7: 2015 | H7: 2016 | I7: 2017 | J7: 2018 | K7: 2019 | L7: 2020 | M7: 2021 | N7: 2022 | O7: 2023 | P7: 2024 | Q7: Source Name | R7: Source URL | S7: Comments
A8: Total Volume of Sorghum Grown in the US (million metric tons) | B8: 9.540125 | C8: 8.6366 | D8: 5.324825 | E8: 6.19355 | F8: 9.808275 | G8: 10.814375 | H8: 14.918775 | I8: 12.006525 | J8: 9.046775 | K8: 9.12465 | L8: 8.5365 | M8: 9.324 | N8: 11.19525 | O8: 4.694625 | P8: 7.943625 | Q8: USDA | R8: https://www.ers.usda.gov/data-products/feed-grains-database/feed-grains-yearbook-tables.aspx | S8: Retrieved January 2026 1 bushel of sorghum=0.025 metric tons
A9: Total Volume of Sorghum consumption (million metric tons) | B9: 5.773725 | C9: 5.19325 | D9: 3.85465 | E9: 4.72045 | F9: 4.064 | G9: 2.420625 | H9: 6.03175 | I9: 6.18445 | J9: 4.0535 | K9: 6.114625 | L9: 4.296425 | M9: 2.596075 | N9: 3.125625 | O9: 2.544775 | P9: 1.880725 | Q9: USDA | R9: https://www.ers.usda.gov/data-products/feed-grains-database/feed-grains-yearbook-tables.aspx | S9: Retrieved January 2026 1 bushel of sorghum=0.025 metric tons
A10: Sorghum imports (million metric tons) | B10: 0.000125 | C10: 0.00075 | D10: 0.002625 | E10: 0.239325 | F10: 0.00225 | G10: 0.0094 | H10: 0.114675 | I10: 0.043525 | J10: 0.05045 | K10: 0.000975 | L10: 0.00125 | M10: 0.000725 | N10: 0.000325 | O10: 0.0002 | P10: 0.000525 | Q10: USDA | R10: https://www.ers.usda.gov/data-products/feed-grains-database/feed-grains-yearbook-tables.aspx | S10: Retrieved January 2026 1 bushel of sorghum=0.025 metric tons
A11: Sorghum exports (million metric tons) | B11: 4.103325 | C11: 3.78885 | D11: 1.58525 | E11: 1.9074 | F11: 5.27455 | G11: 8.793725 | H11: 8.546125 | I11: 5.944925 | J11: 5.00885 | K11: 2.290825 | L11: 5.080475 | M11: 6.973075 | N11: 7.395975 | O11: 2.72605 | P11: 5.851575 | Q11: USDA | R11: https://www.ers.usda.gov/data-products/feed-grains-database/feed-grains-yearbook-tables.aspx | S11: Retrieved January 2026 1 bushel of sorghum=0.025 metric tons
A12: Beginning stocks (million metric tons) | B12: 1.3678 | C12: 1.031 | D12: 0.68625 | E12: 0.5738 | F12: 0.378825 | G12: 0.8508 | H12: 0.460225 | I12: 0.9158 | J12: 0.836475 | K12: 0.87135 | L12: 1.591525 | M12: 0.752375 | N12: 0.50795 | O12: 1.181925 | P12: 0.605925 | Q12: USDA | R12: https://www.ers.usda.gov/data-products/feed-grains-database/feed-grains-yearbook-tables.aspx | S12: Retrieved January 2026 1 bushel of sorghum=0.025 metric tons
A13: Ending stocks (million metric tons) | B13: 1.031 | C13: 0.68625 | D13: 0.5738 | E13: 0.378825 | F13: 0.8508 | G13: 0.460225 | H13: 0.9158 | I13: 0.836475 | J13: 0.87135 | K13: 1.591525 | L13: 0.752375 | M13: 0.50795 | N13: 1.181925 | O13: 0.605925 | P13: 0.817775 | Q13: USDA | R13: https://www.ers.usda.gov/data-products/feed-grains-database/feed-grains-yearbook-tables.aspx | S13: Retrieved January 2026 1 bushel of sorghum=0.025 metric tons
A14: Uses
A15: Total Volume of Sorghum Consumed for Feed (million metric tons) | B15: 3.523725 | C15: 3.06825 | D15: 1.72965 | E15: 2.33705 | F15: 2.316825 | G15: 2.045375 | H15: 2.60805 | I15: 3.3191 | J15: 2.543425 | K15: 3.47425 | L15: 2.417375 | M15: 2.4265 | N15: 1.9988 | O15: 1.06195 | P15: 1.273525 | Q15: USDA | R15: https://www.ers.usda.gov/data-products/feed-grains-database/feed-grains-yearbook-tables.aspx | S15: Retrieved January 2026 1 bushel of sorghum=0.025 metric tons
A16: Total Volume of Sorghum Consumed for Food, alcohol and industrial use (million metric tons): | B16: 2.231425 | C16: 2.10875 | D16: 2.10565 | E16: 2.358675 | F16: 1.72525 | G16: 0.349275 | H16: 3.403475 | I16: 2.84805 | J16: 1.49245 | K16: 2.62405 | L16: 1.860425 | M16: 0.14695 | N16: 1.10395 | O16: 1.459675 | P16: 0.587625 | Q16: USDA | R16: https://www.ers.usda.gov/data-products/feed-grains-database/feed-grains-yearbook-tables.aspx | S16: Retrieved January 2026 1 bushel of sorghum=0.025 metric tons
A17: Sorghum Saved for Seed (million metric tons) | B17: 0.018575 | C17: 0.01625 | D17: 0.01935 | E17: 0.024725 | F17: 0.021925 | G17: 0.025975 | H17: 0.020225 | I17: 0.0173 | J17: 0.017625 | K17: 0.016325 | L17: 0.018625 | M17: 0.022625 | N17: 0.022875 | O17: 0.02315 | P17: 0.019575 | Q17: USDA | R17: https://www.ers.usda.gov/data-products/feed-grains-database/feed-grains-yearbook-tables.aspx | S17: Retrieved January 2026 1 bushel of sorghum=0.025 metric tons
A18: Sorghum into Biofuels
A19: Ethanol production as percent of total Sorghum use | Q19: Calculation
A21: ECONOMICS | B21: 2010 | C21: 2011 | D21: 2012 | E21: 2013 | F21: 2014 | G21: 2015 | H21: 2016 | I21: 2017 | J21: 2018 | K21: 2019 | L21: 2020 | M21: 2021 | N21: 2022 | O21: 2023 | P21: 2024 | Q21: Source Name | R21: Source URL | S21: Comments
A22: Sorghum Prices (dollars per metric ton) | B22: 198 | C22: 236 | D22: 249 | E22: 168 | F22: 159 | G22: 130 | H22: 110 | I22: 125 | J22: 185 | K22: 188 | L22: 190 | M22: 212 | N22: 296 | O22: 296 | P22: 252 | Q22: USDA-NASS | R22: https://quickstats.nass.usda.gov/results/10684D48-7FE1-37D9-A4A7-34DDD9A43959 | S22: Retrieved January 2026 1 cwt = 0.04536 metric tons
A23: Direct Value of All Sorghum Grown in the United States (billion dollars) | B23: 1.616773 | C23: 1.259635 | D23: 1.606237 | E23: 1.716927 | F23: 1.72133 | G23: 2.064638 | H23: 1.352438 | I23: 1.168526 | J23: 1.180847 | K23: 1.125759 | L23: 1.767844 | M23: 2.666217 | N23: 1.246906 | O23: 1.556703 | P23: 1.454711 | Q23: USDA-NASS | R23: https://quickstats.nass.usda.gov/results/356755E1-3FFF-3783-93D1-9A40207DD05C | S23: Retrieved January 2026

Sheet BARLEY
A1: BARLEY
A3: PHYSICAL | B3: 2010 | C3: 2011 | D3: 2012 | E3: 2013 | F3: 2014 | G3: 2015 | H3: 2016 | I3: 2017 | J3: 2018 | K3: 2019 | L3: 2020 | M3: 2021 | N3: 2022 | O3: 2023 | P3: 2024 | Q3: Source Name | R3: Source URL | S3: Comments
A4: Number of Farms Growing Barley in the United States (thousand farms) | D4: 18.667 | I4: 11.188 | N4: 9.112 | Q4: USDA | R4: https://quickstats.nass.usda.gov/results/F560C69D-E59A-302C-8EBF-A1DD58243BD2 | S4: Retrieved January 2026
A5: Planted Acreage of barley Planted in the United States (million acres) | B5: 2.872 | C5: 2.564 | D5: 3.66 | E5: 3.528 | F5: 3.031 | G5: 3.583 | H5: 3.059 | I5: 2.486 | J5: 2.494 | K5: 2.767 | L5: 2.727 | M5: 2.707 | N5: 2.927 | O5: 3.109 | P5: 2.381 | Q5: USDA-NASS | R5: https://quickstats.nass.usda.gov/results/616E13D1-D39B-350E-9E93-142A3459195C | S5: Retrieved January 2026
A7: PRODUCTION | B7: 2010 | C7: 2011 | D7: 2012 | E7: 2013 | F7: 2014 | G7: 2015 | H7: 2016 | I7: 2017 | J7: 2018 | K7: 2019 | L7: 2020 | M7: 2021 | N7: 2022 | O7: 2023 | P7: 2024 | Q7: Source Name | R7: Source URL | S7: Comments
A8: Total Volume of barley Grown in the US (million metric tons) | B8: 4.758663 | C8: 3.785061 | D8: 3.250548 | E8: 4.59879 | F8: 4.551645 | G8: 3.812382 | H8: 4.581927 | I8: 4.198194 | J8: 3.008418 | K8: 3.176649 | L8: 3.620589 | M8: 3.58491 | N8: 2.532453 | O8: 3.65232 | P8: 3.908667 | Q8: USDA | R8: https://www.ers.usda.gov/data-products/feed-grains-database/feed-grains-yearbook-tables.aspx | S8: Retrieved January 2026 1 bushel of barley=0.021 metric tons
A9: Total Volume of barley consumption (million metric tons) | B9: 4.426212 | C9: 4.374405 | D9: 4.022823 | E9: 4.473273 | F9: 4.606602 | G9: 4.084248 | H9: 4.251156 | I9: 4.21932 | J9: 3.342969 | K9: 3.353049 | L9: 3.686445 | M9: 3.722817 | N9: 3.406368 | O9: 3.498138 | P9: 3.823176 | Q9: USDA | R9: https://www.ers.usda.gov/data-products/feed-grains-database/feed-grains-yearbook-tables.aspx | S9: Retrieved January 2026 1 bushel of barley=0.021 metric tons
A10: Barley imports (million metric tons) | B10: 0.348516 | C10: 0.199374 | D10: 0.341376 | E10: 0.48909 | F10: 0.393708 | G10: 0.494949 | H10: 0.390201 | I10: 0.202335 | J10: 0.191793 | K10: 0.123333 | L10: 0.148953 | M10: 0.136731 | N10: 0.3087 | O10: 0.492429 | P10: 0.279258 | Q10: USDA | R10: https://www.ers.usda.gov/data-products/feed-grains-database/feed-grains-yearbook-tables.aspx | S10: Retrieved January 2026 1 bushel of barley=0.021 metric tons
A11: Barley exports (million metric tons) | B11: 0.118881 | C11: 0.159138 | D11: 0.185745 | E11: 0.185997 | F11: 0.299733 | G11: 0.300279 | H11: 0.226821 | I11: 0.091875 | J11: 0.106785 | K11: 0.103551 | L11: 0.120267 | M11: 0.289359 | N11: 0.154266 | O11: 0.044688 | P11: 0.104811 | Q11: USDA | R11: https://www.ers.usda.gov/data-products/feed-grains-database/feed-grains-yearbook-tables.aspx | S11: Retrieved January 2026 1 bushel of barley=0.021 metric tons
A12: Beginning stocks (million metric tons) | B12: 1.863393 | C12: 2.425479 | D12: 1.876371 | E12: 1.259727 | F12: 1.688337 | G12: 1.727355 | H12: 1.650159 | I12: 2.14431 | J12: 2.233644 | K12: 1.984101 | L12: 1.827483 | M12: 1.790313 | N12: 1.499778 | O12: 0.780297 | P12: 1.38222 | Q12: USDA | R12: https://www.ers.usda.gov/data-products/feed-grains-database/feed-grains-yearbook-tables.aspx | S12: Retrieved January 2026 1 bushel of barley=0.021 metric tons
A13: Ending stocks (million metric tons) | B13: 2.425479 | C13: 1.876371 | D13: 1.259727 | E13: 1.688337 | F13: 1.727355 | G13: 1.650159 | H13: 2.14431 | I13: 2.233644 | J13: 1.984101 | K13: 1.827483 | L13: 1.790313 | M13: 1.499778 | N13: 0.780297 | O13: 1.38222 | P13: 1.642158 | Q13: USDA | R13: https://www.ers.usda.gov/data-products/feed-grains-database/feed-grains-yearbook-tables.aspx | S13: Retrieved January 2026 1 bushel of barley=0.021 metric tons
A14: Uses
A15: Total Volume of barley Consumed for Feed (million metric tons) | B15: 0.988029 | C15: 1.045527 | D15: 0.767823 | E15: 1.390263 | F15: 1.383627 | G15: 0.721434 | H15: 0.928074 | I15: 0.948234 | J15: 0.155925 | K15: 0.236733 | L15: 0.710115 | M15: 0.643293 | N15: 0.615384 | O15: 0.73332 | P15: 1.18251 | Q15: USDA | R15: https://www.ers.usda.gov/data-products/feed-grains-database/feed-grains-yearbook-tables.aspx | S15: Retrieved January 2026 1 bushel of barley=0.021 metric tons
A16: Total Volume of barley Consumed for Food, alcohol and industrial use (million metric tons): | B16: 3.333288 | C16: 3.228288 | D16: 3.128412 | E16: 2.961483 | F16: 3.11493 | G16: 3.23925 | H16: 3.214722 | I16: 3.183285 | J16: 3.096975 | K16: 3.01854 | L16: 2.880255 | M16: 2.983428 | N16: 2.687979 | O16: 2.655408 | P16: 2.556603 | Q16: USDA | R16: https://www.ers.usda.gov/data-products/feed-grains-database/feed-grains-yearbook-tables.aspx | S16: Retrieved January 2026 1 bushel of barley=0.021 metric tons
A17: Barley Saved for Seed (million metric tons) | B17: 0.104895 | C17: 0.10059 | D17: 0.126588 | E17: 0.121527 | F17: 0.108045 | G17: 0.123564 | H17: 0.10836 | I17: 0.087801 | J17: 0.090069 | K17: 0.097776 | L17: 0.096075 | M17: 0.096096 | N17: 0.103005 | O17: 0.10941 | P17: 0.084063 | Q17: USDA | R17: https://www.ers.usda.gov/data-products/feed-grains-database/feed-grains-yearbook-tables.aspx | S17: Retrieved January 2026 1 bushel of barley=0.021 metric tons
A19: ECONOMICS | B19: 2010 | C19: 2011 | D19: 2012 | E19: 2013 | F19: 2014 | G19: 2015 | H19: 2016 | I19: 2017 | J19: 2018 | K19: 2019 | L19: 2020 | M19: 2021 | N19: 2022 | O19: 2023 | P19: 2024 | Q19: Source Name | R19: Source URL | S19: Comments
A20: Barley Prices (dollars per metric ton) | B20: 190.47619 | C20: 228.09524 | D20: 284.7619 | E20: 298.09524 | F20: 269.04762 | G20: 249.52381 | H20: 246.19048 | I20: 222.85714 | J20: 215.2381 | K20: 223.80952 | L20: 224.28571 | M20: 239.52381 | N20: 314.28571 | O20: 350 | P20: 325.2381 | Q20: USDA-NASS | R20: https://quickstats.nass.usda.gov/results/775E91AB-2C7E-3E11-8F6F-1E6167569EC2 | S20: Retrieved January 2026 1 bushel of barley=0.021 metric tons
A21: Direct Value of All barley Grown in the United States (billion dollars) | B21: 0.691573 | C21: 0.808741 | D21: 1.371381 | E21: 1.265798 | F21: 0.914955 | G21: 1.149831 | H21: 0.949876 | I21: 0.624184 | J21: 0.688963 | K21: 0.788419 | L21: 0.787351 | M21: 0.66527 | N21: 1.160718 | O21: 1.329492 | P21: 0.899879 | Q21: USDA-NASS | R21: https://quickstats.nass.usda.gov/results/BCCC15CB-5216-3401-B519-C2BB83E644E4 | S21: Retrieved January 2026

Sheet WHEAT
A1: WHEAT
A3: PHYSICAL | B3: 2010 | C3: 2011 | D3: 2012 | E3: 2013 | F3: 2014 | G3: 2015 | H3: 2016 | I3: 2017 | J3: 2018 | K3: 2019 | L3: 2020 | M3: 2021 | N3: 2022 | O3: 2023 | P3: 2024 | Q3: Source Name | R3: Source URL | S3: Comments
A4: Number of Farms Growing Wheat in the United States (thousand farms) | D4: 147.632 | I4: 104.792 | N4: 97.014 | Q4: USDA | R4: https://quickstats.nass.usda.gov/results/924115B3-CA65-385F-877C-351EC14F9F6B | S4: Retrieved January 2026
A5: Planted Acreage of Wheat in the United States (million acres) | B5: 52.62 | C5: 54.277 | D5: 55.294 | E5: 56.236 | F5: 56.841 | G5: 54.999 | H5: 50.116 | I5: 46.052 | J5: 47.82 | K5: 45.485 | L5: 44.45 | M5: 46.74 | N5: 45.769 | O5: 49.575 | P5: 46.274 | Q5: USDA | R5: https://quickstats.nass.usda.gov/results/7539B9E8-3C98-3BA5-AB49-19F9CC39402E | S5: Retrieved January 2026
A7: PRODUCTION | B7: 2010 | C7: 2011 | D7: 2012 | E7: 2013 | F7: 2014 | G7: 2015 | H7: 2016 | I7: 2017 | J7: 2018 | K7: 2019 | L7: 2020 | M7: 2021 | N7: 2022 | O7: 2023 | P7: 2024 | Q7: Source Name | R7: Source URL | S7: Comments
A8: Total Volume of Wheat Grown in the US (million metric tons) | B8: 58.868 | C8: 54.244 | D8: 61.298 | E8: 58.105 | F8: 55.147 | G8: 56.117 | H8: 62.832 | I8: 47.38 | J8: 51.311 | K8: 52.581 | L8: 49.523 | M8: 44.804 | N8: 44.898 | O8: 49.095 | P8: 53.851 | Q8: USDA | R8: https://apps.fas.usda.gov/psdonline/app/index.html#/app/downloads | S8: Retrieved April 2018
A9: Total Volume of Wheat consumed in the US (million metric tons) | B9: 29.424 | C9: 31.993 | D9: 37.81 | E9: 34.26 | F9: 31.328 | G9: 31.943 | H9: 31.865 | I9: 29.245 | J9: 29.991 | K9: 30.437 | L9: 30.185 | M9: 30.411 | N9: 30.361 | O9: 30.18 | P9: 31.235 | Q9: USDA | R9: https://apps.fas.usda.gov/psdonline/app/index.html#/app/downloads | S9: Retrieved June 2018
A10: Wheat Imports (million metric tons) | B10: 2.638 | C10: 3.079 | D10: 3.383 | E10: 4.694 | F10: 4.116 | G10: 3.069 | H10: 3.212 | I10: 4.299 | J10: 3.662 | K10: 2.828 | L10: 2.726 | M10: 2.617 | N10: 3.309 | O10: 3.75 | P10: 4.054 | Q10: USDA | R10: https://apps.fas.usda.gov/psdonline/app/index.html#/app/downloads | S10: Retrieved June 2018
A11: Wheat Exports (million metric tons) | B11: 35.147 | C11: 28.606 | D11: 27.544 | E11: 32.012 | F11: 23.523 | G11: 21.168 | H11: 28.6 | I11: 24.658 | J11: 25.503 | K11: 26.373 | L11: 27.048 | M11: 21.656 | N11: 20.7 | O11: 19.212 | P11: 22.477 | Q11: USDA | R11: https://apps.fas.usda.gov/psdonline/app/index.html#/app/downloads | S11: Retrieved June 2018
A12: Beginning stocks (million metric tons) | B12: 26.552 | C12: 23.487 | D12: 20.211 | E12: 19.538 | F12: 16.065 | G12: 20.477 | H12: 26.552 | I12: 32.131 | J12: 29.907 | K12: 29.386 | L12: 27.985 | M12: 23.001 | N12: 18.355 | O12: 15.501 | P12: 18.954 | Q12: USDA | R12: https://apps.fas.usda.gov/psdonline/app/index.html#/app/downloads | S12: Retrieved April 2018
A13: Ending stocks (million metric tons) | B13: 23.487 | C13: 20.211 | D13: 19.538 | E13: 16.065 | F13: 20.477 | G13: 26.552 | H13: 32.131 | I13: 29.907 | J13: 29.386 | K13: 27.985 | L13: 23.001 | M13: 18.355 | N13: 15.501 | O13: 18.954 | P13: 23.147 | Q13: USDA | R13: https://apps.fas.usda.gov/psdonline/app/index.html#/app/downloads | S13: Retrieved April 2018
A15: ECONOMICS | B15: 2010 | C15: 2011 | D15: 2012 | E15: 2013 | F15: 2014 | G15: 2015 | H15: 2016 | I15: 2017 | J15: 2018 | K15: 2019 | L15: 2020 | M15: 2021 | N15: 2022 | O15: 2023 | P15: 2024 | Q15: Source Name | R15: Source URL | S15: Comments
A16: Wheat Prices (dollars per metric ton) | B16: 189.62963 | C16: 275.55556 | D16: 281.48148 | E16: 271.11111 | F16: 234.44444 | G16: 195.55556 | H16: 152.22222 | I16: 164.44444 | J16: 190.37037 | K16: 175.55556 | L16: 180 | M16: 253.33333 | N16: 344.44444 | O16: 284.07407 | P16: 214.81481 | Q16: USDA-NASS | R16: https://quickstats.nass.usda.gov/results/FDBAF890-6232-3032-8271-F98ED7B43DEE | S16: Retrieved January 2026 1 bushel of wheat=0.027 metric tons
A17: Direct Value of All wheat Grown in the United States (billion dollars) | B17: 12.579125 | C17: 14.269225 | D17: 17.383149 | E17: 14.604442 | F17: 11.914954 | G17: 10.018323 | H17: 9.17919 | I17: 8.255119 | J17: 9.66325 | K17: 8.919117 | L17: 9.345872 | M17: 12.208186 | N17: 14.213326 | O17: 12.259414 | P17: 10.928966 | Q17: USDA-NASS | R17: https://quickstats.nass.usda.gov/results/25621CF1-71CE-3AF9-9CE4-69B2C52D0D72 | S17: Retrieved January 2026
A40: Feed
A41: Fuel Alcohol
A42: High Fructose wheat Syrup
A43: Glucose and Dextrose
A44: Starch
A45: Cereal
A46: Alcoholic Beverages
A47: Seed

Sheet SOY
A1: SOY
A3: PHYSICAL | B3: 2010 | C3: 2011 | D3: 2012 | E3: 2013 | F3: 2014 | G3: 2015 | H3: 2016 | I3: 2017 | J3: 2018 | K3: 2019 | L3: 2020 | M3: 2021 | N3: 2022 | O3: 2023 | P3: 2024 | Q3: Source Name | R3: Source URL | S3: Comments
A4: Number of Farms Growing Soy in the United States (thousand farms) | D4: 302.963 | I4: 303.191 | N4: 270.851 | Q4: USDA | R4: https://quickstats.nass.usda.gov/results/110FC2E2-86FA-3DD3-9E05-1D109EDE0FFD | S4: Retrieved January 2026
A5: Acreage of Soybeans planted in the United States (million acres) | B5: 77.404 | C5: 75.046 | D5: 77.198 | E5: 76.82 | F5: 83.296 | G5: 82.66 | H5: 83.453 | I5: 90.162 | J5: 89.167 | K5: 76.1 | L5: 83.354 | M5: 87.195 | N5: 87.45 | O5: 83.6 | P5: 87.05 | Q5: USDA | R5: https://www.ers.usda.gov/data-products/oil-crops-yearbook/oil-crops-yearbook/ | S5: Retrieved January 2026
A6: Acreage of Soybeans harvested in the United States (million acres) | B6: 76.61 | C6: 73.776 | D6: 76.144 | E6: 76.233 | F6: 82.611 | G6: 81.742 | H6: 82.706 | I6: 89.542 | J6: 87.594 | K6: 74.918 | L6: 82.603 | M6: 86.292 | N6: 86.174 | O6: 82.271 | P6: 86.05 | Q6: USDA | R6: https://www.ers.usda.gov/data-products/oil-crops-yearbook/oil-crops-yearbook/ | S6: Retrieved January 2026
A7: Yield of Soy grown in the United States (metric tons per acre) | B7: 1.1740669 | C7: 1.1334829 | D7: 1.0786823 | E7: 1.1889747 | F7: 1.2838229 | G7: 1.2970448 | H7: 1.4026237 | I7: 1.3302594 | J7: 1.3649342 | K7: 1.2797844 | L7: 1.37816 | M7: 1.3968999 | N7: 1.3379939 | O7: 1.3659192 | P7: 1.3700788 | Q7: USDA | R7: https://www.ers.usda.gov/data-products/oil-crops-yearbook/oil-crops-yearbook/ | S7: Retrieved January 2026 1 bushel of soy=0.027 metric tons
A9: PRODUCTION | B9: 2010 | C9: 2011 | D9: 2012 | E9: 2013 | F9: 2014 | G9: 2015 | H9: 2016 | I9: 2017 | J9: 2018 | K9: 2019 | L9: 2020 | M9: 2021 | N9: 2022 | O9: 2023 | P9: 2024 | Q9: Source Name | R9: Source URL | S9: Comments
A10: Total Volume of Soybean Grown in the US (million metric tons) | B10: 90.745137 | C10: 89.945262 | D10: 83.623833 | E10: 82.135188 | F10: 90.639108 | G10: 106.05789 | H10: 106.02303 | I10: 116.00539 | J10: 119.11409 | K10: 119.56005 | L10: 95.87889 | M10: 113.84015 | N10: 120.54128 | O10: 115.30029 | P10: 112.37554 | Q10: USDA | R10: https://www.ers.usda.gov/data-products/oil-crops-yearbook/oil-crops-yearbook/ | S10: Retrieved January 2026 1 bushel of soy=0.027 metric tons
A11: Total volume of soy consumption (million metric tons) | B11: 50.322168 | C11: 47.969535 | D11: 48.429982 | E11: 48.163878 | F11: 49.647279 | G11: 54.547376 | H11: 54.042181 | I11: 55.27871 | J11: 58.40647 | K11: 59.449418 | L11: 61.292336 | M11: 60.801767 | N11: 62.394346 | O11: 62.790047 | P11: 65.062208 | Q11: USDA | R11: https://www.ers.usda.gov/data-products/oil-crops-yearbook/oil-crops-yearbook/ | S11: Retrieved January 2026 1 bushel of soy=0.027 metric tons
A12: Soybean Imports (million metric tons) | B12: 0.39387888 | C12: 0.39012561 | D12: 0.43556405 | E12: 1.0939412 | F12: 1.9379802 | G12: 0.89761126 | H12: 0.63560456 | I12: 0.6015791 | J12: 0.5888835 | K12: 0.3795471 | L12: 0.4152735 | M12: 0.535005 | N12: 0.4297104 | O12: 0.6617808 | P12: 0.5625477 | Q12: USDA | R12: https://www.ers.usda.gov/data-products/oil-crops-yearbook/oil-crops-yearbook/ | S12: Retrieved January 2026 1 bushel of soy=0.027 metric tons
A13: Soybean Exports (million metric tons) | B13: 40.474299 | C13: 40.634396 | D13: 36.861777 | E13: 35.843202 | F13: 44.241091 | G13: 49.745413 | H13: 52.451243 | I13: 58.496879 | J13: 57.610734 | K13: 47.34261 | L13: 45.437625 | M13: 61.175566 | N13: 58.106443 | O13: 53.447691 | P13: 45.763156 | Q13: USDA | R13: https://www.ers.usda.gov/data-products/oil-crops-yearbook/oil-crops-yearbook/ | S13: Retrieved January 2026 1 bushel of soy=0.027 metric tons
A14: Beginning stocks (million metric tons) | B14: 3.731346 | C14: 4.073895 | D14: 5.805351 | E14: 4.57299 | F14: 3.795039 | G14: 2.483757 | H14: 5.14647 | I14: 5.311683 | J14: 8.143065 | K14: 11.828835 | L14: 24.976404 | M14: 14.540607 | N14: 6.938433 | O14: 7.408638 | P14: 7.132968 | Q14: USDA | R14: https://www.ers.usda.gov/data-products/oil-crops-yearbook/oil-crops-yearbook/ | S14: Retrieved January 2026 1 bushel of soy=0.027 metric tons
A15: Ending stocks (million metric tons) | B15: 4.073895 | C15: 5.805351 | D15: 4.57299 | E15: 3.795039 | F15: 2.483757 | G15: 5.14647 | H15: 5.311683 | I15: 8.143065 | J15: 11.828835 | K15: 24.976404 | L15: 14.540607 | M15: 6.938433 | N15: 7.408638 | O15: 7.132968 | P15: 9.245691 | Q15: USDA | R15: https://www.ers.usda.gov/data-products/oil-crops-yearbook/oil-crops-yearbook/ | S15: Retrieved January 2026 1 bushel of soy=0.027 metric tons
A16: Uses
A17: Total Volume of Soy Consumed for Crush (million metric tons) | B17: 47.295529 | C17: 44.49715 | D17: 45.981513 | E17: 45.600381 | F17: 46.814976 | G17: 50.584332 | H17: 50.928394 | I17: 51.332348 | J17: 55.483164 | K17: 56.483738 | L17: 58.442963 | M17: 57.795787 | N17: 59.504549 | O17: 59.722321 | P17: 61.703186 | Q17: USDA | R17: https://www.ers.usda.gov/data-products/oil-crops-yearbook/oil-crops-yearbook/ | S17: Retrieved January 2026 1 bushel of soy=0.027 metric tons
A18: Total Volume of Soy Consumed for Seed, feed and residual (million metric tons) | B18: 3.0266383 | C18: 3.4723853 | D18: 2.4484685 | E18: 2.5634972 | F18: 2.8323029 | G18: 3.9630434 | H18: 3.1137876 | I18: 3.9463625 | J18: 2.9233062 | K18: 2.96568 | L18: 2.8493721 | M18: 3.0059802 | N18: 2.8897965 | O18: 3.0677265 | P18: 3.3590214 | Q18: USDA | R18: https://www.ers.usda.gov/data-products/oil-crops-yearbook/oil-crops-yearbook/ | S18: Retrieved January 2026 1 bushel of soy=0.027 metric tons
A19: Soy into Biofuels
A20: Soybean Oil Going to Biodiesel (million metric tons) | B20: 0.76040337 | C20: 1.2414827 | D20: 2.2108098 | E20: 2.1268952 | F20: 2.3031477 | G20: 2.2854666 | H20: 2.5719647 | I20: 2.8124096 | J20: 3.3265158 | K20: 3.9296079 | L20: 3.9271222 | M20: 4.0460451 | N20: 4.7077231 | O20: 5.6745918 | P20: 5.8917321 | Q20: USDA | R20: https://www.ers.usda.gov/data-products/us-bioenergy-statistics/us-bioenergy-statistics/ | S20: Retrieved January 2026 1 metric ton = 2,204.622 pounds
A21: Percent Soybean Oil Used for Biodiesel | B21: 0.10600782 | C21: 0.16543333 | D21: 0.26331679 | E21: 0.24958621 | F21: 0.26854149 | G21: 0.26575634 | H21: 0.28122906 | I21: 0.31216398 | J21: 0.34301393 | K21: 0.37873745 | L21: 0.38794729 | M21: 0.38261702 | N21: 0.4180388 | O21: 0.47015357 | P21: 0.47836682 | Q21: USDA | R21: https://www.ers.usda.gov/data-products/us-bioenergy-statistics/us-bioenergy-statistics/ | S21: Retrieved January 2026
A23: ECONOMICS | B23: 2010 | C23: 2011 | D23: 2012 | E23: 2013 | F23: 2014 | G23: 2015 | H23: 2016 | I23: 2017 | J23: 2018 | K23: 2019 | L23: 2020 | M23: 2021 | N23: 2022 | O23: 2023 | P23: 2024 | Q23: Source Name | R23: Source URL | S23: Comments
A24: Average Soy Price (dollar per metric tons) | B24: 355.18519 | C24: 418.51852 | D24: 462.96296 | E24: 533.33333 | F24: 481.48148 | G24: 374.07407 | H24: 331.48148 | I24: 350.74074 | J24: 345.55556 | K24: 314.07407 | L24: 317.40741 | M24: 400 | N24: 492.59259 | O24: 525.92593 | P24: 459.25926 | Q24: 368.51852 | R24: https://www.ers.usda.gov/data-products/oil-crops-yearbook/oil-crops-yearbook/ | S24: Retrieved January 2026 1 bushel of soy=0.027 metric tons
A25: Soybean Oil Price (dollars per metric ton) | B25: 792.56161 | C25: 1172.8589 | D25: 1144.1988 | E25: 1039.0383 | F25: 842.82699 | G25: 696.66055 | H25: 658.30013 | I25: 717.60446 | J25: 662.26845 | K25: 623.02618 | L25: 653.67042 | M25: 1253.7685 | N25: 1608.9331 | O25: 1438.7363 | P25: 1042.3453 | Q25: USDA-ERS (Oil Crops Outlook 2018) | R25: https://www.ers.usda.gov/publications/pub-details/?pubid=86740 | S25: Retrieved January 2026 1 metric ton = 2,204.622 pounds
A26: Direct Value of All Soy Grown in the United States (billion dollars) | B26: 37.571277 | C26: 38.542177 | D26: 43.723144 | E26: 43.582901 | F26: 39.474861 | G26: 35.195882 | H26: 40.694573 | I26: 41.30874 | J26: 37.557828 | K26: 30.518566 | L26: 45.732122 | M26: 59.140279 | N26: 60.695837 | O26: 51.555913 | P26: 44.097484 | Q26: USDA | R26: https://www.ers.usda.gov/data-products/oil-crops-yearbook/oil-crops-yearbook/ | S26: Retrieved January 2026
A27: Value of Soybeans Used for Biodiesel (billion dollars) | B27: =B25*B20/1000 -> 0.60266652 | C27: =C25*C20/1000 -> 1.456084 | D27: =D25*D20/1000 -> 2.529606 | E27: =E25*E20/1000 -> 2.2099257 | F27: =F25*F20/1000 -> 1.941155 | G27: =G25*G20/1000 -> 1.5921944 | H27: =H25*H20/1000 -> 1.6931247 | I27: =I25*I20/1000 -> 2.0181976 | ... P27: =P25*P20/1000 -> 6.1412191 | Q27: Calculation
A29: ENVIRONMENTAL | B29: 2010 | C29: 2011 | D29: 2012 | E29: 2013 | F29: 2014 | G29: 2015 | H29: 2016 | I29: 2017 | J29: 2018 | K29: 2019 | L29: 2020 | M29: 2021 | N29: 2022 | O29: 2023 | P29: 2024 | Q29: Source Name | R29: Source URL | S29: Comments
A30: Fertilizer Use
A31: Nitrogen (million metric tons) | B31: 0.10111644 | C31: 0.1514999 | D31: 0.15171724 | E31: NA | F31: NA | G31: 0.18415856 | H31: NA | Q31: USDA | R31: https://www.ers.usda.gov/data-products/fertilizer-use-and-price.aspx | S31: Retrieved April 2018 1 short ton=0.907185 metric tons
A32: Phosphate (million metric tons) | B32: 0.5006668 | C32: 0.6350295 | D32: 0.62808386 | E32: NA | F32: NA | G32: 0.75426642 | H32: NA | Q32: USDA | R32: https://www.ers.usda.gov/data-products/fertilizer-use-and-price.aspx | S32: Retrieved April 2018 1 short ton=0.907185 metric tons
A33: Potash (million metric tons) | B33: 0.70219748 | C33: 1.0369125 | D33: 1.0464284 | E33: NA | F33: NA | G33: 1.2080519 | H33: NA | Q33: USDA | R33: https://www.ers.usda.gov/data-products/fertilizer-use-and-price.aspx | S33: Retrieved April 2018 1 short ton=0.907185 metric tons
A56: Feed
A57: Fuel Alcohol
A58: High Fructose Corn Syrup
A59: Glucose and Dextrose
A60: Starch
A61: Cereal
A62: Alcoholic Beverages
A63: Seed

Sheet CANOLA
A1: CANOLA
A3: PHYSICAL | B3: 2010 | C3: 2011 | D3: 2012 | E3: 2013 | F3: 2014 | G3: 2015 | H3: 2016 | I3: 2017 | J3: 2018 | K3: 2019 | L3: 2020 | M3: 2021 | N3: 2022 | O3: 2023 | P3: 2024 | Q3: Source Name | R3: Source URL | S3: Comments
A4: Number of Farms Growing Canola in the United States (thousand farms) | D4: 3.995 | I4: 4.208 | N4: 4.058 | Q4: USDA | R4: https://quickstats.nass.usda.gov/results/D152A1E1-36F0-3C4E-889E-CC202E0A2E27 | S4: Retrieved January 2026
A5: Planted Acreage of Canola Planted in the United States (million acres) | B5: 0.82 | C5: 1.4488 | D5: 1.0615 | E5: 1.7544 | F5: 1.348 | G5: 1.715 | H5: 1.777 | I5: 1.709 | J5: 2.077 | K5: 1.9827 | L5: 2.036 | M5: 1.831 | N5: 2.1455 | O5: 2.206 | P5: 2.3445 | Q5: USDA | R5: https://www.ers.usda.gov/data-products/oil-crops-yearbook/oil-crops-yearbook/ | S5: Retrieved January 2026
A7: PRODUCTION | B7: 2010 | C7: 2011 | D7: 2012 | E7: 2013 | F7: 2014 | G7: 2015 | H7: 2016 | I7: 2017 | J7: 2018 | K7: 2019 | L7: 2020 | M7: 2021 | N7: 2022 | O7: 2023 | P7: 2024 | Q7: Source Name | R7: Source URL | S7: Comments
A8: Total Volume of Canola Grown in the U.S. (million metric tons) | B8: 0.66441322 | C8: 1.1102257 | D8: 0.69309387 | E8: 1.0848164 | F8: 0.99928922 | G8: 1.1369727 | H8: 1.3047933 | I8: 1.3966068 | J8: 1.3859111 | K8: 1.6366479 | L8: 1.5408378 | M8: 1.5869419 | N8: 1.2315263 | O8: 1.7303751 | P8: 1.8857745 | Q8: USDA | R8: https://www.ers.usda.gov/data-products/oil-crops-yearbook/oil-crops-yearbook/ | S8: Retrieved January 2026 1 metric ton = 2,204.622 pounds
A9: Total volume of Canola consumption (million metric tons) | B9: 1.1122088 | C9: 1.2900171 | D9: 1.1666399 | E9: 1.2641623 | F9: 1.6845972 | G9: 1.7354449 | H9: 1.5412284 | I9: 1.9948218 | J9: 1.7573008 | K9: 1.7177303 | L9: 1.8240732 | M9: 2.0721031 | N9: 1.6482055 | O9: 1.9209016 | P9: 2.099862 | Q9: USDA | R9: https://www.ers.usda.gov/data-products/oil-crops-yearbook/oil-crops-yearbook/ | S9: Retrieved January 2026 1 metric ton = 2,204.622 pounds
A10: Canola imports (million metric tons) | B10: 0.56798946 | C10: 0.48218677 | D10: 0.62196824 | E10: 0.39403404 | F10: 0.92739364 | G10: 0.77686287 | H10: 0.35880981 | I10: 0.69734721 | J10: 0.65144274 | K10: 0.56363236 | L10: 0.56295116 | M10: 0.44023962 | N10: 0.50313004 | O10: 0.57764746 | P10: 0.31650139 | Q10: USDA | R10: https://www.ers.usda.gov/data-products/oil-crops-yearbook/oil-crops-yearbook/ | S10: Retrieved January 2026 1 metric ton = 2,204.622 pounds
A11: Canola exports (million metric tons) | B11: 0.1770181 | C11: 0.29373134 | D11: 0.15285243 | E11: 0.17712824 | F11: 0.15948254 | G11: 0.15956182 | H11: 0.17580293 | I11: 0.11849242 | J11: 0.15353834 | K11: 0.18087925 | L11: 0.18296655 | M11: 0.15573434 | N11: 0.12873324 | O11: 0.14874604 | P11: 0.16774425 | Q11: USDA | R11: https://www.ers.usda.gov/data-products/oil-crops-yearbook/oil-crops-yearbook/ | S11: Retrieved January 2026 1 metric ton = 2,204.622 pounds
A12: Beginning stocks (million metric tons) | B12: 0.20409712 | C12: 0.12196649 | D12: 0.10190137 | E12: 0.070070969 | F12: 0.080913644 | G12: 0.12890963 | H12: 0.10944824 | I12: 0.16080988 | J12: 0.10814779 | K12: 0.087739304 | L12: 0.13834254 | M12: 0.21858486 | N12: 0.2124532 | O12: 0.10924458 | P12: 0.22082697 | Q12: USDA | R12: https://www.ers.usda.gov/data-products/oil-crops-yearbook/oil-crops-yearbook/ | S12: Retrieved January 2026 1 metric ton = 2,204.622 pounds
