Workbook

Sheet CONTENTS
A1: TABLE OF CONTENTS
A4: Bioenergy
A6: Ethanol
A7: Biobutanol
A8: Biodiesel
A9: Fats
A10: Renewable Diesel
A11: Renewable Jet Fuel
A12: Wood Pellets
A13: Waste to Energy
A14: Biogas
A15: Trade
... A26: Funding

Sheet ETHANOL
A1: ETHANOL
A3: PHYSICAL | B3: 2010 | C3: 2011 | D3: 2012 | E3: 2013 | F3: 2014 | G3: 2015 | H3: 2016 | I3: 2017 | J3: 2018 | K3: 2019 | L3: 2020 | M3: 2021 | N3: 2022 | O3: 2023 | P3: Source Name | Q3: Source URL | R3: Comments
A4: Number of Ethanol Plants installed in the United States | B4: 204 | C4: 209 | D4: 211 | E4: 210 | F4: 213 | G4: 214 | H4: 213 | I4: 209 | J4: 210 | K4: 205 | L4: 208 | M4: 208 | N4: 199 | O4: 198 | P4: RFA | Q4: http://www.ethanolrfa.org/pocket-guide/ | R4: Retrieved January 2024
A5: Number Ethanol Plants in the United States-Starch | H5: 203 | I5: 202 | J5: 204 | K5: 199 | L5: 201 | M5: 199 | N5: 195 | O5: 197 | P5: Ethanol producer RFA | Q5: [2016-2019, 2022] http://ethanolproducer.com/plants/listplants/US/Existing/Sugar-Starch/ [2020-2021] http://www.ethanolrfa.org/pocket-guide/ | R5: Retrieved January 2024
A6: Number Ethanol Plants in the United States-Cellulosic | H6: 10 | I6: 7 | J6: 6 | K6: 6 | L6: 11 | M6: 11 | N6: 8 | O6: 9 | P6: Ethanol producer RFA | Q6: [2016-2019, 2022] http://ethanolproducer.com/plants/listplants/US/Existing/Cellulosic [2020-2021] http://www.ethanolrfa.org/pocket-guide/ | R6: Retrieved January 2024
A7: Number Ethanol Plants in the United States-Corn | J7: 196 | K7: 197 | L7: 199 | M7: 198 | N7: 190 | O7: 195 | P7: Ethanol producer RFA | Q7: [2018-2019, 2022] http://ethanolproducer.com/plants/listplants/US/Existing/Cellulosic [2020-2021] http://www.ethanolrfa.org/pocket-guide/ | R7: Retrieved January 2024
A8: Number Ethanol Plants in the United States-Sorghum | J8: 13 | K8: 14 | L8: 9 | M8: 10 | N8: 12 | O8: 10 | P8: Ethanol producer RFA | Q8: [2018-2019, 2022] http://ethanolproducer.com/plants/listplants/US/Existing/Cellulosic [2020-2021] http://www.ethanolrfa.org/pocket-guide/ | R8: Retrieved January 2024
A9: Number Ethanol Plants in the United States-Other (Tobacco, crop residue, waste stream) | J9: 5 | K9: 4 | L9: 8 | M9: 9 | N9: 5 | O9: 7 | P9: Ethanol producer RFA | Q9: [2018-2019, 2022] http://ethanolproducer.com/plants/listplants/US/Existing/Cellulosic [2020-2021] http://www.ethanolrfa.org/pocket-guide/ | R9: Retrieved January 2024
A10: Number of Ethanol Plants Operational in the United States | C10: 193 | D10: 194 | E10: 192 | F10: 198 | G10: 199 | H10: 200 | I10: 201 | J10: 199 | K10: 200 | L10: 201 | M10: 197 | N10: 192 | O10: 187 | P10: EIA RFA | Q10: [2011-2012] http://www.eia.gov/petroleum/ethanolcapacity/ [2013-2021] http://www.ethanolrfa.org/pocket-guide/ | R10: Retrieved January 2024
A11: Number of Existing Plants Under Construction | E11: 7 | F11: 3 | G11: 3 | H11: 3 | I11: 7 | J11: 9 | K11: 4 | L11: 1 | M11: 5 | N11: 4 | O11: 2 | P11: RFA | Q11: http://www.ethanolrfa.org/pocket-guide/ | R11: Retrieved January 2024
A12: Number Proposed Ethanol Plants in the United States | I12: 11 | J12: 1 | K12: 1 | N12: 0 | O12: 1 | P12: Ethanol producer | Q12: http://ethanolproducer.com/plants/listplants/US/Existing/Sugar-Starch/ | R12: Retrieved January 2024
A13: Number of States which have an Ethanol Production Facility | B13: 29 | C13: 29 | D13: 29 | E13: 28 | F13: 29 | G13: 29 | H13: 28 | I13: 28 | J13: 27 | K13: 26 | L13: 25 | M13: 24 | N13: 22 | O13: 22 | P13: RFA | Q13: http://www.ethanolrfa.org/pocket-guide/ | R13: Retrieved January 2024
A14: Ethanol plant capacities (billion gallons) | B14: 14.46 | C14: 13.614 | D14: 13.728 | E14: 13.852 | F14: 13.681 | G14: 14.369 | H14: 14.903 | I14: 15.584 | J14: 16.542 | K14: 16.868 | L14: 17.378 | M14: 17.546 | N14: 17.38 | O14: 17.663 | P14: EIA EIA | Q14: [2010-2021] https://www.eia.gov/petroleum/ethanolcapacity/index.php [2022] https://www.eia.gov/biofuels/update/ | R14: Retrieved January 2024
A16: PRODUCTION | B16: 2010 | C16: 2011 | D16: 2012 | E16: 2013 | F16: 2014 | G16: 2015 | H16: 2016 | I16: 2017 | J16: 2018 | K16: 2019 | L16: 2020 | M16: 2021 | N16: 2022 | O16: 2023 | P16: Source Name | Q16: Source URL | R16: Comments
A17: Total Volume of Ethanol Produced in US (billion gallons) | B17: 13.298 | C17: 13.929 | D17: 13.218 | E17: 13.293 | F17: 14.313 | G17: 14.807 | H17: 15.413 | I17: 15.936 | J17: 16.091 | K17: 15.778 | L17: 13.941 | M17: 15.016 | N17: 15.361 | O17: 15.62 | P17: EIA | Q17: https://www.eia.gov/totalenergy/data/monthly/pdf/mer.pdf | R17: Retrieved January 2024
A18: Total Volume of Ethanol Consumed (billion gallons) | B18: 12.858 | C18: 12.893 | D18: 12.882 | E18: 13.216 | F18: 13.444 | G18: 13.947 | H18: 14.356 | I18: 15.485 | J18: 14.42 | K18: 14.552 | L18: 12.681 | M18: 13.944 | N18: 14.023 | O18: 14.249 | P18: EIA | Q18: https://www.eia.gov/totalenergy/data/monthly/pdf/sec10_7.pdf | R18: Retrieved January 2024
A19: Total Volume of Ethanol Consumed: Transportation (billion gallons) | B19: 13.420745 | C19: 13.472314 | D19: 13.472314 | E19: 13.820403 | F19: 14.091138 | G19: 14.310305 | H19: 14.735838 | I19: 14.903437 | J19: 14.86476 | K19: 14.980791 | L19: 12.943816 | M19: 14.310394 | N19: 14.400639 | O19: 14.619808 | P19: EIA | Q19: https://www.eia.gov/totalenergy/data/monthly/pdf/mer.pdf | R19: Retrieved January 2024, Table 10.2c 1 gallon of ethanol = 77566 BTUs
A20: Total Volume of Ethanol Consumed: Industrial sector (billion gallons) | B20: 0.21916683 | C20: 0.21916683 | D20: 0.21916683 | E20: 0.232059 | F20: 0.18049033 | G20: 0.232059 | H20: 0.23206044 | I20: 0.23206044 | J20: 0.23206044 | K20: 0.23206044 | L20: 0.24495269 | M20: 0.24495269 | N20: 0.24495269 | O20: 0.24495269 | P20: EIA | Q20: https://www.eia.gov/totalenergy/data/monthly/pdf/sec10_5.pdf | R20: Retrieved January 2024, Table 10.2b 1 gallon of ethanol = 77566 BTUs
A21: Total Volume of Ethanol Imported into the US (billion gallons) | B21: 0.015666 | C21: 0.171864 | D21: 0.49413 | E21: 0.376992 | F21: 0.074676 | G21: 0.091518 | H21: 0.036204 | I21: 0.076608 | J21: 0.054348 | K21: 0.195048 | L21: 0.15414 | M21: 0.060774 | N21: 0.06909 | O21: 0.027258 | P21: EIA | Q21: https://www.eia.gov/dnav/pet/hist/LeafHandler.ashx?n=PET&s=MFEIMUS1&f=A | R21: Retrieved January 2024 1 barrel of ethanol = 42 gallons
A22: Total Volume of Ethanol Exported From the US (billion gallons) | B22: 0.398496 | C22: 1.195194 | D22: 0.741552 | E22: 0.618954 | F22: 0.846258 | G22: 0.832062 | H22: 1.170288 | I22: 1.389864 | J22: 1.709568 | K22: 1.46664 | L22: 1.317204 | M22: 1.242444 | N22: 1.313592 | O22: 1.43346 | P22: EIA | Q22: https://www.eia.gov/dnav/pet/hist/LeafHandler.ashx?n=pet&s=m_epooxe_eex_nus-z00_mbbl&f=a | R22: Retrieved January 2024 1 barrel of ethanol = 42 gallons
A23: CORN FOR ETHANOL | B23: 2010 | C23: 2011 | D23: 2012 | E23: 2013 | F23: 2014 | G23: 2015 | H23: 2016 | I23: 2017 | J23: 2018 | K23: 2019 | L23: 2020 | M23: 2021 | N23: 2022 | O23: 2023 | P23: Source Name | Q23: Source URL | R23: Comments
A24: Total corn used for Fuel ethanol use (million metric tons) | B24: 125.46852 | C24: 125.0008 | D24: 116.02818 | E24: 128.09225 | F24: 130.00225 | G24: 130.59035 | H24: 135.79883 | I24: 140.12068 | J24: 134.45065 | K24: 121.41688 | L24: 125.68988 | M24: 132.99038 | N24: 129.40353 | O24: 135 | P24: USDA | Q24: https://www.ers.usda.gov/data-products/us-bioenergy-statistics/#:~:text=Ethanol%2C%20made%20mostly%20from%20corn,all%20biofuel%20production%20in%202012.&text=ERS%20analysts%20track%20U.S.%20ethanol,production%2C%20consumption%2C%20and%20trade. | R24: Retrieved January 2024 1 bushel of corn=0.025 metric tons
A26: ECONOMICS | B26: 2010 | C26: 2011 | D26: 2012 | E26: 2013 | F26: 2014 | G26: 2015 | H26: 2016 | I26: 2017 | J26: 2018 | K26: 2019 | L26: 2020 | M26: 2021 | N26: 2022 | O26: 2023 | P26: Source Name | Q26: Source URL | R26: Comments
... A28: Price for Ethanol Per gallon (dollar per gge) | B28: 2.76 | C28: 3.84 | D28: 3.75 | E28: 3.75 | F28: 3.585 | G28: 2.73 | H28: 2.325 | I28: 2.4 | J28: 1.86 | K28: 1.81 | L28: 2.66 | M28: 3.82 | N28: 3.42 | O28: 3.05 | P28: USDA | Q28: https://www.ers.usda.gov/data-products/us-bioenergy-statistics/ | R28: Retrieved January 2024 1.5 gallons ethanol = 1 gallon gasoline
A29: Price for E85 Per gallon (dollar per gge) | B29: 3.37 | C29: 4.38 | D29: 4.7075 | E29: 4.5025 | F29: 4.435 | G29: 2.95 | H29: 2.455 | I29: 2.675 | J29: 2.925 | K29: 2.905 | L29: 2.59 | M29: =(2.65+3.12+3.4+3.55)/4 -> 3.18 | N29: =(3.87+4.6+5.1+4.13)/4 -> 4.425 | O29: =(3.96+3.84+3.88+3.6)/4 -> 3.82 | P29: AFD | Q29: https://www.afdc.energy.gov/fuels/prices.html | R29: Retrieved January 2024
A30: Price for gasoline Per gallon (dollar per gge) | B30: 2.745 | C30: 3.4775 | D30: 3.65 | E30: 3.495 | F30: 3.5075 | G30: 2.4725 | H30: 2.13 | I30: 2.3625 | J30: 2.74 | K30: 2.6175 | L30: 2.225 | M30: =(2.32+2.82+3.09+3.25)/4 -> 2.87 | N30: =(3.28+4.13+4.7+4.05)/4 -> 4.04 | O30: =(3.31+3.69+3.59+3.72)/4 -> 3.5775 | P30: AFD | Q30: https://www.afdc.energy.gov/fuels/prices.html | R30: Retrieved January 2024
A31: Number of direct jobs working with ethanol production | B31: 70400 | C31: 90200 | D31: 70000 | E31: 86504 | F31: 83949 | G31: 85967 | H31: 74420 | I31: 71906 | J31: 71637 | K31: 68542 | L31: 62180 | M31: 73193 | N31: 78802 | O31: 72463 | P31: RFA | Q31: http://www.ethanolrfa.org/pocket-guide/ | R31: Retrieved January 2024
A32: Number of indirect and induced jobs working with ethanol production | B32: 329600 | C32: 311400 | D32: 295000 | E32: 300277 | F32: 295265 | G32: 271440 | H32: 264756 | I32: 285587 | J32: 294516 | K32: 277389 | L32: 242600 | M32: 334220 | N32: 342876 | O32: 322002 | P32: RFA | Q32: http://www.ethanolrfa.org/pocket-guide/ | R32: Retrieved January 2024
A33: GDP contribution/influence (billion dollars) | B33: 54 | C33: 42.4 | D33: 40.6 | E33: 44 | F33: 53 | G33: 44 | H33: 42 | I33: 45 | J33: 46 | K33: 42.8 | L33: 34.7 | M33: 52.1 | N33: 57 | O33: 54.2 | P33: RFA | Q33: http://www.ethanolrfa.org/pocket-guide/ | R33: Retrieved January 2024
A34: Household income from industry (billion dollars) | B34: 36 | C34: 29.9 | D34: 29.9 | E34: 31 | F34: 27 | G34: 24 | H34: 23 | I34: 24 | J34: 25 | K34: 22.9 | L34: 18.6 | M34: 28.7 | N34: 34.8 | O34: 32.5 | P34: RFA | Q34: http://www.ethanolrfa.org/pocket-guide/ | R34: Retrieved January 2024
A35: Tax Revenue (billion dollars) | D35: 7.9 | E35: 8.3 | F35: 10.3 | G35: 8.7 | H35: 8.5 | I35: 10.7 | J35: 8.8 | K35: 7.9 | L35: 6.3 | M35: 10.4 | N35: 12.3 | O35: 10.4 | P35: RFA | Q35: "[2013-2014] http://www.ethanolrfa.org/pocket-guide/ [2019-2021] https://ethanolrfa.org/library/reports-studies-and-white-papers/ethanol-and-the-economy" | R35: Retrieved January 2024
A36: Crude oil (dollar per barrel) | B36: 79.48 | C36: 94.88 | D36: 94.05 | E36: 97.98 | F36: 93.17 | G36: 48.66 | H36: 43.29 | I36: 50.8 | J36: 65.23 | K36: 56.99 | L36: 39.68 | M36: 68.17 | N36: 94.53 | O36: 77.64 | P36: Macrotrends | Q36: https://www.macrotrends.net/1369/crude-oil-price-history-chart | R36: Retrieved January 2024

Sheet BIOBUTANOL
A1: BIOBUTANOL
A3: PRODUCTION | B3: 2010 | C3: 2011 | D3: 2012 | E3: 2013 | F3: 2014 | G3: 2015 | H3: 2016 | I3: 2017 | J3: 2018 | K3: 2019 | L3: 2020 | M3: 2021 | N3: 2022 | O3: 2023 | P3: Source Name | Q3: Source URL | R3: Comments
A4: Total Volume of Biobutanol entering the commercial market in the US (thousand gallons) | E4: 12 | F4: 0 | G4: 0 | H4: 125 | I4: 0 | J4: 0 | K4: 0 | L4: 0.44 | M4: 0 | N4: 0 | O4: 0 | P4: EPA | Q4: https://www.epa.gov/fuels-registration-reporting-and-compliance-help/rins-generated-transactions | R4: Retrieved December 2023

Sheet BIODIESEL
A1: BIODIESEL
A3: PHYSICAL | B3: 2010 | C3: 2011 | D3: 2012 | E3: 2013 | F3: 2014 | G3: 2015 | H3: 2016 | I3: 2017 | J3: 2018 | K3: 2019 | L3: 2020 | M3: 2021 | N3: 2022 | O3: 2023 | P3: Source Name | Q3: Source URL | R3: Comments
A4: Number of Biodiesel Plants in the United States | C4: 103 | D4: 112 | E4: 115 | F4: 98 | G4: 94 | H4: 96 | I4: 95 | J4: 100 | K4: 91 | L4: 85 | M4: 75 | N4: 72 | O4: 59 | P4: EIA | Q4: https://www.eia.gov/biofuels/biodiesel/capacity/ | R4: Retrieved February 2024
A5: Number of Proposed Biodiesel Plants | H5: 6 | I5: 0 | J5: 0 | K5: 0 | M5: 9 | O5: 3 | P5: Biodiesel Magazine | Q5: http://www.biodieselmagazine.com/plants/listplants/USA/proposed/ | R5: Retrieved February 2024
A6: Number of Existing Plants Under Construction | G6: 16 | H6: 15 | I6: 10 | J6: 12 | K6: 12 | M6: 14 | O6: 3 | P6: Biodiesel Magazine | Q6: http://www.biodieselmagazine.com/plants/listplants/USA/construction/ | R6: Retrieved February 2024
A7: Number of States which have a Biodiesel Production Facility | C7: 35 | D7: 37 | E7: 38 | F7: 35 | G7: 36 | H7: 37 | I7: 36 | J7: 38 | K7: 37 | L7: 33 | M7: 32 | N7: 29 | O7: 29 | P7: EIA | Q7: https://www.eia.gov/biofuels/biodiesel/production/archive/ https://www.eia.gov/biofuels/biodiesel/capacity/ | R7: Retrieved February 2024
A8: Plant capacity (billion gallons) | K8: 2.563 | L8: 2.514 | M8: 2.409 | N8: 2.255 | O8: 2.086 | P8: EIA | Q8: https://www.eia.gov/biofuels/biodiesel/capacity/ | R8: Retrieved February 2024
A10: PRODUCTION | B10: 2010 | C10: 2011 | D10: 2012 | E10: 2013 | F10: 2014 | G10: 2015 | H10: 2016 | I10: 2017 | J10: 2018 | K10: 2019 | L10: 2020 | M10: 2021 | N10: 2022 | O10: 2023 | P10: Source Name | Q10: Source URL | R10: Comments
A11: Total Production of Biodiesel in US (billion gallons) | B11: 0.3435 | C11: 0.9675 | D11: 0.9696 | E11: 1.358 | F11: 1.268 | G11: 1.266 | H11: 1.569 | I11: 1.596 | J11: 1.857 | K11: 1.725 | L11: 1.815 | M11: 1.709 | N11: 1.622 | O11: 1.699 | P11: EIA | Q11: [2010-2019] https://www.eia.gov/biofuels/biodiesel/production/archive/ [2020-2021] https://www.eia.gov/totalenergy/data/monthly/pdf/mer.pdf | R11: Retrieved January 2024
A12: Total Volume of Biodiesel Consumed in US (billion gallons) | B12: 0.25863034 | C12: 0.88561299 | D12: 0.90128755 | E12: 1.4263855 | F12: 1.4185509 | G12: 1.4969239 | H12: 2.0847212 | I12: 1.9828363 | J12: 1.9044633 | K12: 1.813 | L12: 1.876 | M12: 1.71 | N12: 1.658 | O12: 1.939 | P12: EIA | Q12: https://www.eia.gov/totalenergy/data/monthly/pdf/sec10_5.pdf | R12: Retrieved January 2024 1 gallon of biodiesel = 127,595 BTUs
A13: Total Volume of Biodiesel Imported into the US (million gallons) | B13: 23.688 | C13: 37.38 | D13: 35.826 | E13: 342.384 | F13: 192.276 | G13: 352.758 | H13: 708.918 | I13: 393.708 | J13: 166.698 | K13: 171.276 | L13: 196.728 | M13: 210.21 | N13: 249.9 | O13: 501.018 | P13: EIA | Q13: https://www.eia.gov/totalenergy/data/monthly/pdf/sec10_8.pdf | R13: Retrieved January 2024 1 barrel of biodiesel = 42 gallons
A14: Total Volume of Biodiesel Exported from the US (million gallons) | B14: 108.696 | C14: 75.558 | D14: 128.352 | E14: 196.35 | F14: 82.908 | G14: 87.822 | H14: 88.116 | I14: 93.156 | J14: 103.74 | K14: 114.66 | L14: 145.236 | M14: 186.984 | N14: 238.182 | O14: 251.16 | P14: EIA | Q14: https://www.eia.gov/totalenergy/data/monthly/pdf/sec10_8.pdf | R14: Retrieved January 2024 1 barrel of biodiesel = 42 gallons
A15: Number of Biodiesel stations | B15: 644 | C15: 627 | D15: 675 | E15: 757 | F15: 783 | G15: 713 | H15: 716 | I15: 704 | J15: 680 | K15: 611 | L15: 712 | M15: 730 | N15: 1193 | O15: 1700 | P15: USDA | Q15: https://www.ers.usda.gov/data-products/us-bioenergy-statistics/ | R15: Retrieved January 2024
A17: ECONOMICS | B17: 2010 | C17: 2011 | D17: 2012 | E17: 2013 | F17: 2014 | G17: 2015 | H17: 2016 | I17: 2017 | J17: 2018 | K17: 2019 | L17: 2020 | M17: 2021 | N17: 2022 | O17: 2023 | P17: Source Name | Q17: Source URL | R17: Comments
A18: Price Per Gallon of Biodiesel (dollar per gallon) | B18: 3.436375 | C18: 5.1727083 | D18: 4.51625 | E18: 4.6016667 | F18: 3.455 | G18: 2.8358333 | H18: 3.2391667 | I18: 3.2725 | J18: 3.1016667 | K18: =AVERAGE(3.03, 3.11, 2.95, 2.87, 2.83, 2.8, 2.87, 2.89, 2.9, 2.93, 2.97, 3.17 ) -> 2.9433333 | L18: =AVERAGE(3.25, 3.1, 2.97, 2.71, 2.67, 2.8, 2.88, 3.12, 2.99, 3.09, 3.39, 3.51 ) -> 3.04 | M18: =AVERAGE(4.13, 4.42, 4.91, 5.41, 6.05, 5.97, 5.88, 5.56, 5.28, 5.45, 5.57, 5.45 ) -> 5.34 | N18: =AVERAGE(5.46, 5.93, 6.48, 6.78, 7.09, 6.97, 6.57, 6.71, 6.79, 6.81, 6.72, 5.87 ) -> 6.515 | O18: =AVERAGE(5.73, 5.54, 5.09, 5.12, 4.99, 5.33, 5.66, 5.65, 5.47, 4.45, 4.49, 4.56 ) -> 5.1733333 | P18: USDA | Q18: https://www.ers.usda.gov/data-products/us-bioenergy-statistics/ | R18: Retrieved February 2024
A19: Price Per Gallon of B99/100 (dollar per gge) | B19: 3.6275 | C19: 4.125 | D19: 4.2275 | E19: 4.2125 | F19: 4.18 | G19: 3.615 | H19: 3 | I19: 3.12 | J19: 3.4625 | K19: 3.535 | L19: =AVERAGE(3.65,3.44,3.08,3.26 ) -> 3.3575 | M19: =AVERAGE(3.11,3.49,3.56,3.73 ) -> 3.4725 | N19: =AVERAGE(3.88,4.96,5.48,5.15 ) -> 4.8675 | O19: =AVERAGE(5.11,4.85,4.44,4.76 ) -> 4.79 | P19: AFDC | Q19: https://www.afdc.energy.gov/fuels/prices.html | R19: Retrieved February 2024
A20: Price Per Gallon of B20 (dollar per gge) | B20: 2.8 | C20: 3.53 | D20: 3.6875 | E20: 3.6675 | F20: 3.5975 | G20: 2.635 | H20: 2.1675 | I20: 2.3025 | J20: 2.6675 | K20: 2.485 | L20: =AVERAGE(2.6,2.13,2.11,2.06 ) -> 2.225 | M20: =AVERAGE(2.18,2.53,2.74,2.96 ) -> 2.6025 | N20: =AVERAGE(3.08,4.16,4.8,4.4 ) -> 4.11 | O20: =AVERAGE(4.01,3.62,3.4,3.98 ) -> 3.7525 | P20: AFDC | Q20: https://www.afdc.energy.gov/fuels/prices.html | R20: Retrieved February 2024
A21: Price Per Gallon of Diesel (dollar per gge) | B21: 2.67 | C21: 4.1675 | D21: 3.5525 | E21: 3.535 | F21: 3.485 | G21: 2.555 | H21: 2.0725 | I21: 2.3075 | J21: 2.8025 | K21: =AVERAGE(2.65,2.75,2.71,2.74) -> 2.7125 | L21: =AVERAGE(2.71,2.33,2.2,2.13 ) -> 2.3425 | M21: =AVERAGE(2.35,2.77,2.9,3.1 ) -> 2.78 | N21: =AVERAGE(3.22,4.5,5.02,4.6 ) -> 4.335 | O21: =AVERAGE(4.08,3.78,3.45,4.02 ) -> 3.8325 | P21: AFDC | Q21: https://www.afdc.energy.gov/fuels/prices.html | R21: Retrieved February 2024
A22: Average Soy Price (dollar per metric tons) | B22: 418.51852 | C22: 462.96296 | D22: 533.33333 | E22: 481.48148 | F22: 374.07407 | G22: 331.48148 | H22: 350.74074 | I22: 345.55556 | J22: 314.07407 | K22: 329.81481 | L22: =AVERAGE(317.407,400) -> 358.7035 | M22: =AVERAGE(400,492.59259) -> 446.29629 | N22: =AVERAGE(529.62,492.59259) -> 511.10629 | O22: 529.62 | P22: USDA | Q22: https://www.ers.usda.gov/data-products/oil-crops-yearbook/oil-crops-yearbook/ | R22: Retrieved February 2024 1 bushel of soy=0.027 metric tons
A23: Number of direct jobs working with biodiesel production | F23: 49500 | G23: 49500 | H23: 61100 | I23: 62200 | J23: 72300 | K23: 67300 | L23: 70860 | M23: 63900 | N23: 63180 | O23: 66261 | P23: IRENA | Q23: https://www.irena.org/publicationsearch?keywords=jobs%20annual%20review | R23: Retrieved February 2024

Sheet FATS
A1: ANIMAL FATS AND RECYCLED GREASES
A3: PRODUCTION | B3: 2009 | C3: 2010 | D3: 2011 | E3: 2012 | F3: 2013 | G3: 2014 | H3: 2015 | I3: 2016 | J3: 2017 | K3: 2018 | L3: 2019 | M3: 2020 | N3: 2021 | O3: 2022 | P3: 2023 | Q3: Source Name | R3: Source URL | S3: Comments
A4: Production
A5: Poultry Fat (Thousand metric tons) | D5: 1004.9 | E5: 1025.2 | F5: 1040.2 | G5: 1056.5 | H5: 1088.8 | I5: 1113.3 | J5: 1095.3 | K5: 1025.6 | L5: 1133.9 | M5: 1146.5 | N5: 957.1 | O5: 918 | P5: 1039.6 | Q5: Render Magazine | R5: https://pubs.rendermagazine.com/archives/2024/2024-04.pdf | S5: Retrieved April 2024
A6: Tallow (Thousand metric tons) | D6: 2646.2 | E6: 2608.7 | F6: 2589.3 | G6: 2441.4 | H6: 2385.7 | I6: 2559.5 | J6: 2594.9 | K6: 2770.8 | L6: 2767.4 | M6: 2601.9 | N6: 2860.8 | O6: 2834.2 | P6: 2793.1 | Q6: Render Magazine | R6: https://pubs.rendermagazine.com/archives/2024/2024-04.pdf | S6: Retrieved April 2024
A7: White Grease (Thousand metric tons) | D7: 721.5 | E7: 720 | F7: 718 | G7: 707.3 | H7: 758.7 | I7: 787.6 | J7: 750.5 | K7: 736.8 | L7: 768.9 | M7: 734.2 | N7: 697.6 | O7: 745.9 | P7: 741 | Q7: Render Magazine | R7: https://pubs.rendermagazine.com/archives/2024/2024-04.pdf | S7: Retrieved April 2024
A8: Yellow Grease (Thousand metric tons) | D8: 906.4 | E8: 885.9 | F8: 896.4 | G8: 933.2 | H8: 926.4 | I8: 916.4 | J8: 913 | K8: 990.7 | L8: 1348.3 | M8: 1346 | N8: 1349.9 | O8: 1359.3 | Q8: Render Magazine | R8: https://pubs.rendermagazine.com/archives/2024/2024-04.pdf | S8: Retrieved April 2024
A9: Other fats (Thousand metric tons) | D9: 345.2 | E9: 348.6 | F9: 346.7 | G9: 333.9 | H9: 341.7 | I9: 336 | J9: 369.2 | K9: 285.9 | L9: 209.4 | M9: 207.2 | N9: 229.2 | O9: 175.6 | P9: 135.2 | Q9: Render Magazine | R9: https://pubs.rendermagazine.com/archives/2024/2024-04.pdf | S9: Retrieved April 2024
A10: Consumption for Feed & Food | B10: 2009 | C10: 2010 | D10: 2011 | E10: 2012 | F10: 2013 | G10: 2014 | H10: 2015 | I10: 2016 | J10: 2017 | K10: 2018 | L10: 2019 | M10: 2020 | N10: 2021 | O10: 2022 | P10: 2023
A11: Poultry Fat (Thousand metric tons) | D11: 896 | E11: 931.4 | F11: 952.6 | G11: 959 | H11: 983.7 | I11: 999.4 | J11: 1000.9 | K11: 979.4 | L11: 74.1 | M11: 78.5 | N11: 139.4 | O11: 73.3 | Q11: Render Magazine | R11: https://rendermagazine.com/wp-content/uploads/2019/07/Render_Apr19.pdf | S11: Retrieved January 2024
A12: Tallow (Thousand metric tons) | D12: 1792.3 | E12: 1934.5 | F12: 1990.3 | G12: 1899.6 | H12: 1846.8 | I12: 2084.4 | J12: 2116.1 | K12: 2150 | L12: 132.6 | M12: 166.9 | N12: 604.7 | O12: 794.6 | Q12: Render Magazine | R12: https://rendermagazine.com/wp-content/uploads/2019/07/Render_Apr19.pdf | S12: Retrieved January 2024
A13: White Grease (Thousand metric tons) | D13: 442.4 | E13: 526.4 | F13: 498.5 | G13: 492.5 | H13: 505.9 | I13: 534.8 | J13: 491.4 | K13: 475 | L13: 243.2 | M13: 277.6 | N13: 314.8 | O13: 300.2 | Q13: Render Magazine | R13: https://pubs.rendermagazine.com/2023-04/#p=18 | S13: Retrieved January 2024
A14: Yellow Grease (Thousand metric tons) | D14: 126.5 | E14: 146 | F14: 80.6 | G14: 123.7 | H14: 126.5 | I14: 23.1 | J14: 0 | K14: 0 | L14: 655.7 | M14: 477.6 | N14: 1535.2 | O14: 2273.1 | Q14: Render Magazine | R14: https://rendermagazine.com/wp-content/uploads/2019/07/Render_Apr19.pdf | S14: Retrieved January 2024
A15: TOTAL (Thousand metric tons) | D15: =SUM(D11:D14) -> 3257.2 | E15: =SUM(E11:E14) -> 3538.3 | F15: =SUM(F11:F14) -> 3522 | G15: =SUM(G11:G14) -> 3474.8 | H15: =SUM(H11:H14) -> 3462.9 | I15: =SUM(I11:I14) -> 3641.7 | J15: =SUM(J11:J14) -> 3608.4 | K15: =SUM(K11:K14) -> 3604.4 | ... O15: =SUM(O11:O14) -> 3441.2 | Q15: Calculation
A16: Consumtpion for Biofuels | B16: 2009 | C16: 2010 | D16: 2011 | E16: 2012 | F16: 2013 | G16: 2014 | H16: 2015 | I16: 2016 | J16: 2017 | K16: 2018 | L16: 2019 | M16: 2020 | N16: 2021 | O16: 2022 | P16: 2023
A17: Poultry Going to Biodiesel (Thousand metric tons) | B17: 61.234987 | C17: 45.35925 | D17: 108.8622 | E17: 79.83228 | F17: 73.028392 | G17: 79.83228 | H17: 89.357722 | I17: 99.79035 | J17: 72.121207 | K17: 51.255952 | L17: 73.934229 | M17: 78.471502 | N17: 139.70649 | O17: 73.481985 | P17: 76.801 | Q17: EIA | R17: https://www.eia.gov/biofuels/biodiesel/production/archive/2020/2020_09/table3.pdf Monthly Issues can be found here: https://www.eia.gov/biofuels/update/ | S17: Retrieved January 2024 1 metric ton = 2,204.622 pounds
A18: Tallow Going to Biodiesel (Thousand metric tons) | B18: 240.85762 | C18: 77.110725 | D18: 195.49837 | E18: 174.63311 | F18: 210.92051 | G18: 172.36515 | H18: 195.04477 | I18: 150.59271 | J18: 156.48941 | K18: 219.53877 | L18: 132.44659 | M18: 166.92204 | N18: 734.81985 | O18: 898.56674 | P18: 1904.018 | Q18: EIA | R18: https://www.eia.gov/biofuels/biodiesel/production/archive/2020/2020_09/table3.pdf | S18: Retrieved January 2024 1 metric ton = 2,204.622 pounds
A19: White Grease Going to Biodiesel (Thousand metric tons) | B19: 151.49989 | C19: 151.0463 | D19: 241.7648 | E19: 185.06574 | F19: 212.28129 | G19: 193.684 | H19: 267.16598 | I19: 262.17646 | J19: 268.07317 | K19: 280.32016 | L19: 243.12115 | M19: 277.59861 | N19: 315.24679 | O19: 301.18542 | P19: 270.27 | Q19: EIA | R19: https://www.eia.gov/biofuels/biodiesel/production/archive/2020/2020_09/table3.pdf | S19: Retrieved January 2024 1 metric ton = 2,204.622 pounds
A20: Yellow Grease to Biodiesel (Thousand metric tons) | B20: 70.76043 | C20: 111.58375 | D20: 213.64207 | E20: 303.90697 | F20: 474.45775 | G20: 487.15834 | H20: 568.80499 | I20: 630.03998 | J20: 667.23456 | K20: 756.59229 | L20: 655.42921 | M20: 477.6329 | N20: 1539.4929 | O20: 2272.0448 | P20: 3092.8 | Q20: EIA | R20: https://www.eia.gov/biofuels/biodiesel/production/archive/2020/2020_09/table3.pdf | S20: Retrieved January 2024 1 metric ton = 2,204.622 pounds
A21: Other fats Going to Biodiesel (Thousand metric tons) | B21: 37.648177 | C21: 37.194585 | D21: 127.0059 | E21: 152.86067 | F21: 148.32475 | G21: 97.97598 | H21: 80.739465 | I21: 31.297882 | J21: 29.02992 | K21: 100.24394 | L21: W | M21: 16.782922 | N21: 35.833807 | O21: 28.130672 | P21: 35.7 | Q21: EIA | R21: https://www.eia.gov/biofuels/biodiesel/production/archive/2020/2020_09/table3.pdf | S21: Retrieved January 2024 1 metric ton = 2,204.622 pounds
A22: TOTAL (Thousand metric tons) | B22: =SUM(B17:B21) -> 562.0011 | C22: =SUM(C17:C21) -> 422.29462 | D22: =SUM(D17:D21) -> 886.77333 | E22: =SUM(E17:E21) -> 896.29878 | F22: =SUM(F17:F21) -> 1119.0127 | G22: =SUM(G17:G21) -> 1031.0157 | H22: =SUM(H17:H21) -> 1201.1129 | I22: =SUM(I17:I21) -> 1173.8974 | ... P22: =SUM(P17:P21) -> 5379.589 | Q22: Calculation
A23: Exports | B23: 2009 | C23: 2010 | D23: 2011 | E23: 2012 | F23: 2013 | G23: 2014 | H23: 2015 | I23: 2016 | J23: 2017 | K23: 2018 | L23: 2019 | M23: 2020 | N23: 2021 | O23: 2022 | P23: 2023
A24: Poultry Fat (Thousand metric tons) | E24: 14.5 | F24: 14.9 | G24: 18.4 | H24: 16.4 | I24: 14.7 | J24: 16.1 | K24: 14.8 | L24: 12.9 | M24: 19 | N24: 17 | O24: 17 | P24: 19.2 | Q24: Render Magazine | R24: https://pubs.rendermagazine.com/archives/2024/2024-04.pdf | S24: Retrieved April 2024
A25: Tallow (Thousand metric tons) | D25: =598.4+60 -> 658.4 | E25: =486.7+75.4 -> 562.1 | F25: 453.4 | G25: 443.3 | H25: 407.9 | I25: 403.4 | J25: 402.3 | K25: 445.4 | L25: =301+121.4 -> 422.4 | M25: 299.7 | N25: 187.7 | O25: 214.6 | P25: =108.4+45.7 -> 154.1 | Q25: Render Magazine | R25: https://pubs.rendermagazine.com/archives/2024/2024-04.pdf | S25: Retrieved April 2024
A26: White Grease (Thousand metric tons) | D26: =34.8+2.5 -> 37.3 | E26: =24.8+1.4 -> 26.2 | F26: 29.9 | G26: 22 | H26: 20 | I26: 19.5 | J26: 18 | K26: 17.2 | L26: 22.5 | M26: 18.1 | N26: 81.3 | O26: 26.7 | P26: 0.107 | Q26: Render Magazine | R26: https://pubs.rendermagazine.com/archives/2024/2024-04.pdf | S26: Retrieved April 2024
A27: Yellow Grease (Thousand metric tons) | D27: 566.2 | E27: 452.1 | F27: 361 | G27: 333.1 | H27: 253 | I27: 286.2 | J27: 300.2 | K27: 360.7 | L27: 448.2 | M27: 766.3 | N27: 761.1 | O27: 489.9 | P27: 192.4 | Q27: Render Magazine | R27: https://pubs.rendermagazine.com/archives/2024/2024-04.pdf | S27: Retrieved April 2024
A28: TOTAL (Thousand metric tons) | D28: =SUM(D24:D27) -> 1261.9 | E28: =SUM(E24:E27) -> 1054.9 | F28: =SUM(F24:F27) -> 859.2 | G28: =SUM(G24:G27) -> 816.8 | H28: =SUM(H24:H27) -> 697.3 | I28: =SUM(I24:I27) -> 723.8 | J28: =SUM(J24:J27) -> 736.6 | K28: =SUM(K24:K27) -> 838.1 | ... P28: =SUM(P24:P27) -> 365.807 | Q28: Calculation
A29: Imports | B29: 2009 | C29: 2010 | D29: 2011 | E29: 2012 | F29: 2013 | G29: 2014 | H29: 2015 | I29: 2016 | J29: 2017 | K29: 2018 | L29: 2019 | M29: 2020 | N29: 2021 | O29: 2022 | P29: 2023
A30: Poultry Fat (Thousand metric tons) | E30: 0.5 | F30: 0.4 | G30: 4.4 | H30: 6.4 | I30: 5.8 | J30: 19.5 | K30: 5.69 | L30: 3.5 | M30: 2.1 | N30: 1.3 | O30: 3 | P30: 2.3 | Q30: Render Magazine | R30: https://pubs.rendermagazine.com/archives/2024/2024-04.pdf | S30: Retrieved April 2024
A31: Tallow (Thousand metric tons) | E31: 62.6 | F31: 59.5 | G31: 62.6 | H31: 64 | I31: 78.9 | J31: 99.8 | K31: 139.3 | L31: 192 | M31: 243.1 | N31: 333.3 | O31: 554.1 | P31: 795 | Q31: Render Magazine | R31: https://pubs.rendermagazine.com/archives/2024/2024-04.pdf | S31: Retrieved April 2024
A32: White Grease (Thousand metric tons) | E32: 17.7 | F32: 21.8 | G32: 20.8 | H32: 34.4 | I32: 28.8 | J32: 27 | K32: 35.8 | L32: 27.2 | M32: 23 | N32: 45.3 | O32: 70.5 | P32: 71.5 | Q32: Render Magazine | R32: https://pubs.rendermagazine.com/archives/2024/2024-04.pdf | S32: Retrieved April 2024
A33: Yellow Grease (Thousand metric tons) | E33: 16.1 | F33: 20.6 | G33: 17.2 | H33: 22.4 | I33: 23 | J33: 38.7 | K33: 62.9 | L33: 88 | M33: 83 | N33: 129.5 | O33: 395.6 | P33: 1405.6 | Q33: Render Magazine | R33: https://pubs.rendermagazine.com/archives/2024/2024-04.pdf | S33: Retrieved April 2024
A34: TOTAL (Thousand metric tons) | E34: =SUM(E30:E33) -> 96.9 | F34: =SUM(F30:F33) -> 102.3 | G34: =SUM(G30:G33) -> 105 | H34: =SUM(H30:H33) -> 127.2 | I34: =SUM(I30:I33) -> 136.5 | J34: =SUM(J30:J33) -> 185 | K34: =SUM(K30:K33) -> 243.69 | L34: =SUM(L30:L33) -> 310.7 | ... P34: =SUM(P30:P33) -> 2274.4 | Q34: Calculation
A35: Percent into Biodiesel | B35: 2009 | C35: 2010 | D35: 2011 | E35: 2012 | F35: 2013 | G35: 2014 | H35: 2015 | I35: 2016 | J35: 2017 | K35: 2018 | L35: 2019 | M35: 2020 | N35: 2021 | O35: 2022 | P35: 2023
A36: Poultry Fat (%) | D36: =D17/(D5)*100 -> 10.833138 | E36: =E17/(E5)*100 -> 7.7869957 | F36: =F17/(F5)*100 -> 7.0206107 | G36: =G17/(G5)*100 -> 7.5562972 | H36: =H17/(H5)*100 -> 8.2069914 | I36: =I17/(I5)*100 -> 8.9634734 | J36: =J17/(J5)*100 -> 6.5846076 | K36: =K17/(K5)*100 -> 4.9976553 | ... P36: =P17/(P5)*100 -> 7.3875529 | Q36: Calculation
A37: Tallow (%) | D37: =D18/(D6)*100 -> 7.3878908 | E37: =E18/(E6)*100 -> 6.6942581 | F37: =F18/(F6)*100 -> 8.1458507 | G37: =G18/(G6)*100 -> 7.0600946 | H37: =H18/(H6)*100 -> 8.1755784 | I37: =I18/(I6)*100 -> 5.8836769 | J37: =J18/(J6)*100 -> 6.0306529 | K37: =K18/(K6)*100 -> 7.923299 | ... P37: =P18/(P6)*100 -> 68.16863 | Q37: Calculation
A38: White Grease (%) | D38: =D19/(D7)*100 -> 33.508635 | E38: =E19/(E7)*100 -> 25.703575 | F38: =F19/(F7)*100 -> 29.565639 | G38: =G19/(G7)*100 -> 27.383571 | H38: =H19/(H7)*100 -> 35.213652 | I38: =I19/(I7)*100 -> 33.288022 | J38: =J19/(J7)*100 -> 35.719276 | K38: =K19/(K7)*100 -> 38.045625 | ... P38: =P19/(P7)*100 -> 36.473684 | Q38: Calculation
A39: Yellow Grease (%) | D39: =D20/(D8)*100 -> 23.570396 | E39: =E20/(E8)*100 -> 34.304885 | F39: =F20/(F8)*100 -> 52.929245 | G39: =G20/(G8)*100 -> 52.202994 | H39: =H20/(H8)*100 -> 61.399503 | I39: =I20/(I8)*100 -> 68.751635 | J39: =J20/(J8)*100 -> 73.081551 | K39: =K20/(K8)*100 -> 76.369465 | ... O39: =O20/(O8)*100 -> 167.14815 | Q39: Calculation
A41: ECONOMICS | B41: 2009 | C41: 2010 | D41: 2011 | E41: 2012 | F41: 2013 | G41: 2014 | H41: 2015 | I41: 2016 | J41: 2017 | K41: 2018 | L41: 2019 | M41: 2020 | N41: 2021 | O41: 2022 | P41: 2023 | Q41: Source Name | R41: Source URL | S41: Comments
A42: Price
...

Sheet RENEWABLE DIESEL
A1: RENEWABLE DIESEL
A3: PHYSICAL | B3: 2010 | C3: 2011 | D3: 2012 | E3: 2013 | F3: 2014 | G3: 2015 | H3: 2016 | I3: 2017 | J3: 2018 | K3: 2019 | L3: 2020 | M3: 2021 | N3: 2022 | O3: 2023 | P3: Source Name | Q3: Source URL | R3: Comments
A4: Number of Renewable Diesel Plants | M4: 6 | N4: 11 | O4: 17 | P4: EIA | Q4: https://www.eia.gov/biofuels/renewable/capacity/ | R4: Retrieved January 2024
A5: Number of States which have Renewable Diesel Plants in the United States | M5: 5 | N5: 6 | O5: 11 | P5: EIA | Q5: https://www.eia.gov/biofuels/renewable/capacity/ | R5: Retrieved January 2024
A6: Renewable Diesel plant capacities (billion gallons) | M6: 0.791 | N6: 1.75 | O6: 3 | P6: EIA | Q6: https://www.eia.gov/biofuels/renewable/capacity/ | R6: Retrieved January 2024
A8: PRODUCTION | B8: 2010 | C8: 2011 | D8: 2012 | E8: 2013 | F8: 2014 | G8: 2015 | H8: 2016 | I8: 2017 | J8: 2018 | K8: 2019 | L8: 2020 | M8: 2021 | N8: 2022 | O8: 2023 | P8: Source Name | Q8: Source URL | R8: Comments
A9: Total Production of Renewable diesel in the US (million gallons) | B9: 8.776593 | C9: 62.04129 | D9: 52.401102 | E9: 113.28586 | F9: 159.14121 | G9: 176.84762 | H9: 241.48744 | I9: 258.34213 | J9: 305.48445 | K9: 492.00796 | L9: 534 | M9: 861 | N9: 1499 | O9: 2593 | P9: EPA | Q9: https://www.epa.gov/fuels-registration-reporting-and-compliance-help/rins-generated-transactions | R9: Retrieved December 2023
A10: Total Consumption of Renewable diesel in the US (million gallons) | B10: 8.776593 | C10: 62.04129 | D10: 102.67402 | E10: 416.6854 | F10: 487.8927 | G10: 513.14457 | H10: 591.17347 | I10: 602.72382 | J10: 615.33108 | K10: 912.38458 | L10: 966 | M10: 1209 | N10: 1718 | O10: 2868 | P10: EPA | Q10: https://www.epa.gov/fuels-registration-reporting-and-compliance-help/rins-generated-transactions | R10: Retrieved December 2023
A11: Total Volume of Renewable diesel Exported from the US (million gallons) | H11: 0 | I11: 0 | J11: 0 | K11: 0 | L11: 0 | M11: 0 | N11: 0 | O11: 0 | P11: EIA | Q11: https://www.eia.gov/dnav/pet/pet_move_neti_a_EP00_IMN_mbblpd_m.htm | R11: Retrieved December 2023
A12: Total Volume of Renewable diesel Imported into the US (million gallons) | D12: 25.41 | E12: 206.682 | F12: 120.666 | G12: 204.708 | H12: 222.768 | I12: 189.378 | J12: 173.208 | K12: 258.006 | L12: 279.636 | M12: 392.28 | N12: 262.668 | O12: 362.124 | P12: EIA | Q12: https://www.eia.gov/dnav/pet/pet_move_impcus_a2_nus_EPOORDO_im0_mbbl_a.htm | R12: Retrieved December 2023

Sheet RENEWABLE JET FUEL
A1: RENEWABLE JET FUEL
A3: PRODUCTION | B3: 2010 | C3: 2011 | D3: 2012 | E3: 2013 | F3: 2014 | G3: 2015 | H3: 2016 | I3: 2017 | J3: 2018 | K3: 2019 | L3: 2020 | M3: 2021 | N3: 2022 | O3: 2023 | P3: Source Name | Q3: Source URL | R3: Comments
A4: Total production of renewable jet fuel (million gallons) | H4: 1.943717 | I4: 1.711017 | J4: 1.828178 | K4: 2.428702 | L4: 4.608399 | M4: 5.080073 | N4: 7.893137 | O4: 14.016105 | P4: EPA | Q4: https://www.epa.gov/fuels-registration-reporting-and-compliance-help/rins-generated-transactions | R4: Retrieved January 2024
A5: Total consumption of renewable jet fuel (million gallons) | H5: 1.943717 | I5: 1.711017 | J5: 1.828178 | K5: 2.428702 | L5: 4.608399 | M5: 5.080073 | N5: 15.819877 | O5: 26.300097 | P5: EPA | Q5: https://www.epa.gov/fuels-registration-reporting-and-compliance-help/rins-generated-transactions | R5: Retrieved January 2024
A6: Total consumption of jet fuel major US Airlines (million gallons) | H6: 17138 | I6: 17662 | J6: 18325 | K6: 18746 | L6: 11067 | M6: 14617 | N6: 17510 | P6: GAO | Q6: https://www.gao.gov/products/gao-23-105300 | R6: Retrieved January 2024 1L = 0.26172 gallon
A7: Airline off-take agreement (thousand gallons) | E7: 15005 | F7: 395994 | G7: 921009 | H7: 639006 | I7: 39996 | J7: 106 | K7: 255135.12 | L7: 108781.3 | M7: 2412304.6 | N7: 5683241.9 | O7: 2977690.5 | P7: ICAO | Q7: https://www.icao.int/environmental-protection/GFAAF/Pages/Offtake-Agreements.aspx#InplviewHashef347ce3-9fcc-4b72-be6a-207e60680777=ShowInGrid%3DTrue | R7: Retrieved December 2023 1 liter = 0.26172 gallons
A8: Airline off-take agreement | E8: 1 | F8: 2 | G8: 2 | H8: 6 | I8: 2 | J8: 5 | K8: 4 | L8: 5 | M8: 23 | N8: 43 | O8: 28 | P8: ICAO | Q8: https://www.icao.int/environmental-protection/GFAAF/Pages/Offtake-Agreements.aspx#InplviewHashef347ce3-9fcc-4b72-be6a-207e60680777=ShowInGrid%3DTrue | R8: Retrieved January 2024
A9: Number of Eligible Producers | D9: 1 | E9: 2 | F9: 3 | G9: 3 | H9: 3 | I9: 4 | J9: 4 | K9: 4 | L9: 5 | M9: 6 | N9: 6 | O9: 9 | P9: ICAO | Q9: https://www.icao.int/environmental-protection/GFAAF/Pages/Production-Facilities.aspx | R9: Retrieved January 2024
A10: Number of Facilities in Service | D10: 4 | E10: 5 | F10: 6 | G10: 6 | H10: 6 | I10: 7 | J10: 7 | K10: 7 | L10: 10 | M10: 11 | N10: 11 | O10: 14 | P10: ICAO | Q10: https://www.icao.int/environmental-protection/GFAAF/Pages/Production-Facilities.aspx | R10: Retrieved January 2024
A11: Number of Airports with SAF (Ongoing Delivery) | F11: 0 | G11: 0 | H11: 2 | I11: 5 | J11: 9 | K11: 11 | L11: 14 | M11: 46 | N11: 63 | O11: 79 | P11: ICAO | Q11: https://www.icao.int/environmental-protection/GFAAF/Pages/Airports.aspx | R11: Retrieved January 2024
A12: Number of Airports with SAF (Batch Delivery) | F12: 1 | G12: 1 | H12: 3 | I12: 5 | J12: 10 | K12: 15 | L12: 16 | M12: 21 | N12: 31 | O12: 43 | P12: ICAO | Q12: https://www.icao.int/environmental-protection/GFAAF/Pages/Airports.aspx | R12: Retrieved January 2024
A13: Number of States with SAF available at airports | G13: 1 | H13: 2 | I13: 2 | J13: 3 | K13: 3 | L13: 4 | M13: 5 | N13: 6 | O13: 7 | P13: 4AIR | Q13: Where to find Sustainable Aviation Fuel — 4AIR | R13: Retrieved January 2024
A14: Domestic CO2 emissions from aviation sector (Million metric tons) | B14: 288.14 | C14: 296.04 | D14: 301.89 | E14: 311.24 | F14: 321.69 | G14: 338.84 | H14: 356.18 | I14: 380.57 | J14: 395.41 | K14: 403.72 | L14: 279.79 | M14: 321.13 | N14: 347.73 | P14: IEA | Q14: https://www.iea.org/energy-system/transport/aviation#tracking | R14: Retrieved January 2025
A15: Internationa CO2 emissions form aviation sector (Million metric tons) | B15: 465.88 | C15: 479.74 | D15: 481.25 | E15: 490.26 | F15: 505.94 | G15: 534.97 | H15: 559.09 | I15: 595.24 | J15: 622.53 | K15: 632.73 | L15: 302.56 | M15: 343.88 | N15: 436.72 | P15: IEA | Q15: https://www.iea.org/energy-system/transport/aviation#tracking | R15: Retrieved January 2025

Sheet WOOD PELLETS
A1: WOOD PELLETS
A3: PHYSICAL | B3: 2010 | C3: 2011 | D3: 2012 | E3: 2013 | F3: 2014 | G3: 2015 | H3: 2016 | I3: 2017 | J3: 2018 | K3: 2019 | L3: 2020 | M3: 2021 | N3: 2022 | O3: 2023 | P3: Source Name | Q3: Source URL | R3: Comments
A4: Total Operational Capacity of Pellet Mill Facilities (million metric tons) | G4: 9.4225 | H4: 11.158927 | I4: 13.019865 | J4: 12.355042 | K4: 13.0586 | L4: 13.99425 | M4: 13.3658 | N4: 12.8441 | O4: 13.9023 | P4: Biomass Industry Directory | Q4: Biomass Industry Directory, published by BBI International | R4: Retrieved January 2024
A5: Number of WP Plants in the United States | E5: 123 | F5: 122 | G5: 137 | H5: 147 | I5: 148 | J5: 140 | K5: 126 | L5: 124 | M5: 116 | N5: 123 | O5: 118 | P5: Biomass Industry Directory | Q5: Biomass Industry Directory, published by BBI International | R5: Retrieved January 2024
A6: Number of Proposed WP Plants | E6: 11 | F6: 15 | G6: 22 | H6: 18 | I6: 7 | J6: 0 | K6: 3 | L6: 1 | M6: 3 | N6: 3 | O6: 5 | P6: Biomass Industry Directory | Q6: Biomass Industry Directory, published by BBI International | R6: Retrieved January 2024
A7: Number of Existing Plants Under Construction | E7: 7 | F7: 9 | G7: 9 | H7: 11 | I7: 4 | J7: 4 | K7: 2 | L7: 5 | M7: 4 | N7: 4 | O7: 1 | P7: Biomass Industry Directory | Q7: Biomass Industry Directory, published by BBI International | R7: Retrieved January 2024
A8: Number of Existing Plants that Were Put on Standby | H8: 13 | I8: 11 | J8: 6 | K8: 0 | L8: 5 | M8: 1 | N8: 1 | O8: 1 | P8: Biomass Industry Directory | Q8: Biomass Industry Directory, published by BBI International | R8: Retrieved January 2024
A9: Number of States which have an WP Production Facility | E9: 36 | F9: 36 | G9: 36 | H9: 38 | I9: 37 | J9: 40 | K9: 38 | L9: 37 | M9: 36 | N9: 36 | O9: 35 | P9: Biomass Industry Directory | Q9: Biomass Industry Directory, published by BBI International | R9: Retrieved January 2024
A11: PRODUCTION + CONSUMPTION | B11: 2010 | C11: 2011 | D11: 2012 | E11: 2013 | F11: 2014 | G11: 2015 | H11: 2016 | I11: 2017 | J11: 2018 | K11: 2019 | L11: 2020 | M11: 2021 | N11: 2022 | O11: 2023 | P11: Source Name | Q11: Source URL | R11: Comments
A12: Wood pellets Production (million metric tons) | D12: 3.474 | E12: 4.704 | F12: 5.947 | G12: 6.517 | H12: 6.393 | I12: 6.9 | J12: 7.468361 | K12: 8.592713 | L12: 8.412359 | M12: 8.4486 | N12: 9.544 | O12: 9.820703 | P12: FAOSTAT | Q12: http://www.fao.org/faostat/en/#data/FO | R12: Retrieved January 2024
A13: Wood pellets Imports (million metric tons) | D13: 0.086 | E13: 0.152442 | F13: 0.219987 | G13: 0.207 | H13: 0.204847 | I13: 0.211617 | J13: 0.221 | K13: 0.211615 | L13: 0.204958 | M13: 0.195951 | N13: 0.19442 | O13: 0.17687225 | P13: FAOSTAT | Q13: http://www.fao.org/faostat/en/#data/FO | R13: Retrieved January 2024
A14: Wood pellets Exports (million metric tons) | D14: 1.898125 | E14: 2.882517 | F14: 4.005057 | G14: 4.669 | H14: 4.709 | I14: 5.203981 | J14: 6.017 | K14: 6.858462 | L14: 7.25686 | M14: 7.52255 | N14: 8.97716 | O14: 9.54 | P14: FAOSTAT | Q14: http://www.fao.org/faostat/en/#data/FO | R14: Retrieved January 2024
A15: Wood pellets Consumption (million metric tons) | D15: =+D12+D13-D14 -> 1.661875 | E15: =+E12+E13-E14 -> 1.973925 | F15: =+F12+F13-F14 -> 2.16193 | G15: =+G12+G13-G14 -> 2.055 | H15: =+H12+H13-H14 -> 1.888847 | I15: =+I12+I13-I14 -> 1.907636 | J15: =+J12+J13-J14 -> 1.672361 | K15: =+K12+K13-K14 -> 1.945866 | ... O15: =+O12+O13-O14 -> 0.45757525 | P15: Estimation
A16: Electricity Net Generation from Wood (trillion BTUs) | B16: 126.83607 | C16: 127.78123 | D16: 128.97548 | E16: 136.58114 | F16: 144.47001 | G16: 143.06762 | H16: 139.7169 | I16: 140.41639 | J16: 139.9148 | K16: =38543*3412.14/1000000 -> 131.51411 | L16: 123.5843 | M16: 124.41686 | N16: 121.00813 | O16: 107.27427 | P16: EIA | Q16: https://www.eia.gov/totalenergy/data/monthly/pdf/mer.pdf | R16: Retrieved January 2024 1 kwh= 3412.14 BTUs
A17: Industrial Sector | B17: 87.712471 | C17: 91.073429 | D17: 91.189442 | E17: 94.485569 | F17: 92.943281 | G17: 93.212841 | H17: 93.69054 | I17: 93.629122 | J17: 93.983984 | K17: =26433*3412.14/1000000 -> 90.193097 | L17: =24916*3412.14/1000000 -> 85.01688 | M17: =24413*3412.14/1000000 -> 83.300574 | N17: =23287*3412.14/1000000 -> 79.458504 | O17: 74.336882 | P17: EIA | Q17: https://www.eia.gov/totalenergy/data/monthly/pdf/mer.pdf | R17: Retrieved January 2024 1 kwh= 3412.14 BTUs
A18: Electric Power Sector | B18: 39.055354 | C18: 36.622499 | D18: 37.704147 | E18: 41.976146 | F18: 51.274228 | G18: 49.690995 | H18: 45.790919 | I18: 46.545002 | J18: 45.671494 | K18: =12020*3412.14/1000000 -> 41.013923 | L18: 38.253502 | M18: 40.59423 | N18: 40.952504 | O18: 32.568876 | P18: EIA | Q18: https://www.eia.gov/totalenergy/data/monthly/pdf/mer.pdf | R18: Retrieved January 2024 1 kwh= 3412.14 BTUs
A19: Heating from Wood in the US (trillion BTUs) | B19: =+B20-B16 -> 2090.1639 | C19: =+C20-C16 -> 2085.2188 | D19: =+D20-D16 -> 2022.0245 | E19: =+E20-E16 -> 2201.4189 | F19: =+F20-F16 -> 2256.53 | G19: =+G20-G16 -> 2168.9324 | H19: =+H20-H16 -> 2090.2831 | I19: =+I20-I16 -> 2144.5836 | ... O19: =+O20-O16 -> 1810.7257 | P19: Estimation
A20: Energy Consumption from Wood in US (trillion BTUs) | B20: 2217 | C20: 2213 | D20: 2151 | E20: 2338 | F20: 2401 | G20: 2312 | H20: 2230 | I20: 2285 | J20: 2359 | K20: 2237 | L20: 1970 | M20: 1989 | N20: 2012 | O20: 1918 | P20: EIA | Q20: https://www.eia.gov/totalenergy/data/monthly/pdf/mer.pdf | R20: Retrieved April 2024
A21: Residential Sector | B21: 541 | C21: 524 | D21: 438 | E21: 572 | F21: 579 | G21: 513 | H21: 448 | I21: 433 | J21: 525 | K21: 546 | L21: 345 | M21: 344 | N21: 422 | O21: 450 | P21: EIA | Q21: https://www.eia.gov/totalenergy/data/monthly/pdf/mer.pdf | R21: Retrieved April 2024
A22: Commercial Sector | B22: 72 | C22: 69 | D22: 61 | E22: 70 | F22: 76 | G22: 79 | H22: 84 | I22: 84 | J22: 84 | K22: 84 | L22: 83 | M22: 83 | N22: 83 | O22: 82 | P22: EIA | Q22: https://www.eia.gov/totalenergy/data/monthly/pdf/mer.pdf | R22: Retrieved April 2024
A23: Industrial Sector | B23: 1409 | C23: 1438 | D23: 1462 | E23: 1489 | F23: 1495 | G23: 1476 | H23: 1474 | I23: 1539 | J23: 1537 | K23: 1413 | L23: 1356 | M23: 1366 | N23: 1308 | O23: 1224 | P23: EIA | Q23: https://www.eia.gov/totalenergy/data/monthly/pdf/mer.pdf | R23: Retrieved April 2024
A24: Electric Power Sector | B24: 196 | C24: 182 | D24: 190 | E24: 207 | F24: 251 | G24: 244 | H24: 224 | I24: 229 | J24: 221 | K24: 201 | L24: 185 | M24: 199 | N24: 198 | O24: 162 | P24: EIA | Q24: https://www.eia.gov/totalenergy/data/monthly/pdf/mer.pdf | R24: Retrieved April 2024
A25: Wood pellet production worldwide (million metric tons) | B25: 15.7 | C25: 18.3 | D25: 18.053589 | E25: 21.19902 | F25: 25.093777 | G25: 27.381663 | H25: 29.304248 | I25: 33.410286 | J25: 37.627758 | K25: 41.975705 | L25: 42.988148 | M25: 44.971052 | N25: 48.070887 | O25: 49.94409 | P25: Hawkins Wright; REN21; FAO | Q25: [2010-2011] http://task32.ieabioenergy.com/wp-content/uploads/2017/03/03-Fiona_Matthews.pdf [2012-2018] http://www.fao.org/faostat/en/#data/FO | R25: Retrieved April 2024
A26: Average Annual Densified Biomass Capacity (million metric tons) | H26: 10.003977 | I26: 10.867589 | J26: 10.730605 | K26: 10.806215 | L26: 12.010147 | M26: 12.96185 | N26: 13.244444 | O26: 13.26499 | P26: EIA | Q26: http://www.eia.gov/biofuels/biomass/ | R26: Retrieved April 2024
A27: Wood Pellets Exported from US (in million $) | D27: 258.234 | E27: 370.981 | F27: 519.399 | G27: 682.978 | H27: 612.496 | I27: 666.545 | J27: 809.855 | K27: 942.627 | L27: 981.593 | M27: 1059.261 | N27: 1545.409 | O27: 1753.4892 | P27: FAOSTAT | Q27: http://www.fao.org/faostat/en/#data/FO | R27: Retrieved April 2024
A28: Wood Pellets Imported from US (in million $) | D28: 18.348 | E28: 30.262 | F28: 44.906 | G28: 45.782 | H28: 34.745 | I28: 41.134 | J28: 41.139 | K28: 42.323 | L28: 42.118 | M28: 42.997 | N28: 46.788 | O28: 50.057676 | P28: FAOSTAT | Q28: http://www.fao.org/faostat/en/#data/FO | R28: Retrieved April 2024
O29: =+O14/30.18505982 -> 0.31605039
A30: ECONOMICS | B30: 2010 | C30: 2011 | D30: 2012 | E30: 2013 | F30: 2014 | G30: 2015 | H30: 2016 | I30: 2017 | J30: 2018 | K30: 2019 | L30: 2020 | M30: 2021 | N30: 2022 | O30: 2023 | P30: Source Name | Q30: Source URL | R30: Comments
A31: Total Jobs Created in the Wood Pellet Industry | B31: 26549 | C31: 25477 | D31: 25484 | E31: 25085 | F31: 26895 | G31: 23416 | H31: 23596 | I31: 24432 | J31: 25040 | K31: 24738 | L31: 24306 | M31: 25517 | N31: 26939 | O31: 27349 | P31: NAICS | Q31: https://data.bls.gov/cew/apps/data_views/data_views.htm#tab=Tables | R31: Retrieved January 2024

Sheet WASTE TO ENERGY
A1: WASTE TO ENERGY
A3: PHYSICAL | B3: 2010 | C3: 2011 | D3: 2012 | E3: 2013 | F3: 2014 | G3: 2015 | H3: 2016 | I3: 2017 | J3: 2018 | K3: 2019 | L3: 2020 | M3: 2021 | N3: 2022 | O3: 2023 | P3: Source Name | Q3: Source URL | R3: Comments
A4: Number of WTE Plants in the United States | B4: 86 | C4: 85 | D4: 85 | E4: 84 | F4: 84 | G4: 78 | H4: 77 | I4: 76 | J4: 75 | K4: 75 | L4: 64 | M4: 98 | N4: 60 | O4: 61 | P4: EIA | Q4: https://www.eia.gov/electricity/data/eia860m/ | R4: Retrieved February 2024
A5: Number of WTE Plants Proposed in US | B5: 2 | C5: 0 | D5: 2 | E5: 2 | F5: 1 | G5: 0 | H5: 0 | I5: 0 | J5: 0 | K5: 0 | L5: 1 | M5: 2 | N5: 2 | O5: 3 | P5: EIA | Q5: https://www.eia.gov/electricity/data/eia860m/ | R5: Retrieved February 2024
A6: Number of WTE Existing Plants that Were Put on Standby | B6: 2 | C6: 2 | D6: 2 | E6: 2 | F6: 2 | G6: 2 | H6: 1 | I6: 1 | J6: 1 | K6: 0 | L6: 2 | M6: 2 | N6: 0 | O6: 0 | P6: EIA | Q6: https://www.eia.gov/electricity/data/eia860m/ | R6: Retrieved February 2024
A7: Number of WTE Existing Plants that Were Closed-Shut Down | B7: 11 | C7: 10 | D7: 11 | E7: 13 | F7: 8 | G7: 9 | H7: 11 | I7: 11 | J7: 20 | K7: 16 | L7: 11 | M7: 13 | N7: 2 | O7: 0 | P7: EIA | Q7: https://www.eia.gov/electricity/data/eia860m/ | R7: Retrieved February 2024
A8: Number of WTE Fuel Switching Plants in US | B8: 20 | C8: 20 | D8: 16 | E8: 13 | F8: 15 | G8: 15 | H8: 15 | I8: 10 | J8: 16 | K8: 13 | L8: 14 | M8: 13 | N8: 14 | O8: 14 | P8: EIA | Q8: https://www.eia.gov/electricity/data/eia860m/ | R8: Retrieved February 2024
A9: Number of States which have an WTE Fuel Switching Production Facility | B9: 9 | C9: 9 | D9: 7 | E9: 5 | F9: 7 | G9: 7 | H9: 7 | I9: 8 | J9: 6 | K9: 6 | L9: 8 | M9: 8 | N9: 8 | O9: 8 | P9: EIA | Q9: https://www.eia.gov/electricity/data/eia860m/ | R9: Retrieved February 2024
A11: PRODUCTION | B11: 2010 | C11: 2011 | D11: 2012 | E11: 2013 | F11: 2014 | G11: 2015 | H11: 2016 | I11: 2017 | J11: 2018 | K11: 2019 | L11: 2020 | M11: 2021 | N11: 2022 | O11: 2023 | P11: Source Name | Q11: Source URL | R11: Comments
A12: Municipal solid waste generation in the United States (million metric tons) | B12: =+SUM(B13:B15) -> 251.05 | C12: =+SUM(C13:C15) -> 250.5 | D12: =+SUM(D13:D15) -> 251.84 | E12: =+SUM(E13:E15) -> 255.02 | F12: =+SUM(F13:F15) -> 258.95 | G12: =+SUM(G13:G15) -> 262.11 | H12: =+SUM(H13:H15) -> 266.78 | I12: 268.7 | J12: 292.4 | P12: EPA | Q12: [2010-2018]https://www.epa.gov/facts-and-figures-about-materials-waste-and-recycling/advancing-sustainable-materials-management | R12: Retrieved February 2024 1 ton = 0.9072 metric tons
A13: Recycled and composted | B13: =65.26+20.17 -> 85.43 | C13: 87 | D13: 86.89 | E13: 87.56 | F13: 89.57 | G13: =67.56+23.39 -> 90.95 | H13: 93.7 | I13: =67.18+26.99 -> 94.17 | J13: 93.9 | P13: EPA | Q13: [2010-2018]https://www.epa.gov/facts-and-figures-about-materials-waste-and-recycling/advancing-sustainable-materials-management | R13: Retrieved February 2024 1 ton = 0.9072 metric tons
A14: Combusted with Energy recovery | B14: 29.31 | C14: 31.8 | D14: 32.5 | E14: 33.16 | F14: 33.21 | G14: 33.55 | H14: 33.9 | I14: 34.03 | J14: 34.55 | P14: EPA | Q14: [2010-2018]https://www.epa.gov/facts-and-figures-about-materials-waste-and-recycling/advancing-sustainable-materials-management | R14: Retrieved February 2024 1 ton = 0.9072 metric tons
A15: Landfilled | B15: 136.31 | C15: 131.7 | D15: 132.45 | E15: 134.3 | F15: 136.17 | G15: 137.61 | H15: 139.18 | I15: 139.59 | J15: 146.12 | P15: EPA | Q15: [2010-2018]https://www.epa.gov/facts-and-figures-about-materials-waste-and-recycling/advancing-sustainable-materials-management | R15: Retrieved February 2024 1 ton = 0.9072 metric tons
A16: Biogenic Municipal Solid Waste: Consumption for Electricity Generation (million metric tons) | B16: 17.633246 | C16: 15.396998 | D16: 16.968 | E16: 17.007 | F16: 16.706 | G16: 16.631 | H16: 16.994 | I16: 16.348 | J16: 16.783 | K16: 15.559 | L16: 15.516 | M16: 15.223 | N16: 14.589 | O16: 13.86 | P16: EIA | Q16: http://www.eia.gov/electricity/annual/html/epa_05_07_a.html | R16: Retrieved April 2024 1 ton = 0.9072 metric tons
A17: Biogenic Municipal Solid Waste: Consumption for Heating Generation (million metric tons) | B17: 2.0747664 | C17: 1.8180288 | D17: 1.986 | E17: 1.865 | F17: 1.955 | G17: 1.986 | H17: 2.232 | I17: 2.124 | J17: 2.05 | K17: 1.667 | L17: 1.65 | M17: 1.712 | N17: 1.647 | O17: 1.543 | P17: EIA | Q17: http://www.eia.gov/electricity/annual/html/epa_05_07_b.html | R17: Retrieved April 2024 1 ton = 0.9072 metric tons
A18: Biogenic Municipal Solid Waste: Consumption for Energy Generation (million metric tons) | B18: 19.70892 | C18: 17.251315 | D18: 18.954 | E18: 18.871 | F18: 18.661 | G18: 18.617 | H18: 19.226 | I18: 18.473 | J18: 18.833 | K18: 17.225 | L18: 17.166 | M18: 16.934 | N18: 16.236 | O18: 15.403 | P18: EIA | Q18: http://www.eia.gov/electricity/annual/html/epa_05_07_c.html | R18: Retrieved April 2024 1 ton = 0.9072 metric tons
A19: Electric utilities | B19: 0.3646944 | C19: 0.3519936 | D19: 0.418 | E19: 0.456 | F19: 0.444 | G19: 0.452 | H19: 0.464 | I19: 0.422 | J19: 0.467 | K19: 0.297 | L19: 0.28 | M19: 0.252 | N19: 0.274 | O19: 0.283 | P19: EIA | Q19: http://www.eia.gov/electricity/annual/html/epa_05_07_c.html | R19: Retrieved April 2024 1 ton = 0.9072 metric tons
A20: Independent power producers | B20: 15.985771 | C20: 13.940942 | D20: 14.757 | E20: 14.574 | F20: 14.459 | G20: 14.452 | H20: 14.838 | I20: 14.195 | J20: 14.611 | K20: 13.684 | L20: 13.732 | M20: 13.315 | N20: 7.747 | O20: 7.39 | P20: EIA | Q20: http://www.eia.gov/electricity/annual/html/epa_05_07_c.html | R20: Retrieved April 2024 1 ton = 0.9072 metric tons
A21: Commercial sector | B21: 3.2196528 | C21: 2.8150416 | D21: 3.577 | E21: 3.646 | F21: 3.551 | G21: 3.502 | H21: 3.7 | I21: 3.639 | J21: 3.557 | K21: 3.047 | L21: 2.956 | M21: 3.187 | N21: 8.215 | O21: 7.73 | P21: EIA | Q21: http://www.eia.gov/electricity/annual/html/epa_05_07_c.html | R21: Retrieved April 2024 1 ton = 0.9072 metric tons
A22: Industrial Sector | B22: 0.1378944 | C22: 0.1433376 | D22: 0.203 | E22: 0.195 | F22: 0.206 | G22: 0.211 | H22: 0.224 | I22: 0.216 | J22: 0.197 | K22: 0.197 | L22: 0.198 | M22: 0.18 | N22: 0 | O22: 0 | P22: EIA | Q22: http://www.eia.gov/electricity/annual/html/epa_05_07_c.html | R22: Retrieved April 2024 1 ton = 0.9072 metric tons
A23: Biogenic Municipal Solid Waste: Consumption for Electricity Generation (Trillion BTUs) | B23: 144.934 | C23: 135.241 | D23: 135.735 | E23: 135.764 | F23: 134.408 | G23: 133.117 | H23: 135.957 | I23: 130.942 | J23: 134.465 | K23: 115.114 | L23: 114.814 | M23: 113.173 | N23: 108.508 | O23: 103.306 | P23: EIA | Q23: http://www.eia.gov/electricity/annual/html/epa_05_07_d.html | R23: Retrieved February 2024
A24: Biogenic Municipal Solid Waste: Consumption for Heating Generation (Trillion BTUs) | B24: 17.502 | C24: 16.766 | D24: 16.31 | E24: 15.168 | F24: 15.783 | G24: 16.623 | H24: 18.259 | I24: 17.72 | J24: 16.724 | K24: 12.308 | L24: 11.939 | M24: 12.721 | N24: 12.244 | O24: 12.535 | P24: EIA | Q24: http://www.eia.gov/electricity/annual/html/epa_05_07_e.html | R24: Retrieved February 2024
A25: Biogenic Municipal Solid Waste: Consumption for Energy Generation (Trillion BTUs) | B25: 162.436 | D25: 152.045 | E25: 150.932 | F25: 150.191 | G25: 149.74 | H25: 154.216 | I25: 148.662 | J25: 151.188 | K25: 127.422 | L25: 126.752 | M25: 125.894 | N25: 120.753 | O25: 115.841 | P25: EIA | Q25: http://www.eia.gov/electricity/annual/html/epa_05_07_f.html | R25: Retrieved February 2024
A26: Electric utilities | B26: 3.322 | C26: 3.433 | D26: 3.91 | E26: 4.459 | F26: 4.429 | G26: 4.295 | H26: 4.434 | I26: 4.172 | J26: 4.568 | K26: 2.454 | L26: 2.284 | M26: 2.029 | N26: 2.212 | O26: 2.275 | P26: EIA | Q26: http://www.eia.gov/electricity/annual/html/epa_05_07_f.html | R26: Retrieved February 2024
A27: Independent power producers | B27: 130.467 | C27: 121.648 | D27: 117.598 | E27: 115.574 | F27: 115.709 | G27: 114.886 | H27: 17.88 | I27: 112.857 | J27: 116.339 | K27: 101 | L27: 101.362 | M27: 98.516 | N27: 57.217 | O27: 54.557 | P27: EIA | Q27: http://www.eia.gov/electricity/annual/html/epa_05_07_f.html | R27: Retrieved February 2024
A28: Commercial sector | B28: 27.509 | C28: 25.664 | D28: 28.923 | E28: 29.342 | F28: 28.411 | G28: 28.821 | H28: 30.095 | I28: 29.794 | J28: 28.686 | K28: 22.473 | L28: 21.629 | M28: 23.994 | N28: 61.324 | O28: 59.009 | P28: EIA | Q28: http://www.eia.gov/electricity/annual/html/epa_05_07_f.html | R28: Retrieved February 2024
A29: Industrial Sector | B29: 1.138 | C29: 1.262 | D29: 1.614 | E29: 1.557 | F29: 1.643 | G29: 1.739 | H29: 1.806 | I29: 1.839 | J29: 1.596 | K29: 1.495 | L29: 1.478 | M29: 1.355 | N29: 0 | O29: 0 | P29: EIA | Q29: http://www.eia.gov/electricity/annual/html/epa_05_07_f.html | R29: Retrieved February 2024
A31: ECONOMICS | B31: 2010 | C31: 2011 | D31: 2012 | E31: 2013 | F31: 2014 | G31: 2015 | H31: 2016 | I31: 2017 | J31: 2018 | K31: 2019 | L31: 2020 | M31: 2021 | N31: 2022 | O31: 2023 | P31: Source Name | Q31: Source URL | R31: Comments
A32: Revenue from waste electricity generation in the U.S. (million dollars) | C32: 640 | D32: 290 | E32: 550 | F32: 348 | G32: 524 | H32: 227 | I32: 142 | J32: 54 | K32: 57 | L32: 54 | M32: 55 | N32: 55 | P32: AEE | Q32: https://info.aee.net/hubfs/Market%20Report%202019/AEN%202019%20Market%20Report.pdf | R32: Retrieved February 2024
A33: Jobs in WTE Facilities | E33: 5350 | F33: 4753 | H33: 4640 | J33: 4600 | K33: 7000 | P33: ERC | Q33: [domain expired]http://energyrecoverycouncil.org/wp-content/uploads/2019/10/ERC-2018-directory.pdf | R33: Retrieved February 2024
A34: Total jobs (direct, indirect, and induced) created by WTE | E34: =+E33+8557 -> 13907 | F34: 13878 | H34: 13756 | J34: 13601 | P34: ERC | Q34: [domain expired]http://energyrecoverycouncil.org/wp-content/uploads/2019/10/ERC-2018-directory.pdf | R34: Retrieved February 2024
A35: Total Economic output by WTE (million dollars) | E35: 5600 | F35: 5561 | H35: 5576.2 | J35: 5567 | P35: ERC | Q35: [domain expired]http://energyrecoverycouncil.org/wp-content/uploads/2019/10/ERC-2018-directory.pdf | R35: Retrieved February 2024

Sheet BIOGAS
A1: BIOGAS
A3: PHYSICAL | B3: 2010 | C3: 2011 | D3: 2012 | E3: 2013 | F3: 2014 | G3: 2015 | H3: 2016 | I3: 2017 | J3: 2018 | K3: 2019 | L3: 2020 | M3: 2021 | N3: 2022 | O3: 2023 | P3: Source Name | Q3: Source URL | R3: Comments
A4: Number of anaerobic digestion (AD) Plants | B4: 133 | C4: 158 | D4: 183 | E4: 209 | F4: 218 | G4: 225 | H4: 229 | I4: 234 | J4: 245 | K4: 257 | L4: 282 | M4: 341 | N4: 400 | O4: 429 | P4: EPA | Q4: https://www.epa.gov/agstar/livestock-anaerobic-digester-database | R4: Retrieved February 2024
A5: Used for Electricity | B5: 25 | C5: 38 | D5: 50 | E5: 61 | F5: 64 | G5: 65 | H5: 68 | I5: 71 | J5: 75 | K5: 95 | L5: 97 | M5: 101 | N5: 100 | O5: 100 | P5: EPA | Q5: https://www.epa.gov/agstar/livestock-anaerobic-digester-database | R5: Retrieved February 2024
A6: Used for Boiler/Furnace | B6: 14 | C6: 14 | D6: 14 | E6: 14 | F6: 14 | G6: 14 | H6: 14 | I6: 14 | J6: 14 | K6: 11 | L6: 29 | M6: 29 | N6: 15 | O6: 15 | P6: EPA | Q6: https://www.epa.gov/agstar/livestock-anaerobic-digester-database | R6: Retrieved February 2024
A7: Used for "Flare Full Time" | B7: 13 | C7: 13 | D7: 13 | E7: 13 | F7: 13 | G7: 13 | H7: 13 | I7: 13 | J7: 13 | K7: 11 | L7: 10 | M7: 10 | N7: 12 | O7: 12 | P7: EPA | Q7: https://www.epa.gov/agstar/livestock-anaerobic-digester-database | R7: Retrieved February 2024
A8: Used for Cogeneration | B8: 81 | C8: 93 | D8: 106 | E8: 121 | F8: 127 | G8: 133 | H8: 134 | I8: 136 | J8: 143 | K8: 107 | L8: 119 | M8: 119 | N8: 101 | O8: 101 | P8: EPA | Q8: https://www.epa.gov/agstar/livestock-anaerobic-digester-database | R8: Retrieved February 2024
A9: Number of Existing AD Plants Under Construction | B9: 0 | C9: 1 | D9: 4 | E9: 1 | F9: 0 | G9: 0 | H9: 0 | I9: 1 | J9: 3 | K9: 6 | L9: 7 | M9: 15 | N9: 24 | O9: 29 | P9: EPA | Q9: https://www.epa.gov/agstar/livestock-anaerobic-digester-database | R9: Retrieved February 2024
A10: Number of New AD Plants that Went online from livestock | B10: 19 | C10: 25 | D10: 25 | E10: 26 | F10: 9 | G10: 7 | H10: 4 | I10: 5 | J10: 11 | K10: 14 | L10: 18 | M10: 44 | N10: 24 | O10: 1 | P10: EPA | Q10: https://www.epa.gov/agstar/livestock-anaerobic-digester-database | R10: Retrieved February 2024
A11: Number of AD Plants that Shut Down | B11: 3 | C11: 8 | D11: 1 | E11: 3 | F11: 5 | G11: 4 | H11: 9 | I11: 4 | J11: 2 | K11: 3 | L11: 1 | N11: 2 | P11: EPA | Q11: https://www.epa.gov/agstar/livestock-anaerobic-digester-database | R11: Retrieved February 2024
A12: Number of States which have an AD Production Facility | B12: 29 | C12: 34 | D12: 35 | E12: 36 | F12: 36 | G12: 36 | H12: 36 | I12: 36 | J12: 36 | K12: 36 | L12: 35 | M12: 35 | N12: 34 | O12: 35 | P12: EPA | Q12: https://www.epa.gov/agstar/livestock-anaerobic-digester-database | R12: Retrieved February 2024
A13: Number of landfill Plants | B13: 359 | C13: 394 | D13: 425 | E13: 451 | F13: 474 | G13: 483 | H13: 490 | I13: 497 | J13: 514 | K13: 565 | L13: 545 | M13: 549 | N13: 516 | O13: 535 | P13: EPA | Q13: [2010-2019] https://www.epa.gov/lmop/landfill-technical-data [2020-2021] https://www.epa.gov/lmop/landfill-gas-energy-project-data | R13: Retrieved February 2024
A14: Number of States which have a landfill Facility | B14: 46 | C14: 46 | D14: 48 | E14: 48 | F14: 49 | G14: 49 | H14: 49 | I14: 49 | J14: 49 | K14: 49 | L14: 49 | M14: 49 | N14: 49 | O14: 45 | P14: EPA | Q14: [2010-2019] https://www.epa.gov/lmop/landfill-technical-data [2020-2021] https://www.epa.gov/lmop/landfill-gas-energy-project-data | R14: Retrieved February 2024
A16: PRODUCTION | B16: 2010 | C16: 2011 | D16: 2012 | E16: 2013 | F16: 2014 | G16: 2015 | H16: 2016 | I16: 2017 | J16: 2018 | K16: 2019 | L16: 2020 | M16: 2021 | N16: 2022 | O16: 2023 | P16: Source Name | Q16: Source URL | R16: Comments
A17: Biogas potential from landfills (billion cubic feet) | J17: 125.12775 | L17: 344.75903 | M17: 346.13106 | N17: 434.8368 | O17: 435.8735 | P17: EPA | Q17: https://www.epa.gov/lmop/landfill-gas-energy-project-data | R17: Retrieved February 2024
