Workbook

Sheet NEtZero
A1: 2023 companies with targets | B1: Net-Zero targets | C1: Other mitigation targets | D1: No target | E1: TOTAL | F1: Source | G1: URL | H1: Retrieve Date
A2: European Union | B2: 0.71 | C2: 0.22 | D2: 0.07 | E2: 466 | F2: Net Zero Tracker | G2: https://ca1-nzt.edcdn.com/Reports/Net_Zero_Stocktake_2023.pdf?v=1696255114/ | H2: 45383
A3: United States | B3: 0.46 | C3: 0.28 | D3: 0.27 | E3: 626 | F3: Net Zero Tracker | G3: https://ca1-nzt.edcdn.com/Reports/Net_Zero_Stocktake_2023.pdf?v=1696255114/ | H3: 45383
A4: China | B4: 0.2 | C4: 0.1 | D4: 0.7 | E4: 282 | F4: Net Zero Tracker | G4: https://ca1-nzt.edcdn.com/Reports/Net_Zero_Stocktake_2023.pdf?v=1696255114/ | H4: 45383
A5: RoW | B5: 0.68 | C5: 0.15 | D5: 0.17 | E5: 702 | F5: Net Zero Tracker | G5: https://ca1-nzt.edcdn.com/Reports/Net_Zero_Stocktake_2023.pdf?v=1696255114/ | H5: 45383
A6: World | B6: 0.68 | C6: 0.15 | D6: 0.17 | E6: 2076 | F6: Net Zero Tracker | G6: https://ca1-nzt.edcdn.com/Reports/Net_Zero_Stocktake_2023.pdf?v=1696255114/ | H6: 45383
A8: Total Emissions share (%) 2023 | B8: Total Emissions share (%) | F8: Source | G8: URL | H8: Retrieve Date
A9: Other countries with similar net zero announcements | B9: 0.33094 | F9: Climate Action Tracker | G9: https://climateactiontracker.org/global/cat-net-zero-target-evaluations/ | H9: 45383
A10: European Union (EU27) | B10: 0.07495 | F10: Climate Action Tracker | G10: https://climateactiontracker.org/global/cat-net-zero-target-evaluations/ | H10: 45383
A11: China | B11: 0.2795 | F11: Climate Action Tracker | G11: https://climateactiontracker.org/global/cat-net-zero-target-evaluations/ | H11: 45383
A12: United States | B12: 0.13623 | F12: Climate Action Tracker | G12: https://climateactiontracker.org/global/cat-net-zero-target-evaluations/ | H12: 45383
A13: India | B13: 0.06729 | F13: Climate Action Tracker | G13: https://climateactiontracker.org/global/cat-net-zero-target-evaluations/ | H13: 45383
A14: Countries with no net zero target | B14: 0.11109 | F14: Climate Action Tracker | G14: https://climateactiontracker.org/global/cat-net-zero-target-evaluations/ | H14: 45383

Sheet NetZeroStates
A1: last_updated | B1: id_code | C1: name | D1: end_target_status | E1: end_target | F1: end_target_year | H1: status_date | I1: interim_target | J1: interim_target_percentage_reduction | K1: interim_target_baseline_year | L1: interim_target_year | M1: end_target_text | N1: interim_target_text | O1: target_notes | P1: source_url | Q1: gasses_coverage | R1: territorial_emissions | S1: consumption_emissions | T1: historical_emissions | U1: coverage_notes | V1: has_plan | W1: plan_options | X1: reporting_mechanism | Y1: equity | Z1: accountability | AA1: governance_notes | AB1: carbon_credit_offsets | AC1: removals_targets | AD1: cdr | AE1: sinks_and_credits_notes | AF1: population | AG1: ghg | AH1: inventory_year | AI1: gdp_real | AJ1: interim_target_other | AK1: carbon_credit_conditions | AL1: max_emission_offset | AM1: conditions_other | AN1: end_target_percentage_reduction | AO1: end_target_baseline_year | AP1: end_target_other
A2: 2024-03-13 10:44:21 | B2: REG-0003 | C2: Louisiana | D2: In law | E2: Net zero | F2: 2050 | H2: 2020 | I2: Emissions reduction target | J2: 26 | K2: 2005 | L2: 2025 | M2: by 2050 reduce greenhouse gas emissions to net zero | N2: by 2025, reduce net greenhouse gas emissions by 26-28% of 2005 levels by 2030, reduce net greenhouse gas emissions by 40-50% of 2005 levels | O2: https://gov.louisiana.gov/page/climate-initiatives-task-force | P2: https://gov.louisiana.gov/assets/docs/CCI-Task-force/CAP/Climate_Action_Plan_FINAL_3.pdf | Q2: Carbon dioxide and other GHGs | R2: Yes | S2: No | T2: No | U2: https://gov.louisiana.gov/assets/docs/CCI-Task-force/CAP/Climate_Action_Plan_FINAL_3.pdf, pg. 3 The GHG emissions reduction goals (Figure 1) are derived in part from the declaration by the Intergovernmental Panel on Climate Change (IPCC) that “global net human-caused emissions of carbon dioxide [CO2]...would need to fall by about 45 percent from 2010 levels by 2030, reaching ‘net zero’ around 2050.”1 These goals also align with the U.S.' Nationally Determined Contributions (NDCs) which represent its commitment in the Paris Climate Agreement to limit global warming to 1.5°C,2 and are calibrated to 2005 to correspond to Louisiana‘s 2010 Greenhouse Gas Inventory (GHG Inventory). Additionally, Governor Edwards’ goals put Louisiana in line with commitments made by dozens of other states as well as businesses operating in multiple sectors internationally, nationally, and within Louisiana. These businesses span a variety of industrial sectors including energy producers, public utilities, chemical manufacturers, technology firms, and finance. https://gov.louisiana.gov/assets/docs/CCI-Task-force/CAP/Climate_Action_Plan_FINAL_3.pdf, pg. 11 in Louisiana, the industrial sector contributes an overwhelming 66% of overall state emissions. Though Louisiana’s GHG emissions are most concentrated in the industrial sector, transportation and power generation emissions across the state are also significant. The transportation sector is responsible for 19% of CO2e emissions, and the electric power sector makes up 13% of Louisiana’s CO2e emissions. | V2: Yes | W2: Measures for all emission scopes that are covered by the target|Information on the emission reductions expected from these measures within a certain time period|Information on the extent to which measures will be applied (e.g. if switching to EVs, what share of the fleet; if installing an own solar PV installation, what is the installed capacity)|Schedule for regular review of measures | X2: Annual reporting | Y2: Yes | Z2: Not Specified | AA2: 2023 Annual Report: https://drive.google.com/uc?id=1qzBtt2Dt0QF4PHWqEQi49UNWF0HHIgSn&export=download EQUITY https://gov.louisiana.gov/assets/docs/CCI-Task-force/CAP/Climate_Action_Plan_FINAL_3.pdf, pg 36 "In Louisiana and around the world, climate change and GHG emissions disproportionately impact low-income, Black, and Indigenous communities. These communities are the least responsible for emissions but bear the highest costs in health and environmental degradation. In addition to their own inherent value as people of the state of Louisiana and the price they have paid through past inequities, these communities hold tremendous knowledge of the state’s lands, waters, wildlife, and environment and are needed leaders in the implementation of GHG-reducing actions. Representation and process integration are the foundation for equitable opportunity and outcomes. From the start of the Climate Action Plan development process, the Task Force and supporting members were chosen with this reality in mind, and open discussion of equity considerations were fostered during public meetings. In addition, an equity advisory group was formed to specifically consider the potential outcomes of policy proposals for advancing or negating progress toward a more equitable society. The equity advisory group developed a definition of climate equity and evaluated the potential impact of climate actions on the three equity-centered fundamental objectives aimed at reducing disparities, addressing historic and structural inequities, and increasing participation for Black, low- income, historically marginalized, and Indigenous peoples across Louisiana." STRATEGY 17. Build a more inclusive and resilient economy for all Louisiana residents https://gov.louisiana.gov/assets/docs/CCI-Task-force/CAP/Climate_Action_Plan_FINAL_3.pdf, pg 97 Deliberate action is necessary to ensure that all Louisianans have equitable access to future economic opportunities and that any disruptions to the economy associated with the energy transition do not fall disproportionately on any one community. By prioritizing the success of those who have historically been excluded from the benefits of prior economic transitions and those who are most directly affected by the energy transition, the shift to a low-carbon economy can more broadly, inclusively, and equitably provide benefits throughout the state. | AB2: Not Specified | AC2: No | AD2: Yes (nature-based and CCS-based removals) | AE2: "Louisiana's forested areas 'are a considerable carbon sink' with wetlands -- assessed for the first time in this inventory -- also supporting carbon sequestration... Louisiana’s land-based carbon sequestration has increased since 2012, contributing to an annual reduction of 35 MMT CO2e, which is comparable to the entire power generation sector." https://gov.louisiana.gov/assets/docs/CCI-Task-force/CAP/Climate_Action_Plan_FINAL_3.pdf, pg 38 ACTION 14.2 Support the expansion of urban tree canopy and green spaces https://gov.louisiana.gov/assets/docs/CCI-Task-force/CAP/Climate_Action_Plan_FINAL_3.pdf, pg 89 Activities that reforest public areas in urban environments, increase urban green spaces (e.g., parks, gardens, farms), and provide landscape-based stormwater management through green infrastructure can sequester carbon while also reducing heat island effect, reducing localized flooding, and increasing access to open space. Further co-benefits are reduced energy consumption and ongoing energy use due to a reduced heat island effect. This action proposes the state government, through LDAF, serve as convenor of parish and municipal governments to develop and promote a coherent, statewide approach that supports tree planting programs and maintenance in urban areas, particularly in historically underserved communities. In addition to this statewide approach, this action should empower locals to survey existing tree canopies in urban areas, with progress tracked and reported annually. Near-term deployment of a statewide approach and local surveys of existing canopies should inform longer-term urban transportation projects. Specific focus should be on increasing tree canopy and open space access in low-income, urban areas in both regional and local plans (e.g., State Watershed Plan, Hazard Mitigation Plan, Comprehensive Plans). ACTION 15.1 Optimize the carbon sequestration potential of Louisiana’s coastal wetlands through implementation of Coastal Master Plan projects https://gov.louisiana.gov/assets/docs/CCI-Task-force/CAP/Climate_Action_Plan_FINAL_3.pdf, pg 90 Implementation of Louisiana’s Coastal Master Plan* includes coastal restoration actions to reduce land loss with a focus on risk reduction to support coastal communities. This action proposes that the Coastal Protection and Restoration Authority (CPRA) incorporate climate mitigation goals and measures (e.g., carbon sequestration potential of wetlands) into future iterations of the Coastal Master Plan as well as into project design and prioritization. Carbon sequestration potential should further make the case for investment in Louisiana’s coastal program and unlock additional resources for project implementation. (Associated Submitted Action Proposals: 77) ACTION 16.7 Encourage sustainable forest management and greater use of Louisiana forest products for construction https://gov.louisiana.gov/assets/docs/CCI-Task-force/CAP/Climate_Action_Plan_FINAL_3.pdf, pg 95 Markets for wood products create incentives for landowners to plant more trees and better manage forests, resulting in more carbon sequestered. Educating landowners on and establishing sustainable forestry practices maximizes carbon sequestration of forested lands, encourages participation in carbon markets, and enhances early succession benefits and realized co-benefits to ecosystems and species. Further, implementation of a Buy Clean Louisiana policy (Action 6.1) will encourage and require manufacturers and end users to purchase sustainably forested products in construction and consumer products, increasing the amount of carbon stored by trees. This action proposes LDAF’s Forestry Protection Program and the Louisiana Forestry Association (LFA) partner to educate major foresters on the sustainable management of forests and the necessary steps to engage in existing carbon markets. ACTION 26.2 Solicit a study to more comprehensively understand potential impacts of CCUS technology and infrastructure on communities, ecosystems, and cultural resources to inform siting and permitting deployment https://gov.louisiana.gov/assets/docs/CCI-Task-force/CAP/Climate_Action_Plan_FINAL_3.pdf, pg 110 With Louisiana’s extensive geologic storage potential and federal incentives for near-term investment, Louisiana is seeing significant interest and investment in the deployment of CCUS to address industrial GHG emissions. Members of the Task Force and the public have raised concerns related to the capture process at facilities, transport through pipelines, and geologic storage underground. To address these concerns, this action recommends the state, through leadership of DNR, and its research institutions synthesize existing research on CCUS and disseminate information and materials for public education. The state and its research institutions should also fund a comprehensive understanding of CCUS impacts, including but not limited to siting impacts on cultural characteristics of neighboring populations, air quality impacts on nearby communities, increased energy intensity for different industry processes, pipeline safety implications, environmental and resilience impact of pipeline buildout, potential incidents of geologic storage, and long-term risks and costs. (Associated Submitted Action Proposals: N/A) | AF2: 4649000
A3: 2024-03-19 14:22:41 | B3: REG-0004 | C3: Nevada | D3: In policy document | E3: Net zero | F3: 2050 | H3: 2021 | I3: Emissions reduction target | J3: 28 | K3: 2005 | L3: 2025 | M3: long-term reductions of greenhouse gas emissions to zero or near-zero by the year 2050 | N3: statewide reduction of net greenhouse gas emissions of 28 percent by the year 2025, as compared to the level of greenhouse gas emissions in this State in 2005 statewide reduction in net greenhouse gas emissions of 45 percent by the year 2030, as compared to the level of greenhouse gas emissions in this State in 2005 However, under current policies and based on the best available science, Nevada is currently on a path to reduce economy-wide GHG emissions 24% by 2025 (4% short of the 28% goal) and 26% by 2030 (19% short of the 45% goal), thus missing the emissions-reduction goals. (GHG inventory, p.12) | O3: The targets themselves do not appear to be in law (referring to policies "that could achieve reductions"), but the submission of the annual report is Law SB254: https://www.leg.state.nv.us/App/NELIS/REL/80th2019/Bill/6431/Text GHG inventory 2021: https://ndep.nv.gov/uploads/air-pollutants-docs/ghg_report_2021.pdf | P3: https://climateaction.nv.gov/wp-content/uploads/2021/01/NVClimateStrategy_011921.pdf | Q3: Carbon dioxide and other GHGs | R3: Yes | S3: Not Specified | T3: No | U3: "statewide inventory of greenhouse gas emissions" | V3: Yes | W3: Measures for all emission scopes that are covered by the target|Information on the emission reductions expected from these measures within a certain time period|Information on the extent to which measures will be applied (e.g. if switching to EVs, what share of the fleet; if installing an own solar PV installation, what is the installed capacity) | X3: Annual reporting | Y3: Yes | Z3: Not Specified | AA3: Annual reporting: " requiring the State Department of Conservation and Natural Resources to issue an annual report concerning greenhouse gas emissions in this State"; "equires the report to provide policies, identified by an entity or entities designated by the Governor, that could achieve reductions in greenhouse gas emissions and a qualitative assessment of whether such policies support long-term reductions of greenhouse gas emissions in this State to zero or near-zero by the year 2050" Reporting here: https://ndep.nv.gov/air/air-pollutants/greenhouse-gas-emissions Public plan: Nevada's 2020 State Climate Strategy has catalog of policies it plans to implement across different sectors, and each policy is assessed on 4 metrics: (1.) GHG Emissions reduction potential; (2.) Climate justice considerations; (3.) Budgetary and economic implications; (4.) Implementation feasibility (Climate Strategy, p.52) Equity: One of the key metrics per proposed climate policy is climate justice, which is defined as: Have communities of color, low-income households, and tribal partners (i.e., Indigenous communities) been directly engaged and consulted about the challenges and opportunities associated with the policy? Will the policy avoid any negative impacts to vulnerable communities, provide the opportunity for a net benefit, and/or reconcile broader social justice issues? (Climate Strategy, p.53) GHG inventory (2021) suggests need to establish a state climate structure centred on equity, environmental justice, and economic recovery (p. 50). In Kleinmann report (2023): "While much of the strategic modeling of CCS and CDR deployment has focused on techno–economic impact categories, these types of analyses can overlook the cumulative social and environmental impacts of these approaches. Many of the strategies identified in this study could place increasing stress on marginalized populations." (p. 7, https://kleinmanenergy.upenn.edu/wp-content/uploads/2022/04/KCEP-Digest-Net-Zero-Nevada_withthanks.pdf) | AB3: Not Specified | AC3: No | AD3: Yes (nature-based removals e.g. Forestation, soil carbon enhancement) | AE3: NATURE BASED REMOVALS ARE ADDRESSED but no explicit details are provided on the extent of these nature-based removal schemes and by how much they will reduce emissions by. In https://climateaction.nv.gov/wp-content/uploads/2021/01/NVClimateStrategy_011921.pdf there is reference to: Promote land management practices that increase carbon sequestration by natural lands that are typical and/or native to Nevada. Expand speci | AF3: 3080000 | AG3: 36200000 | AH3: 2017
A4: 2023-05-12 06:50:54 | B4: REG-0005 | C4: Colorado | D4: In law | E4: Net zero | F4: 2050 | H4: 2023 | I4: Emissions reduction target | J4: 26 | K4: 2005 | L4: 2025 | M4: (2) It is further declared that: (g) (I) Accordingly, Colorado shall strive to increase renewable energy generation and eliminate statewide greenhouse gas pollution by the middle of the twenty-first century and have goals of achieving, at a minimum: ... (F) A ONE HUNDRED percent reduction in statewide greenhouse gas pollution by 2050. | N4: (A) A twenty-six percent reduction in statewide greenhouse gas pollution by 2025; (B) A fifty percent reduction in statewide greenhouse gas pollution by 2030; (C) A SIXTY- FIVE PERCENT REDUCTION IN STATEWIDE GREENHOUSE GAS POLLUTION BY 2035; (D) A SEVENTY - FIVE PERCENT REDUCTION IN STATEWIDE GREENHOUSE GAS POLLUTION BY 2040; (E) A NINETY PERCENT REDUCTION IN STATEWIDE GREENHOUSE GAS POLLUTION BY 2045; and ... (II) The reductions identified in this subsection (2)(g) are measured relative to 2005 statewide greenhouse gas pollution levels. | O4: 2019 law: https://leg.colorado.gov/bills/hb19-1261 Full 2023 bill: https://leg.colorado.gov/sites/default/files/documents/2023A/bills/2023a_016_enr.pdf https://www.edf.org/media/colorado-legislature-passes-bill-strengthening-states-climate-targets | P4: https://leg.colorado.gov/bills/sb23-016 | Q4: Carbon dioxide and other GHGs | R4: Not Specified | S4: Not Specified | T4: No | U4: Methane also included in target (e.g., " "Recovered methane protocol" means a documented set of procedures and requirements established by the air quality control commission to quantify ongoing greenhouse gas emission reductions or greenhouse gas removal enhancements achieved by a recovered methane project and to calculate the project baseline.") | V4: Yes | W4: Information on the extent to which measures will be applied (e.g. if switching to EVs, what share of the fleet; if installing an own solar PV installation, what is the installed capacity)|Information on the emission reductions expected from these measures within a certain time period|Schedule for regular review of measures | X4: No reporting mechanism | Y4: No | Z4: Not Specified | AA4: Equity p14 of Reduction Roadmap: https://energyoffice.colorado.gov/climate-energy/ghg-pollution-reduction-roadmap Revision over time: e) (II) Consistent with section 25-7-102 (2)(g), the commission shall timely promulgate implementing rules and regulations. The implementing rules may take into account other relevant laws and rules, as well as voluntary actions taken by local communities and the private sector, to enhance efficiency and cost-effectiveness, and shall be revised as necessary over time to ensure timely progress toward the 2025, 2030, 2035, 2040, 2045, and 2050 goals. | AB4: Not Specified | AC4: No | AD4: Yes (unspecified) | AE4: ""Recovered methane protocol" means a documented set of procedures and requirements established by the air quality control commission to quantify ongoing greenhouse gas emission reductions or greenhouse gas removal enhancements achieved by a recovered methane project and to calculate the project baseline." "1) The Colorado energy office shall ... (XIII) SUPPORT POLLUTION REDUCTION THROUGH CARBON CAPTURE AND SEQUESTRATION AND OTHER FORMS OF CARBON MANAGEMENT" | AF4: 5759000 | AG4: 89300000 | AH4: 2018 | AI4: 392986000000
A5: 2024-03-12 16:37:59 | B5: REG-0009 | C5: California | D5: In law | E5: Net zero | F5: 2045 | H5: 2020 | I5: Emissions reduction target | J5: 48 | K5: 1990 | L5: 2030 | M5: "achieve carbon neutrality as soon as possible, and no later than 2045, and achieve and maintain net negative emissions thereafter" | N5: 2030: 40% below 1990 levels 2050: 80% below 1990 levels - Scoping plan furthered the interim target: "That includes a 48% reduction of greenhouse gasses by 2030, surpassing the statutory mandate to reduce emissions 40% below 1990 levels in 2030;" (source: https://www.gov.ca.gov/2022/11/16/california-releases-worlds-first-plan-to-achieve-net-zero-carbon-pollution/) | O5: B-55-18 is an executive order, so carries the force of law https://ww2.arb.ca.gov/sites/default/files/2020-08/e3_cn_draft_report_aug2020.pdf https://leginfo.legislature.ca.gov/faces/billTextClient.xhtml?bill_id=201520160SB32 | P5: https://www.ca.gov/archive/gov39/wp-content/uploads/2018/09/9.10.18-Executive-Order.pdf | Q5: Not Specified | R5: Not Specified | S5: Not Specified | T5: No | U5: California's fourth climate change assessment covers Temperature, Water, Wildfire, Sea Level, Communities and Governance (California's Fourth Climate Change Assessment) | V5: Yes | W5: Measures for all emission scopes that are covered by the target|Information on the emission reductions expected from these measures within a certain time period|Schedule for regular review of measures|Information on the extent to which measures will be applied (e.g. if switching to EVs, what share of the fleet; if installing an own solar PV installation, what is the installed capacity) | X5: Annual reporting | Y5: Yes | Z5: Not Specified | AA5: "shall seek to improve air quality and support the health and economic resiliency of urban and rural communities, particularly low-income and disadvantaged communities" and "shall be implemented in a manner that supports climate adaptation and biodiversity" Plans -https://ww2.arb.ca.gov/our-work/programs/ab-32-climate-change-scoping-plan; https://ww2.arb.ca.gov/sites/default/files/2020-08/e3_cn_draft_report_aug2020.pdf | AB5: Not Specified | AC5: No | AD5: Not Specified | AE5: "shall include sequestration targets in the Natural and Working Lands Climate Change Implementation Plan" | AF5: 39510000 | AG5: 425280804 | AH5: 2018 | AI5: 3132800000000
A6: 2024-03-12 14:17:24 | B6: REG-0010 | C6: Hawaii | D6: In law | E6: Climate neutral | F6: 2045 | H6: 2024 | I6: Emissions reduction target | J6: 50 | K6: 2005 | L6: 2030 | M6: "pledge to be carbon-neutral by 2045" - https://governor.hawaii.gov/newsroom/latest-news/governors-office-news-release-governor-david-ige-signs-bills-to-set-carbon-neutral-goal-and-combat-climate-change/ | N6: "Hawaiʻi again reaffirmed this comitment with Act 238 (Session Laws of Hawaii, or SLH 2022) which codified in Hawai‘i Revised Statutes (HRS) §225P-5, requires Hawai‘i to reduce GHG emissions by at least 50 percent below 2005 levels by 2030 and 100% by 2045, in line with the United States’ Paris Agreement commitments and Nationally Determined Contribution." (https://climate.hawaii.gov/wp-content/uploads/2024/03/Hawaii-PCAP-FINAL-March-1-2024-1-3.pdf, page 2) | O6: commitment to have a one hundred per cent renewable energy portfolio by 2045 | P6: https://climate.hawaii.gov/wp-content/uploads/2024/03/Hawaii-PCAP-FINAL-March-1-2024-1-3.pdf | Q6: Carbon dioxide and other GHGs | R6: Yes | S6: Not Specified | T6: No | U6: Gases included are CO2, SF6, N2O, CH4, HFCs, PFCs | V6: Yes | W6: Measures for all emission scopes that are covered by the target|Information on the emission reductions expected from these measures within a certain time period|Information on the extent to which measures will be applied (e.g. if switching to EVs, what share of the fleet; if installing an own solar PV installation, what is the installed capacity) | X6: Annual reporting | Y6: Yes | Z6: Not Specified | AA6: Reports - https://climate.hawaii.gov/hi-mitigation/mitigation-reports/ "Beginning with the regular session of 2024, submit an annual report of its findings and recommendations, including any proposed legislation, to the legislature and the climate change mitigation and adaptation commission no later than twenty days prior to the convening of each regular session" - https://www.capitol.hawaii.gov/session2018/bills/HB2182_CD1_.htm Plan and measures detailed on page 25-28 of https://climate.hawaii.gov/wp-content/uploads/2024/03/Hawaii-PCAP-FINAL-March-1-2024-1-3.pdf "Equity is at the center of Hawai‘i’s response to climate change" and "To build climate equity, it is essential to center the voices and strengths of historically underserved communities and acknowledge the institutions and policies that are responsible for these disparities. Recognizing this, CCMAC puts equity at the center of its mission statement, to quickly “promote ambitious climate-neutral culturally responsive strategies for climate change mitigation and adaptation in a manner that is clean, equitable and resilient.”" (https://climate.hawaii.gov/wp-content/uploads/2024/03/Hawaii-PCAP-FINAL-March-1-2024-1-3.pdf, page 2) | AB6: Not Specified | AC6: No | AD6: Yes (nature-based removals e.g. Forestation, soil carbon enhancement) | AE6: "In Act 33, Session Laws of Hawaii 2017, the State established the carbon farming task force to gain a more thorough understanding of how agricultural land management practices can sequester carbon, provide greenhouse gas benefits, and decrease marine sedimentation" aim to "create a carbon offset program" "3.Increase long term carbon sequestration and ecosystem resilience by planting 2,800 food trees, 1,100 native trees, and 17,000 native understory species on 110 acres over a five-year period." (https://climate.hawaii.gov/wp-content/uploads/2024/03/Hawaii-PCAP-FINAL-March-1-2024-1-3.pdf, page 23) | AF6: 1416000 | AG6: 19580000 | AH6: 2016 | AI6: 97281700000
A7: 2023-01-04 15:14:33 | B7: REG-0011 | C7: Maine | D7: In law | E7: Carbon neutral(ity) | F7: 2045 | H7: 2020 | I7: Emissions reduction target | J7: 45 | K7: 1990 | L7: 2030 | M7: shall strive to achieve a carbon neutral economy no later than 2045 | N7: 2030: gross annual greenhouse gas emissions at least 45% below 1990 2040: gross annual greenhouse gas emissions must, at a minimum, be on an annual trajectory sufficient to achieve the 2050 annual emissions (80%) renewable energy mandate of 80 percent renewable energy by 2030 and a goal of 100 percent by 2050 | O7: https://legislature.maine.gov/legis/bills/bills_129th/billtexts/SP055002.asp | P7: https://www.maine.gov/governor/mills/sites/maine.gov.governor.mills/files/inline-files/Executive%20Order%209-23-2019_0.pdf | Q7: Not Specified | R7: Not Specified | S7: Not Specified | T7: No | V7: Yes | W7: Schedule for regular review of measures|Information on the extent to which measures will be applied (e.g. if switching to EVs, what share of the fleet; if installing an own solar PV installation, what is the installed capacity) | X7: Less than annual reporting | Y7: Yes | Z7: Yes | AA7: Maine Climate Council "update that plan every four years" and "responsible for Maine's Climate Action Plan" Plan from 2020: http://climatecouncil.maine.gov/future/sites/maine.gov.future/files/inline-files/MaineWontWait_December2020_printable_12.1.20.pdf https://www.maine.gov/dep/sustainability/climate/mitigation-actions.html - progress reports are bienniel (Dec 2022 report here: https://www.maine.gov/future/sites/maine.gov.future/files/inline-files/MWWProgressReport_December2022_digital.pdf) goal of 100,000 heat pumps before 2025 goal of weatherizing 17,500 homes by 2025 127 communities are now participating in the Community Resilience Partnership, a new program to encourage cities, towns, and Tribal governments to identify climate and resilience priorities and start or expand their local climate planning and actions | AB7: Not Specified | AC7: No | AD7: Not Specified | AE7: "Develop New Incentives to Increase Carbon Storage" - http://climatecouncil.maine.gov/future/sites/maine.gov.future/files/inline-files/MaineWontWait_December2020_printable_12.1.20.pdf "a comprehensive Maine carbon-cycle analysis is needed for the state to understand and track its progress towards carbon neutrality and allow for accurate potential future participation in carbon-offset markets" - not currently a participant in offsetting | AF7: 1344000 | AG7: 15000000 | AH7: 2018 | AI7: 67717000000
A8: 2024-03-19 17:19:16 | B8: REG-0012 | C8: Massachusetts | D8: In law | E8: Net zero | F8: 2050 | H8: 2020 | I8: Emissions reduction target | J8: 33 | K8: 1990 | L8: 2025 | M8: https://www.mass.gov/doc/clean-energy-and-climate-plan-for-2025-and-2030/download 'A statewide limit of net zero emissions means that in 2050, total GHG emissions emitted by all sources in Massachusetts must be equal to or less than the total amount of carbon sequestered within Massachusetts or through actions directly attributable to Massachusetts' | N8: "As part of a letter issued contemporaneously with the Clean Energy and Climate Plan for 2025 and 2030 (2025/2030 CECP), the Secretary of the Executive Office of Energy and Environmental Affairs has determined that the Commonwealth’s economy-wide emissions limit will be a 33% reduction from 1990 level in 2025, and a 50% reduction in 2030." [p12] | O8: Previous target 25% reduction on 1990 levels for 2020. Massachusetts’ approach to achieving its emissions limits and sublimits is based on three basic principles: (1) electrify non-electric energy uses, (2) decarbonize the electric grid, and (3) reduce energy costs and the costs of transition by increasing the efficiency of transportation and energy systems. | P8: https://malegislature.gov/Bills/191/H4912 | Q8: Carbon dioxide and other GHGs | R8: Not Specified | S8: Not Specified | T8: No | U8: https://www.mass.gov/news/baker-polito-administration-issues-letter-establishing-net-zero-emissions-target https://www.mass.gov/doc/ma-2050-decarbonization-roadmap/download direct and indrect emissions mentioned, but not explicitly clear what the target includes. The 2021 climate law includes setting sector-specific GHG emissions limits, including in residential heating and cooling, commercial and industrial heating and cooling, transportation, electrical power, natural gas distribution and service and industrial processes. GHG emissions associated with agriculture, solid waste decomposition in landfills, and wastewater disposal are not represented in the sector specific sublimit. | V8: Yes | W8: Measures for all emission scopes that are covered by the target|Information on the emission reductions expected from these measures within a certain time period|Schedule for regular review of measures|Information on the extent to which measures will be applied (e.g. if switching to EVs, what share of the fleet; if installing an own solar PV installation, what is the installed capacity) | X8: Annual reporting | Y8: Yes | Z8: Not Specified | AA8: Reports - https://www.mass.gov/info-details/ma-decarbonization-roadmap#final-reports- "Achieving Net Zero Affordably for All" - https://www.mass.gov/doc/ma-2050-decarbonization-roadmap/download "The decarbonization policies and approaches contained in this 2025/2030 CECP will have substantial impacts on Massachusetts residents and the economy. To estimate these impacts, BW Research Partnership and Industrial Economics, Incorporated (the research team) worked with EEA to model the employment, macroeconomic, and equity impacts of the decarbonization pathway" [p119] | AB8: Not Specified | AC8: No | AD8: Yes (unspecified) | AE8: Natural and working lands’ ability to sequester emissions will be a critical component of achieving net zero GHG emissions in Massachusetts. For the first time, this 2025/2030 CECP provides an analysis of the emissions from, and the carbon sequestration by, Massachusetts’ NWL; outlines policies to support the conservation, climate smart management, and restoration of NWL; and identifies additional ongoing and existing actions the Commonwealth is pursuing to achieve net zero emissions by 2050. "Achieving net zero in 2050 will require real, verified annual sequestration of as much as 14.2 MMTCO2e by resources in, or attributable to, the Commonwealth. EEA’s current assessment is that NWL in Massachusetts are not likely to be capable of sequestering carbon dioxide at this rate in 2050 without seriously compromising other ecosystem services and land uses. Thus, it will be necessary to develop regionally consistent sequestration measurement, accounting, and market frameworks that will allow Massachusetts to purchase additional, least-cost sequestration services from other states in the region to allow the Commonwealth to achieve net zero GHG emissions in 2050." [p117] | AF8: 6893000 | AG8: 63000000 | AH8: 2018 | AI8: 596593000000
A9: 2024-03-12 14:00:31 | B9: REG-0013 | C9: Michigan | D9: In law | E9: Carbon neutral(ity) | F9: 2050 | H9: 2020 | I9: Emissions reduction target | J9: 28 | K9: 2005 | L9: 2025 | M9: "economy-wide carbon neutrality no later than 2050, and to maintain net negative greenhouse gas emissions thereafter" | N9: Reduce GHG emissions 28% below 2005 levels by 2025 Reduce GHG emissions 52% below 2005 levels by 2030 | O9: https://www.michigan.gov/whitmer/0,9309,7-387-90499_90704-540278--,00.html https://www.michigan.gov/egle/-/media/Project/Websites/egle/Documents/Offices/OCE/MI-Healthy-Climate-Plan.pdf?rev=d13f4adc2b1d45909bd708cafccbfffa | P9: https://www.michigan.gov/whitmer/news/state-orders-and-directives/2020/09/23/executive-directive-2020-10.pdf | Q9: Not Specified | R9: Yes | S9: Not Specified | T9: No | U9: Not specified- reference is only to GHG | V9: Yes | W9: Information on the extent to which measures will be applied (e.g. if switching to EVs, what share of the fleet; if installing an own solar PV installation, what is the installed capacity) | X9: Annual reporting | Y9: Yes | Z9: Not Specified | AA9: Quite a detailed plan on Energy productions, transportation, businesses and homes, environmental justice, leadership and innovation. | AB9: Not Specified | AC9: No | AD9: Not Specified | AF9: 9987000 | AG9: 162100000 | AH9: 2018 | AI9: 536888000000
A10: 2024-03-19 15:14:18 | B10: REG-0014 | C10: Montana | D10: In policy document | E10: GHG neutral(ity) | F10: 2050 | H10: 2020 | I10: Other | L10: 2035 | M10: "goal of net greenhouse gas neutrality economy-wide at a date to be determined by the Council." Executive Order 8-2019, p. 3, http://formergovernors.mt.gov/bullock/docs/2019EOs/EO-08-2019_Creating%20Climate%20Solutions%20Council.pdf 2020 montana climate solutions plan, p.4, https://deq.mt.gov/files/deqadmin/climate/2020-09-09_montanaclimatesolutions_final.pdf | N10: "interim goal of net ghg neutrality for average annual electric loads in the state by no later than 2035" Executive Order 8-2019, p. 3, http://formergovernors.mt.gov/bullock/docs/2019EOs/EO-08-2019_Creating%20Climate%20Solutions%20Council.pdf 2020 montana climate solutions plan, p.4, https://deq.mt.gov/files/deqadmin/climate/2020-09-09_montanaclimatesolutions_final.pdf | O10: This record gives updates from March 2024 - Montana's Priority Climate Action Plan: This plan differs from past climate planning because it is directly tied to federal funding made available to implement the projects states identify. This is an opportunity for Montana-made, market-driven solutions focused on innovation that will also reduce emissions. Nothing in this plan is intended to be implemented through new policies, regulations, or requirements, and projects that propose to use regulation to cut emissions are not covered by this plan. From the start, DEQ (Department of Environmental Quality) established an expectation that the measures included in Montana’s plan would be non-regulatory, incentive-based actions that focus on innovation and do not expand government. However, priority measures include Healthy Resilient Forests, Sustainable Schools, Innovative Agricultural Practices & Working Lands, Clean, Reliable Transportation, Industrial & Power Sector Innovation, High Performance Homes & Businesses, Waste Reduction or Diversion These suggested measures are accompanied by quantifications of how much emissions reduction each could achieve E.g. within the forests section, Expand Forest Management & Wildfire Mitigation is calculated to have the capacity to reduce GHG emissions by 0.22 MMT CO2e by 2030 or 1.09 MMT by 2050 | P10: https://deq.mt.gov/files/About/CPRG/Montana%20Pollution%20Reduction%20Plan.pdf | Q10: Carbon dioxide and other GHGs | R10: No | S10: Not Specified | T10: No | U10: "net greenhouse gas neutrality economy-wide" (pg 3) http://formergovernors.mt.gov/bullock/docs/2019EOs/EO-08-2019_Creating%20Climate%20Solutions%20Council.pdf | V10: Yes | W10: Measures for all emission scopes that are covered by the target|Information on the emission reductions expected from these measures within a certain time period | X10: Less than annual reporting | Y10: Yes | Z10: Not Specified | AA10: https://deq.mt.gov/about/Climate-Resilience: Plan: Under the Climate Pollution Reductions Grant , DEQ is beginning the process of developing a Montana Climate Action Plan. The planning grant has three deliverables: Priority Climate Action Plan (PCAP) due March 1, 2024 (this has been submitted: https://deq.mt.gov/files/About/CPRG/Montana%20Pollution%20Reduction%20Plan.pdf) Comprehensive Climate Action Plan (CCAP) due summer 2025 Status Report due summer 2027 Equity: In the Priority Climate Action Plan (PCAP), with reference to restoring forests: This measure would deliver substantial benefits to low-income and disadvantaged communities, aligning with Justice. This strategic focus addresses the heightened risks these communities face due to climate change and their limited resources to adapt or recover from such impacts. In addition, the measure would help protect public health by reducing wildfire smoke, a significant source of air pollution. The plan also has a section entitled 'LOW-INCOME AND DISADVANTAGED COMMUNITY BENEFITS ANALYSIS' | AB10: Not Specified | AC10: No | AD10: Yes (nature-based and CCS-based removals) | AE10: March 2024 Priority Climate Action Plan focuses on nature-based removals (reforestation, aovided forest conversion, fire management, soil carbon sequestration). Not much mention of CCS, however a section on Innovation in the Beef & Cattle Industry mentions 'tools to improve efficiency and reduce the environmental impacts of the beef supply chain through capture and reuse of methane gas' - 'If the emissions of 50,000 cows are reduced by 50 percent through methane capture and/or feed advancements,2 that results in 2,495 metric tons of methane reduced every five years' "b) Reducing emissions from traditional electricity generation sources while maintaining competitive advantages in electricity production, generation, and exports such as; 1. Continuing to advance the demonstration and deployment of carbon capture, storage, and utilization in support of negative emissions technologies;" (pg 3) http://formergovernors.mt.gov/bullock/docs/2019EOs/EO-08 2019_Creating%20Climate%20Solutions%20Council.pdf Lots of discussion of carbon capture in Montana Climate Solutions Plan: "Even as Montana diversifies its energy portfolio, fossil fuels are expected to meet a portion of energy demand. The deployment of carbon capture and storage (CCS) technology can accelerate efforts to reduce emissions from power plants and industrial processes, and support other needs such as renewable fuel production central to meeting the net-neutral goal." (pg 52) https://deq.mt.gov/files/DEQAdmin/Climate/2020-09-09_MontanaClimateSolutions_Final.pdf Nature based solutions "3. Northern Plains Precision Agricultural and Soil Carbon Innovation. A Northern Plains precision agriculture and soil carbon innovation cluster would build on and expand research capacity at MSU Northern and MSU. Agriculture is an important sector in Montana’s economy and culture and is a key sector with opportunities to reduce emissions from operations, sequester carbon in soils, and meet regional and global market demands" (pg 64) https://deq.mt.gov/files/DEQAdmin/Climate/2020-09-09_MontanaClimateSolutions_Final.pdf | AF10: 1069000 | AG10: 30700000 | AH10: 2018 | AI10: 52935000000 | AJ10: "interim goal of net ghg neutrality for average annual electric loads in the state by no later than 2035 and the goal of net green house gas neutrality economy-wide at a date to be determined by the concil" executive order 8-2019, p. 3, http://formergovernors.mt.gov/bullock/docs/2019eos/eo-08-2019_creating%20climate%20solutions%20council.pdf 2020 montana climate solutions plan, p.4, https://deq.mt.gov/files/deqadmin/climate/2020-09-09_montanaclimatesolutions_final.pdf
A11: 2024-03-12 14:23:48 | B11: REG-0015 | C11: New York State | D11: In law | E11: Net zero | F11: 2050 | H11: 2019 | I11: Emissions reduction target | J11: 40 | K11: 1990 | L11: 2030 | M11: "Net-Zero emissions statewide by 2050" "adopt measures to put the state on a path to reduce statewide greenhouse gas emissions by eighty-five percent by two thousand fifty and net zero emissions in all sectors of the economy" | N11: 2030: 40% below 1990 levels by 2030 2050: no less than 85% below 1990 levels | O11: "minimum of 70 percent of statewide electric generation be secured by renewable energy systems by 2030 and zero emissions from the statewide electrical demand system in 2040" "the community air monitoring program required by section 2 of the act shall take effect on October 1, 2022" More updated version of the bill at: https://climate.ny.gov/resources/scoping-plan/ | P11: https://www.nysenate.gov/legislation/bills/2019/s6599 | Q11: Carbon dioxide and other GHGs | R11: Yes | S11: No | T11: No | U11: "statewide greenhouse gas emissions means the total annual emissions of greenhouse gases produced within the state from anthropogenic sources and greenhouse gases produced outside of the state that are associated with the generation of electricity imported into the state and the extraction and transmission of fossil fuels imported into the state" | V11: Yes | W11: Measures for all emission scopes that are covered by the target|Information on the emission reductions expected from these measures within a certain time period|Information on the extent to which measures will be applied (e.g. if switching to EVs, what share of the fleet; if installing an own solar PV installation, what is the installed capacity) | X11: Less than annual reporting | Y11: Yes | Z11: Not Specified | AA11: Plan and measures detailed page 12-22 in Executive Summary of https://climate.ny.gov/resources/scoping-plan/ Equity - "provisions to address potential impacts on disadvantaged communities"; "THE COUNCIL SHALL CONVENE A JUST TRANSITION WORKING GROUP "This Scoping Plan prioritizes Disadvantaged Communities and the creation of good, family-sustaining, union jobs accessible to all New Yorkers." (https://climate.ny.gov/resources/scoping-plan/ page 3) "Every four years, DEC will publish a report on the implementation of GHG emission reduction measures, in consultation with the Council and CJWG." (https://climate.ny.gov/resources/scoping-plan/ Executive Summary page 23) | AB11: Yes | AC11: No | AD11: Not Specified | AE11: Offsetting: "the use of such mechanism shall account for not greater than fifteen percent of statewide greenhouse gas emissions estimated as a percentage of nineteen ninety emissions pursuant to section 75-0105 of this article, provided that the use of this mechanism must offset a quantity greater than or equal to the greenhouse gases emitted" "the offset of greenhouse gas emissions shall not result in disadvantaged communities having to bear a disproportionate burden of environmental impacts" | AF11: 19677151 | AG11: 205610000 | AH11: 2016 | AI11: 1772260000000 | AK11: Must be high environmental integrity|Avoid social harm|Maximum percentage of emissions that can be offset|Other conditions | AL11: 15 | AM11: "real, additional, verifiable, enforceable, and permanent" "sufficiently demonstrate that compliance with the greenhouse gas emissions limits is not technologically feasible, and that the source has reduced emissions to the maximum extent practicable" "sources in the electric generation sector shall not be eligible to participate in such mechanism." other prohibited projects: waste-to-energy projects (inc incineration and pyrolysis), biofuels for energy/transport, research projects and studies/assessments without commitment to implement "discernable benefit to the environment rather than to the source" "located in the same county, and within twenty-five linear miles, of the source of emissions, to the extent practicable"
A12: 2023-01-04 15:24:36 | B12: REG-0016 | C12: Washington State | D12: In law | E12: Net zero | F12: 2050 | H12: 2020 | I12: Emissions reduction target | J12: 45 | K12: 1990 | L12: 2030 | M12: "net zero greenhouse gas emissions by 2050" | N12: 2030: 45% below 2005 2040: 70% below 2005 2050: 95% below 2005 & achieve net zero GHG emissions | O12: https://apps.leg.wa.gov/rcw/default.aspx?cite=70A.45.020 | P12: https://ecology.wa.gov/Air-Climate/Climate-change/Greenhouse-gases | Q12: Carbon dioxide and other GHGs | R12: Yes | S12: Not Specified | T12: No | U12: "overall emissions of greenhouse gases in the state" | V12: Yes | W12: Measures for all emission scopes that are covered by the target | X12: Less than annual reporting | Y12: Yes | Z12: Not Specified | AA12: "By December 31st of each even-numbered year beginning in 2010, the department and the department of commerce shall report to the governor and the appropriate committees of the senate and house of representatives the total emissions of greenhouse gases for the preceding two years" - https://apps.leg.wa.gov/rcw/default.aspx?cite=70A.45.020 Equity: limits to be met in a way that (a) Reduces the burdens and creates benefits for vulnerable populations and highly impacted communities with long-term and short-term outcomes for public health, economic well-being, local environments, and community resiliency that benefits all Washington residents; (b) Supports the current skilled and trained construction workforce, retains and creates other high quality employment opportunities, and generates broad, widely shared economic benefits for the state and Washington residents; and (c) Maintains Washington's manufacturing economy and avoids leakage of emissions to other jurisdictions Proposed actions are details in this report https://apps.ecology.wa.gov/publications/SummaryPages/1201004.html (particularly in appendices) | AB12: Yes | AC12: No | AD12: Yes (nature-based removals e.g. Forestation, soil carbon enhancement) | AE12: "all pathways to one and one-half degrees Celsius rely on some amount of negative emissions through carbon sequestration. It is therefore the intent of the legislature to strengthen Washington's statutory greenhouse gas emission limits to reflect current science and to align with the limits that other jurisdictions are setting to combat climate change and to encourage voluntary actions that increase carbon sequestration on natural and working lands and storage in the related products from those lands." - https://apps.leg.wa.gov/rcw/default.aspx?cite=70A.45.020 https://ecology.wa.gov/Air-Climate/Climate-change/Greenhouse-gases/Reducing-greenhouse-gases/Climate-Commitment-Act "A portion of a facility’s compliance obligation can come from credits generated by projects that prevent greenhouse gas emissions, called offset projects. Covered entities can meet up to 5% of their obligations with offsets through 2026, and 4% from 2027 to 2030" | AF12: 7740745 | AG12: 78800000 | AH12: 2018 | AI12: 612996000000 | AK12: Maximum percentage of emissions that can be offset | AL12: 5
A13: 2023-03-21 14:42:25 | B13: REG-0074 | C13: Alabama | E13: No target | I13: No target | O13: Alabama is only 1 of 8 States to not have a Statewide Comprehensive Energy Plan (https://www.naseo.org/stateenergyplans) Alabama is considered as a part of the Southeast region along with (Georgia, Mississippi, North Carolina, South Carolina, and Tennessee). With some initial investigation about net zero target. //efaidnbmnnnibpcajpcglclefindmkaj/https://irp-cdn.multiscreensite.com/be6d1d56/files/uploaded/SDSN_Southeast%20Report_FINAL.pdf | Q13: Not Specified | AF13: 4908620 | AI13: 228143000000
A14: 2024-03-12 14:53:14 | B14: REG-0075 | C14: Alaska | E14: No target | I14: No target | O14: Bill Walker ordered the creation of a Climate Action for Alaska Leadership Team in 2017 (https://gov.alaska.gov/admin-orders/administrative-order-no-289/). They published a plan (https://web.archive.org/web/20181130010258/http://climatechange.gov.alaska.gov/wp-content/uploads/sites/11/2018/09/Ak_Climate_Action_Plan_brochure_final_web.pdf) in 2018 for reductions, but were disbanded by Michael Dunleavy in 2019 (https://gov.alaska.gov/admin-orders/administrative-order-no-309/) | Q14: Not Specified | AF14: 731545 | AI14: 54386000000
A15: 2024-03-12 15:04:17 | B15: REG-0076 | C15: Arizona | E15: No target | I15: No target | O15: In 2006, the then Governor signed Executive Order 2006-13 " to reduce GHG emissions in Arizona to its 2000 emissions level by 2020 and to 50 percent below its 2000 emissions level by 2040" https://apps.azsos.gov/public_services/register/2006/37/governor.pdf In 2010, this was effectively nullified by the signing of a bill prohibiting state regulation of GHGs without permission of the state legislature by the new Governor (https://www.azleg.gov/legtext/49leg/2r/bills/hb2442h.pdf) Arizona Corporation Commissions regulates utilities: https://www.azcc.gov/news/2021/05/26/may-26-2021-special-open-meeting-highlights "Arizona’s regulated utilities [should be] 100% carbon-free energy by 2070" with "50% reduction by 2032, a 65% reduction by 2040, an 80% reduction by 2050, and a 95% reduction by 2060." https://www.azcc.gov/news/2022/01/27/january-contingency-open-meeting-highlights "Commissioners voted 3-2 at their January Contingency Open Meeting to not move forward with a package of energy rules that, if adopted, would have required electric utilities to achieve 100% zero-carbon emissions energy by 2070." | Q15: Not Specified | AF15: 7279000 | AG15: 87000000 | AH15: 2016 | AI15: 370119000000
A16: 2023-09-09 08:00:57 | B16: REG-0077 | C16: Arkansas | E16: No target | I16: No target | O16: No state-wide target in place. Although the report from the Governor's Commission on Global Warming (published in 2008) includes recommended emission reduction goals (written on the second page of the report, which can be accessed here: https://web.archive.org/web/20230618211959/https://uccrnna.org/wp-content/uploads/2017/06/Arkansas_2008_Governors-Commission-On-Global-Warming.pdf) it was only a report, and there doesn’t appear to be any legal instruments that are putting any state-wide emissions reduction target into effect. Arkansas’ lack of an emissions reduction target is also reflected on these websites: - https://climate-xchange.org/dashboard/map/arkansas/ - https://www.c2es.org/document/greenhouse-gas-emissions-targets/ - https://spotforcleanenergy.org/state/arkansas/emissions-standard/ | Q16: Not Specified | AF16: 3018000 | AI16: 130954000000
A17: 2024-03-12 16:52:16 | B17: REG-0078 | C17: Connecticut | D17: In law | E17: Emissions reduction target | F17: 2050 | H17: 2008 | I17: Emissions reduction target | J17: 45 | K17: 2001 | L17: 2030 | M17: By 2050, overall state emissions will be 80% below the level emitted in 2001 Governor's Bill No. 10 - Connecticut General Assembly, p.10, https://www.cga.ct.gov/2022/TOB/S/PDF/2022SB-00010-R00-SB.PDF | N17: The state shall reduce the level of emissions of greenhouse gas: (1) Not later than January 1, 2020, to a level at least 10% below the level emitted in 1990; (2) Not later than January 1, 2030, to a level at least 45% below the level emitted in 2001; (3) Not later than January 1, 2040, to a level of 0% from electricity supplied to electric customers in the state; and (4) Not later than January 1, 2050, to a level at least 80% below the level emitted in 2001 Governor's Bill No. 10 - Connecticut General Assembly, p.10, https://www.cga.ct.gov/2022/TOB/S/PDF/2022SB-00010-R00-SB.PDF | O17: "Economy-wide reduction target of 45% below 2001 levels by 2030...ensures Connecticut is on a downward trajectory from today's GHG emissions to the 80% reduction the Global Warming Solutions Act requires by 2050" (Building a Low Carbon future for Connecticut Report, p.11) | P17: https://www.cga.ct.gov/2022/TOB/S/PDF/2022SB-00010-R00-SB.PDF | Q17: Not Specified | R17: Not Specified | S17: No | T17: No | U17: The target covers the electric sector (focusing on a transition to green energy by 84% in 2050), transportation sector (increase in light-duty ZEV penetration rate to at least 20% by 2030), building sector (transition to 26% renewable thermal technologies by 2050) and non-energy GHG emissions (e..g.g., agricultural, industrial and waste sectors) (Building a Low Carbon future for Connecticut Report) | V17: Yes | W17: Information on the emission reductions expected from these measures within a certain time period|Information on the extent to which measures will be applied (e.g. if switching to EVs, what share of the fleet; if installing an own solar PV installation, what is the installed capacity)|Measures for all emission scopes that are covered by the target | X17: Less than annual reporting | Y17: Yes | Z17: Not Specified | AA17: In relation to equity, there is the aim to be involved in “prioritizing, integrating and advancing equitable distribution of the costs and benefits of climate change mitigation planning policies, specifically addressing disproportionate impacts of such strategies on environmental justice communities,” 2021 GC3 Phase 1 Report: https://portal.ct.gov/-/media/DEEP/climatechange/GC3/GC3_Phase1_Report_Jan2021.pdf Climate Action Timeline for Connecticut: https://portal.ct.gov/DEEP/Climate-Change/Climate-Action-Timeline-for-Connecticut | AB17: Not Specified | AC17: No | AD17: Yes (nature-based removals e.g. Forestation, soil carbon enhancement) | AE17: Aims to increase the mitigation of GHG in Connecticut's forests through several means: a. Evaluate feasibility of a goal of permanent protection of at least 50% of core forests greater than 250 acres by 2040 and identify resources that would be needed to achieve that goal. b. Consider actions to increase statewide forest cover from 59% to over 60% by 2040. 2021 GC3 Phase 1 Report: https://portal.ct.gov/-/media/DEEP/climatechange/GC3/GC3_Phase1_Report_Jan2021.pdf | AF17: 3565000 | AG17: 40603041 | AH17: 2017 | AI17: 287822000000 | AN17: 80 | AO17: 2001
A18: 2023-03-21 15:03:49 | B18: REG-0079 | C18: Delaware | D18: In policy document | E18: Emissions reduction target | F18: 2025 | H18: 2021 | I18: No target | M18: "In 2017, Governor John Carney committed Delaware to reducing greenhouse gas emissions by 26% to 28% from 2005 levels by 2025. Delaware’s Climate Action Plan provides information on our state’s emissions reduction progress and lays out strategies for meeting or exceeding our goal." (pg 12) https://documents.dnrec.delaware.gov/energy/Documents/Climate/Plan/Delaware-Climate-Action-Plan-2021.pdf | P18: https://documents.dnrec.delaware.gov/energy/Documents/Climate/Plan/Delaware-Climate-Action-Plan-2021.pdf | Q18: Carbon dioxide and other GHGs | R18: Not Specified | S18: Not Specified | T18: No | U18: "Delaware’s goal for 2025 is to reduce annual emissions to approximately 16,500,000 MT CO2e, a reduction of 28% (and a difference of about 6,300,000 MT CO2e) compared to 2005. What is MT CO2e? This is called the carbon dioxide equivalent (CO2e), and it allows us to use a single measure to calculate all greenhouse gas emissions: metric tons of carbon dioxide equivalent (MT CO2e)." (pg 51) https://documents.dnrec.delaware.gov/energy/Documents/Climate/Plan/Delaware-Climate-Action-Plan-2021.pdf | V18: Yes | W18: Information on the extent to which measures will be applied (e.g. if switching to EVs, what share of the fleet; if installing an own solar PV installation, what is the installed capacity)|Measures for all emission scopes that are covered by the target|Information on the emission reductions expected from these measures within a certain time period | X18: No reporting mechanism | Y18: Yes | Z18: Not Specified | AA18: "Collaborations and partnerships with communities can help build equity into climate action. Early and continued engagement is essential, as residents can speak first-hand to community-specific climatic and economic impacts." (pg 19) "It is also important to gain an understanding of how climate action, such as transitioning to low-carbon energy, could impact existing jobs or alter job opportunities. Knowledge of potential job gains and losses resulting from climate action can help guide where state resources are most needed to ensure that certain populations are not left behind." (pg 83) https://documents.dnrec.delaware.gov/energy/Documents/Climate/Plan/Delaware-Climate-Action-Plan-2021.pdf | AB18: Not Specified | AC18: No | AD18: Yes (nature-based removals e.g. Forestation, soil carbon enhancement) | AE18: "Delaware’s forests, croplands, wetlands and urban greenspaces can play an important role in responding to climate change. The plants and soils in these “natural and working lands” have the ability to absorb (or sequester) carbon dioxide from the atmosphere. This provides a cost-effective, temporary or long-term carbon storage solution. Capitalizing on natural carbon storage can help offset a portion of emissions released by human activities. Strategies Delaware can implement: - Support best management practices on agricultural lands that provide greenhouse gas emissions co-benefits - Support conservation and restoration of forest lands - Support local communities’ enhancement of urban greenspaces - Improve methods for measuring and tracking carbon sequestration" (pg 16) https://documents.dnrec.delaware.gov/energy/Documents/Climate/Plan/Delaware-Climate-Action-Plan-2021.pdf | AF18: 973764 | AG18: 12600000 | AH18: 2018 | AI18: 77082000000 | AN18: 28 | AO18: 2005
